Workbook
Name CurrentYear: #REF!
Name Estimate_Amount: #REF!
Name Estimated_Amount2: #REF!

Sheet Summary
A1: HHM JV Hotels-5-Year Capital Plan Summary
B17: Property Information
B18: Property Name: | D18: Hotel
B19: Key Count: | D19: 100
B20: State Tax %: | D20: 0.0725
B21: General Manager:
B22: RVP Approval:
B23: 5-Year Plan | D23: 2024-2028
B25: FF&E Reserve Projection
F27: 2023 | G27: =D23 -> 2024-2028 | H27: 2024 | I27: =H27+1 -> 2025 | J27: =I27+1 -> 2026 | K27: =J27+1 -> 2027 | L27: =K27+1 -> 2028
B28: Hotel Revenues | F28: INPUT 2023 FORECASTED REVENUE HERE | G28: =SUM(H28:L28) -> 6000000 | H28: =SUM('2024 Capex Plan'!$I$28:$T$28) -> 1200000 | I28: =SUM('2025 Capex Plan'!$I$28:$T$28) -> 1200000 | J28: =SUM('2026 Capex Plan'!$I$28:$T$28) -> 1200000 | K28: =SUM('2027 Capex Plan'!$I$28:$T$28) -> 1200000 | L28: =SUM('2028 Capex Plan'!$I$28:$T$28) -> 1200000
B29: FF&E Reserve % | F29: =$G$29 -> 0.04 | G29: =AVERAGE('2024 Capex Plan'!F29,'2025 Capex Plan'!F29,'2026 Capex Plan'!F29,'2027 Capex Plan'!F29,'2028 Capex Plan'!F29) -> 0.04 | H29: =$G$29 -> 0.04 | I29: =$G$29 -> 0.04 | J29: =$G$29 -> 0.04 | K29: =$G$29 -> 0.04 | L29: =$G$29 -> 0.04
B30: FF&E Reserve $ | F30: =F28*F29 -> #VALUE! | G30: =G28*G29 -> 240000 | H30: =H28*H29 -> 48000 | I30: =I28*I29 -> 48000 | J30: =J28*J29 -> 48000 | K30: =K28*K29 -> 48000 | L30: =L28*L29 -> 48000
B31: Total Estimated Capital Expenditures | F31: INPUT 2023 FORECASTED CAPEX SPEND | G31: =SUM(H31:L31) -> 175628.2 | H31: =H50 -> 35125.641 | I31: =I50 -> 35125.641 | J31: =J50 -> 35125.641 | K31: =K50 -> 35125.641 | L31: =L50 -> 35125.641
B32: Carryover FF&E Reserve | F32: =F30-F31 -> #VALUE! | G32: =G30-G31 -> 64371.797 | H32: =H30-H31 -> 12874.359 | I32: =I30-I31 -> 12874.359 | J32: =J30-J31 -> 12874.359 | K32: =K30-K31 -> 12874.359 | L32: =L30-L31 -> 12874.359
B33: FF&E Reserve % of Revenue | F33: =F31/F28 -> #VALUE! | G33: =G31/G28 -> 0.029271367 | H33: =H31/H28 -> 0.029271367 | I33: =I31/I28 -> 0.029271367 | J33: =J31/J28 -> 0.029271367 | K33: =K31/K28 -> 0.029271367 | L33: =L31/L28 -> 0.029271367
B35: =D23&" "& D18 & " " & "Non-PIP Capital Plan" -> 2024-2028 Hotel Non-PIP Capital Plan
B37: Item Description | E37: Comments | G37: =G27 -> 2024-2028 | H37: 2024 | I37: =H37+1 -> 2025 | J37: =I37+1 -> 2026 | K37: =J37+1 -> 2027 | L37: =K37+1 -> 2028
B38: (A) Guestrooms - Bathroom, Kitchen | G38: =SUM(H38:L38) -> 68417.724 | H38: ='2024 Capex Plan'!$L$37 -> 13683.545 | I38: ='2025 Capex Plan'!$L$37 -> 13683.545 | J38: ='2026 Capex Plan'!$L$37 -> 13683.545 | K38: ='2027 Capex Plan'!$L$37 -> 13683.545 | L38: ='2028 Capex Plan'!$L$37 -> 13683.545
B39: (B) Function Space - Meeting Banquet Space | G39: =SUM(H39:L39) -> 36041.631 | H39: ='2024 Capex Plan'!$L$50 -> 7208.3261 | I39: ='2025 Capex Plan'!$L$50 -> 7208.3261 | J39: ='2026 Capex Plan'!$L$50 -> 7208.3261 | K39: ='2027 Capex Plan'!$L$50 -> 7208.3261 | L39: ='2028 Capex Plan'!$L$50 -> 7208.3261
B40: (C) Public Areas - Lobby, Pool, Fitness, Corridors | G40: =SUM(H40:L40) -> 3384.0056 | H40: ='2024 Capex Plan'!$L$63 -> 676.80112 | I40: ='2025 Capex Plan'!$L$63 -> 676.80112 | J40: ='2026 Capex Plan'!$L$63 -> 676.80112 | K40: ='2027 Capex Plan'!$L$63 -> 676.80112 | L40: ='2028 Capex Plan'!$L$63 -> 676.80112
B41: (D) Technology - Computer Systems | G41: =SUM(H41:L41) -> 33789.381 | H41: ='2024 Capex Plan'!$L$76 -> 6757.8761 | I41: ='2025 Capex Plan'!$L$76 -> 6757.8761 | J41: ='2026 Capex Plan'!$L$76 -> 6757.8761 | K41: ='2027 Capex Plan'!$L$76 -> 6757.8761 | L41: ='2028 Capex Plan'!$L$76 -> 6757.8761
B42: (E) Back of House - Administrative, Laundry | G42: =SUM(H42:L42) -> 9014.6306 | H42: ='2024 Capex Plan'!$L$89 -> 1802.9261 | I42: ='2025 Capex Plan'!$L$89 -> 1802.9261 | J42: ='2026 Capex Plan'!$L$89 -> 1802.9261 | K42: ='2027 Capex Plan'!$L$89 -> 1802.9261 | L42: ='2028 Capex Plan'!$L$89 -> 1802.9261
B43: (F) Building - Site, Exterior, Mechanical | G43: =SUM(H43:L43) -> 9014.6306 | H43: ='2024 Capex Plan'!$L$102 -> 1802.9261 | I43: ='2025 Capex Plan'!$L$102 -> 1802.9261 | J43: ='2026 Capex Plan'!$L$102 -> 1802.9261 | K43: ='2027 Capex Plan'!$L$102 -> 1802.9261 | L43: ='2028 Capex Plan'!$L$102 -> 1802.9261
B44: QA Total | G44: =SUM(H44:L44) -> 77432.355 | H44: ='2024 Capex Plan'!$L$115 -> 15486.471 | I44: ='2025 Capex Plan'!$L$115 -> 15486.471 | J44: ='2026 Capex Plan'!$L$115 -> 15486.471 | K44: ='2027 Capex Plan'!$L$115 -> 15486.471 | L44: ='2028 Capex Plan'!$L$115 -> 15486.471
B45: PIP Total | G45: =SUM(H45:L45) -> 45056.261 | H45: ='2024 Capex Plan'!$L$116 -> 9011.2523 | I45: ='2025 Capex Plan'!$L$116 -> 9011.2523 | J45: ='2026 Capex Plan'!$L$116 -> 9011.2523 | K45: ='2027 Capex Plan'!$L$116 -> 9011.2523 | L45: ='2028 Capex Plan'!$L$116 -> 9011.2523
B46: PCA Total | G46: =SUM(H46:L46) -> 3384.0056 | H46: ='2024 Capex Plan'!$L$117 -> 676.80112 | I46: ='2025 Capex Plan'!$L$117 -> 676.80112 | J46: ='2026 Capex Plan'!$L$117 -> 676.80112 | K46: ='2027 Capex Plan'!$L$117 -> 676.80112 | L46: ='2028 Capex Plan'!$L$117 -> 676.80112
B47: Other Total | G47: =SUM(H47:L47) -> 33789.381 | H47: ='2024 Capex Plan'!$L$118 -> 6757.8761 | I47: ='2025 Capex Plan'!$L$118 -> 6757.8761 | J47: ='2026 Capex Plan'!$L$118 -> 6757.8761 | K47: ='2027 Capex Plan'!$L$118 -> 6757.8761 | L47: ='2028 Capex Plan'!$L$118 -> 6757.8761
B48: Total Capital Expenditures excl. Contingency | G48: =SUM(H48:L48) -> 159662 | H48: ='2024 Capex Plan'!$L$119 -> 31932.4 | I48: ='2025 Capex Plan'!$L$119 -> 31932.4 | J48: ='2026 Capex Plan'!$L$119 -> 31932.4 | K48: ='2027 Capex Plan'!$L$119 -> 31932.4 | L48: ='2028 Capex Plan'!$L$119 -> 31932.4
B49: Contingency | D49: Fixed % of Total Capital Expenditures excl. Contingency | E49: =AVERAGE('2024 Capex Plan'!E120,'2025 Capex Plan'!E120,'2026 Capex Plan'!E120,'2027 Capex Plan'!E120,'2028 Capex Plan'!E120) -> 0.1 | F49: =IF(D49="Method - $ per Key","Per Key",IF(D19="Method - $ Allowance","Total","")) | G49: =SUM(H49:L49) -> 15966.2 | H49: ='2024 Capex Plan'!$L$120 -> 3193.24 | I49: ='2025 Capex Plan'!$L$120 -> 3193.24 | J49: ='2026 Capex Plan'!$L$120 -> 3193.24 | K49: ='2027 Capex Plan'!$L$120 -> 3193.24 | L49: ='2028 Capex Plan'!$L$120 -> 3193.24
B50: Total Capital Expenditures | G50: =SUM(H50:L50) -> 175628.2 | H50: =SUM(H48:H49) -> 35125.641 | I50: =SUM(I48:I49) -> 35125.641 | J50: =SUM(J48:J49) -> 35125.641 | K50: =SUM(K48:K49) -> 35125.641 | L50: =SUM(L48:L49) -> 35125.641

Sheet 2024 Capex Plan
B2: Instructions
B3: 1. Fill out Property Name, Key Count, State Tax % , and General Manager in the Property Information Box 2. Input budget Total Revenues in row 28 columns I to T 3. Input current FF&E reserve balance in cell F32 4. Fill out all applicable data by hotel departments found in the Hotel Capital Plan section. Only fill in columns C to H and total amounts will calculate in columns I through M. Remember to select from Category dropdown options. 3. Spread the estimated capex amount by month in columns N though Y. 4. Capex plans should be reviewed with Regional VPs and Engineering. Once the plan has been approved, the RVP should initial in the RVP Approval box in the Property Information section. IMPORTANT: Do not add or delete rows or columns from the model.
B17: Property Information
B18: Property Name: | D18: Hotel
B19: Key Count: | D19: 100
B20: State Tax %: | D20: 0.0725
B21: General Manager:
B22: RVP Approval:
B23: Budget Year | D23: 2024
B25: FF&E Reserve Projection
F27: =D23 -> 2024 | I27: January | J27: February | K27: March | L27: April | M27: May | N27: June | O27: July | P27: August | Q27: September | R27: October | S27: November | T27: December
B28: Hotel Revenues | F28: =SUM(I28:T28) -> 1200000 | I28: 100000 | J28: 100000 | K28: 100000 | L28: 100000 | M28: 100000 | N28: 100000 | O28: 100000 | P28: 100000 | Q28: 100000 | R28: 100000 | S28: 100000 | T28: 100000
B29: FF&E Reserve % | F29: 0.04 | I29: =$F$29 -> 0.04 | J29: =$F$29 -> 0.04 | K29: =$F$29 -> 0.04 | L29: =$F$29 -> 0.04 | M29: =$F$29 -> 0.04 | N29: =$F$29 -> 0.04 | O29: =$F$29 -> 0.04 | P29: =$F$29 -> 0.04 | ... T29: =$F$29 -> 0.04
B30: Estimated FF&E Reserve | F30: =F28*F29 -> 48000 | I30: =I28*I29 -> 4000 | J30: =J28*J29 -> 4000 | K30: =K28*K29 -> 4000 | L30: =L28*L29 -> 4000 | M30: =M28*M29 -> 4000 | N30: =N28*N29 -> 4000 | O30: =O28*O29 -> 4000 | P30: =P28*P29 -> 4000 | ... T30: =T28*T29 -> 4000
B31: Total Estimated Capital Expenditures | F31: =SUM(I31:T31) -> 35125.641 | I31: =N121 -> 35125.641 | J31: =O121 -> 0 | K31: =P121 -> 0 | L31: =Q121 -> 0 | M31: =R121 -> 0 | N31: =S121 -> 0 | O31: =T121 -> 0 | P31: =U121 -> 0 | ... T31: =Y121 -> 0
B32: % of Revenue | F32: =F31/F28 -> 0.029271367 | I32: =I31/I28 -> 0.35125641 | J32: =J31/J28 -> 0 | K32: =K31/K28 -> 0 | L32: =L31/L28 -> 0 | M32: =M31/M28 -> 0 | N32: =N31/N28 -> 0 | O32: =O31/O28 -> 0 | P32: =P31/P28 -> 0 | ... T32: =T31/T28 -> 0
B34: =D23&" "& D18 & " " & "Capital Plan" -> 2024 Hotel Capital Plan
B36: Item Description | D36: Comments | E36: Category | F36: Quantity | G36: Unit Price | H36: Freight Cost | I36: Sub Total | J36: Tax | K36: Purchase Fee | L36: Estimate Amount | M36: Budget Amount | N36: January | O36: February | P36: March | Q36: April | R36: May | S36: June | T36: July | U36: August | V36: September | W36: October | X36: November | Y36: December
B37: (A) Guestrooms - Bathroom, Kitchen | H37: =SUM(H38:H49) -> 1 | I37: =SUM(I38:I49) -> 12151 | J37: =SUM(J38:J49) -> 880.9475 | K37: =SUM(K38:K49) -> 651.59738 | L37: =SUM(L38:L49) -> 13683.545 | M37: =SUM(M38:M49) -> 13683.545 | N37: =SUM(N38:N49) -> 13683.545 | O37: =SUM(O38:O49) -> 0 | ... Y37: =SUM(Y38:Y49) -> 0
B38: A1 | C38: Example | D38: Text | E38: QA | F38: 18 | G38: 675 | H38: 1 | I38: =(F38*G38)+H38 -> 12151 | J38: =I38*$D$20 -> 880.9475 | K38: =SUM(I38:J38)*5% -> 651.59738 | L38: =SUM(I38:K38) -> 13683.545 | M38: =SUM(N38, O38,P38,Q38,R38,S38,T38,U38,V38,W38,X38,Y38) -> 13683.545 | N38: =L38 -> 13683.545
B39: A2 | E39: PCA | I39: =(F39*G39)+H39 -> 0 | J39: =I39*$D$20 -> 0 | K39: =SUM(I39:J39)*5% -> 0 | L39: =SUM(I39:K39) -> 0 | M39: =SUM(N39, O39,P39,Q39,R39,S39,T39,U39,V39,W39,X39,Y39) -> 0
B40: A3 | I40: =(F40*G40)+H40 -> 0 | J40: =I40*$D$20 -> 0 | K40: =SUM(I40:J40)*5% -> 0 | L40: =SUM(I40:K40) -> 0 | M40: =SUM(N40, O40,P40,Q40,R40,S40,T40,U40,V40,W40,X40,Y40) -> 0
B41: A4 | I41: =(F41*G41)+H41 -> 0 | J41: =I41*$D$20 -> 0 | K41: =SUM(I41:J41)*5% -> 0 | L41: =SUM(I41:K41) -> 0 | M41: =SUM(N41, O41,P41,Q41,R41,S41,T41,U41,V41,W41,X41,Y41) -> 0
B42: A5 | I42: =(F42*G42)+H42 -> 0 | J42: =I42*$D$20 -> 0 | K42: =SUM(I42:J42)*5% -> 0 | L42: =SUM(I42:K42) -> 0 | M42: =SUM(N42, O42,P42,Q42,R42,S42,T42,U42,V42,W42,X42,Y42) -> 0
B43: A6 | I43: =(F43*G43)+H43 -> 0 | J43: =I43*$D$20 -> 0 | K43: =SUM(I43:J43)*5% -> 0 | L43: =SUM(I43:K43) -> 0 | M43: =SUM(N43, O43,P43,Q43,R43,S43,T43,U43,V43,W43,X43,Y43) -> 0
B44: A7 | I44: =(F44*G44)+H44 -> 0 | J44: =I44*$D$20 -> 0 | K44: =SUM(I44:J44)*5% -> 0 | L44: =SUM(I44:K44) -> 0 | M44: =SUM(N44, O44,P44,Q44,R44,S44,T44,U44,V44,W44,X44,Y44) -> 0
B45: A8 | I45: =(F45*G45)+H45 -> 0 | J45: =I45*$D$20 -> 0 | K45: =SUM(I45:J45)*5% -> 0 | L45: =SUM(I45:K45) -> 0 | M45: =SUM(N45, O45,P45,Q45,R45,S45,T45,U45,V45,W45,X45,Y45) -> 0
B46: A9 | I46: =(F46*G46)+H46 -> 0 | J46: =I46*$D$20 -> 0 | K46: =SUM(I46:J46)*5% -> 0 | L46: =SUM(I46:K46) -> 0 | M46: =SUM(N46, O46,P46,Q46,R46,S46,T46,U46,V46,W46,X46,Y46) -> 0
B47: A10 | I47: =(F47*G47)+H47 -> 0 | J47: =I47*$D$20 -> 0 | K47: =SUM(I47:J47)*5% -> 0 | L47: =SUM(I47:K47) -> 0 | M47: =SUM(N47, O47,P47,Q47,R47,S47,T47,U47,V47,W47,X47,Y47) -> 0
B48: A11 | I48: =(F48*G48)+H48 -> 0 | J48: =I48*$D$20 -> 0 | K48: =SUM(I48:J48)*5% -> 0 | L48: =SUM(I48:K48) -> 0 | M48: =SUM(N48, O48,P48,Q48,R48,S48,T48,U48,V48,W48,X48,Y48) -> 0
B49: A12 | I49: =(F49*G49)+H49 -> 0 | J49: =I49*$D$20 -> 0 | K49: =SUM(I49:J49)*5% -> 0 | L49: =SUM(I49:K49) -> 0 | M49: =SUM(N49, O49,P49,Q49,R49,S49,T49,U49,V49,W49,X49,Y49) -> 0
B50: (B) Function Space - Meeting Banquet Space | H50: =SUM(H51:H62) -> 1 | I50: =SUM(I51:I62) -> 6401 | J50: =SUM(J51:J62) -> 464.0725 | K50: =SUM(K51:K62) -> 343.25363 | L50: =SUM(L51:L62) -> 7208.3261 | M50: =SUM(M51:M62) -> 7208.3261 | N50: =SUM(N51:N62) -> 7208.3261 | O50: =SUM(O51:O62) -> 0 | ... Y50: =SUM(Y51:Y62) -> 0
B51: B1 | C51: Example | D51: Text | E51: PIP | F51: 4 | G51: 1600 | H51: 1 | I51: =(F51*G51)+H51 -> 6401 | J51: =I51*$D$20 -> 464.0725 | K51: =SUM(I51:J51)*5% -> 343.25363 | L51: =SUM(I51:K51) -> 7208.3261 | M51: =SUM(N51, O51,P51,Q51,R51,S51,T51,U51,V51,W51,X51,Y51) -> 7208.3261 | N51: =L51 -> 7208.3261
B52: B2 | I52: =(F52*G52)+H52 -> 0 | J52: =I52*$D$20 -> 0 | K52: =SUM(I52:J52)*5% -> 0 | L52: =SUM(I52:K52) -> 0 | M52: =SUM(N52, O52,P52,Q52,R52,S52,T52,U52,V52,W52,X52,Y52) -> 0
B53: B3 | I53: =(F53*G53)+H53 -> 0 | J53: =I53*$D$20 -> 0 | K53: =SUM(I53:J53)*5% -> 0 | L53: =SUM(I53:K53) -> 0 | M53: =SUM(N53, O53,P53,Q53,R53,S53,T53,U53,V53,W53,X53,Y53) -> 0
B54: B4 | I54: =(F54*G54)+H54 -> 0 | J54: =I54*$D$20 -> 0 | K54: =SUM(I54:J54)*5% -> 0 | L54: =SUM(I54:K54) -> 0 | M54: =SUM(N54, O54,P54,Q54,R54,S54,T54,U54,V54,W54,X54,Y54) -> 0
B55: B5 | I55: =(F55*G55)+H55 -> 0 | J55: =I55*$D$20 -> 0 | K55: =SUM(I55:J55)*5% -> 0 | L55: =SUM(I55:K55) -> 0 | M55: =SUM(N55, O55,P55,Q55,R55,S55,T55,U55,V55,W55,X55,Y55) -> 0
B56: B6 | I56: =(F56*G56)+H56 -> 0 | J56: =I56*$D$20 -> 0 | K56: =SUM(I56:J56)*5% -> 0 | L56: =SUM(I56:K56) -> 0 | M56: =SUM(N56, O56,P56,Q56,R56,S56,T56,U56,V56,W56,X56,Y56) -> 0
B57: B7 | I57: =(F57*G57)+H57 -> 0 | J57: =I57*$D$20 -> 0 | K57: =SUM(I57:J57)*5% -> 0 | L57: =SUM(I57:K57) -> 0 | M57: =SUM(N57, O57,P57,Q57,R57,S57,T57,U57,V57,W57,X57,Y57) -> 0
B58: B8 | I58: =(F58*G58)+H58 -> 0 | J58: =I58*$D$20 -> 0 | K58: =SUM(I58:J58)*5% -> 0 | L58: =SUM(I58:K58) -> 0 | M58: =SUM(N58, O58,P58,Q58,R58,S58,T58,U58,V58,W58,X58,Y58) -> 0
...

Sheet 2025 Capex Plan
B2: Instructions
B3: 1. Fill out Property Name, Key Count, State Tax % , and General Manager in the Property Information Box 2. Input budget Total Revenues in row 28 columns I to T 3. Input current FF&E reserve balance in cell F32 4. Fill out all applicable data by hotel departments found in the Hotel Capital Plan section. Only fill in columns C to H and total amounts will calculate in columns I through M. Remember to select from Category dropdown options. 3. Spread the estimated capex amount by month in columns N though Y. 4. Capex plans should be reviewed with Regional VPs and Engineering. Once the plan has been approved, the RVP should initial in the RVP Approval box in the Property Information section. IMPORTANT: Do not add or delete rows or columns from the model.
B17: Property Information
B18: Property Name: | D18: Hotel
B19: Key Count: | D19: 100
B20: State Tax %: | D20: 0.0725
B21: General Manager:
B22: RVP Approval:
B23: Budget Year | D23: 2025
B25: FF&E Reserve Projection
F27: =D23 -> 2025 | I27: January | J27: February | K27: March | L27: April | M27: May | N27: June | O27: July | P27: August | Q27: September | R27: October | S27: November | T27: December
B28: Hotel Revenues | F28: =SUM(I28:T28) -> 1200000 | I28: 100000 | J28: 100000 | K28: 100000 | L28: 100000 | M28: 100000 | N28: 100000 | O28: 100000 | P28: 100000 | Q28: 100000 | R28: 100000 | S28: 100000 | T28: 100000
B29: FF&E Reserve % | F29: 0.04 | I29: =$F$29 -> 0.04 | J29: =$F$29 -> 0.04 | K29: =$F$29 -> 0.04 | L29: =$F$29 -> 0.04 | M29: =$F$29 -> 0.04 | N29: =$F$29 -> 0.04 | O29: =$F$29 -> 0.04 | P29: =$F$29 -> 0.04 | ... T29: =$F$29 -> 0.04
B30: Estimated FF&E Reserve | F30: =F28*F29 -> 48000 | I30: =I28*I29 -> 4000 | J30: =J28*J29 -> 4000 | K30: =K28*K29 -> 4000 | L30: =L28*L29 -> 4000 | M30: =M28*M29 -> 4000 | N30: =N28*N29 -> 4000 | O30: =O28*O29 -> 4000 | P30: =P28*P29 -> 4000 | ... T30: =T28*T29 -> 4000
B31: Total Estimated Capital Expenditures | F31: =SUM(I31:T31) -> 35125.641 | I31: =N121 -> 35125.641 | J31: =O121 -> 0 | K31: =P121 -> 0 | L31: =Q121 -> 0 | M31: =R121 -> 0 | N31: =S121 -> 0 | O31: =T121 -> 0 | P31: =U121 -> 0 | ... T31: =Y121 -> 0
B32: % of Revenue | F32: =F31/F28 -> 0.029271367 | I32: =I31/I28 -> 0.35125641 | J32: =J31/J28 -> 0 | K32: =K31/K28 -> 0 | L32: =L31/L28 -> 0 | M32: =M31/M28 -> 0 | N32: =N31/N28 -> 0 | O32: =O31/O28 -> 0 | P32: =P31/P28 -> 0 | ... T32: =T31/T28 -> 0
B34: =D23&" "& D18 & " " & "Capital Plan" -> 2025 Hotel Capital Plan
B36: Item Description | D36: Comments | E36: Category | F36: Quantity | G36: Unit Price | H36: Freight Cost | I36: Sub Total | J36: Tax | K36: Purchase Fee | L36: Estimate Amount | M36: Budget Amount | N36: January | O36: February | P36: March | Q36: April | R36: May | S36: June | T36: July | U36: August | V36: September | W36: October | X36: November | Y36: December
B37: (A) Guestrooms - Bathroom, Kitchen | H37: =SUM(H38:H49) -> 1 | I37: =SUM(I38:I49) -> 12151 | J37: =SUM(J38:J49) -> 880.9475 | K37: =SUM(K38:K49) -> 651.59738 | L37: =SUM(L38:L49) -> 13683.545 | M37: =SUM(M38:M49) -> 13683.545 | N37: =SUM(N38:N49) -> 13683.545 | O37: =SUM(O38:O49) -> 0 | ... Y37: =SUM(Y38:Y49) -> 0
B38: A1 | C38: Example | D38: Text | E38: QA | F38: 18 | G38: 675 | H38: 1 | I38: =(F38*G38)+H38 -> 12151 | J38: =I38*$D$20 -> 880.9475 | K38: =SUM(I38:J38)*5% -> 651.59738 | L38: =SUM(I38:K38) -> 13683.545 | M38: =SUM(N38, O38,P38,Q38,R38,S38,T38,U38,V38,W38,X38,Y38) -> 13683.545 | N38: =L38 -> 13683.545
B39: A2 | I39: =(F39*G39)+H39 -> 0 | J39: =I39*$D$20 -> 0 | K39: =SUM(I39:J39)*5% -> 0 | L39: =SUM(I39:K39) -> 0 | M39: =SUM(N39, O39,P39,Q39,R39,S39,T39,U39,V39,W39,X39,Y39) -> 0
B40: A3 | I40: =(F40*G40)+H40 -> 0 | J40: =I40*$D$20 -> 0 | K40: =SUM(I40:J40)*5% -> 0 | L40: =SUM(I40:K40) -> 0 | M40: =SUM(N40, O40,P40,Q40,R40,S40,T40,U40,V40,W40,X40,Y40) -> 0
B41: A4 | C41: PM Fee | D41: Third Party PM | I41: =(F41*G41)+H41 -> 0 | J41: =I41*$D$20 -> 0 | K41: =SUM(I41:J41)*5% -> 0 | L41: =SUM(I41:K41) -> 0 | M41: =SUM(N41, O41,P41,Q41,R41,S41,T41,U41,V41,W41,X41,Y41) -> 0
B42: A5 | I42: =(F42*G42)+H42 -> 0 | J42: =I42*$D$20 -> 0 | K42: =SUM(I42:J42)*5% -> 0 | L42: =SUM(I42:K42) -> 0 | M42: =SUM(N42, O42,P42,Q42,R42,S42,T42,U42,V42,W42,X42,Y42) -> 0
B43: A6 | I43: =(F43*G43)+H43 -> 0 | J43: =I43*$D$20 -> 0 | K43: =SUM(I43:J43)*5% -> 0 | L43: =SUM(I43:K43) -> 0 | M43: =SUM(N43, O43,P43,Q43,R43,S43,T43,U43,V43,W43,X43,Y43) -> 0
B44: A7 | I44: =(F44*G44)+H44 -> 0 | J44: =I44*$D$20 -> 0 | K44: =SUM(I44:J44)*5% -> 0 | L44: =SUM(I44:K44) -> 0 | M44: =SUM(N44, O44,P44,Q44,R44,S44,T44,U44,V44,W44,X44,Y44) -> 0
B45: A8 | I45: =(F45*G45)+H45 -> 0 | J45: =I45*$D$20 -> 0 | K45: =SUM(I45:J45)*5% -> 0 | L45: =SUM(I45:K45) -> 0 | M45: =SUM(N45, O45,P45,Q45,R45,S45,T45,U45,V45,W45,X45,Y45) -> 0
B46: A9 | I46: =(F46*G46)+H46 -> 0 | J46: =I46*$D$20 -> 0 | K46: =SUM(I46:J46)*5% -> 0 | L46: =SUM(I46:K46) -> 0 | M46: =SUM(N46, O46,P46,Q46,R46,S46,T46,U46,V46,W46,X46,Y46) -> 0
B47: A10 | I47: =(F47*G47)+H47 -> 0 | J47: =I47*$D$20 -> 0 | K47: =SUM(I47:J47)*5% -> 0 | L47: =SUM(I47:K47) -> 0 | M47: =SUM(N47, O47,P47,Q47,R47,S47,T47,U47,V47,W47,X47,Y47) -> 0
B48: A11 | I48: =(F48*G48)+H48 -> 0 | J48: =I48*$D$20 -> 0 | K48: =SUM(I48:J48)*5% -> 0 | L48: =SUM(I48:K48) -> 0 | M48: =SUM(N48, O48,P48,Q48,R48,S48,T48,U48,V48,W48,X48,Y48) -> 0
B49: A12 | I49: =(F49*G49)+H49 -> 0 | J49: =I49*$D$20 -> 0 | K49: =SUM(I49:J49)*5% -> 0 | L49: =SUM(I49:K49) -> 0 | M49: =SUM(N49, O49,P49,Q49,R49,S49,T49,U49,V49,W49,X49,Y49) -> 0
B50: (B) Function Space - Meeting Banquet Space | H50: =SUM(H51:H62) -> 1 | I50: =SUM(I51:I62) -> 6401 | J50: =SUM(J51:J62) -> 464.0725 | K50: =SUM(K51:K62) -> 343.25363 | L50: =SUM(L51:L62) -> 7208.3261 | M50: =SUM(M51:M62) -> 7208.3261 | N50: =SUM(N51:N62) -> 7208.3261 | O50: =SUM(O51:O62) -> 0 | ... Y50: =SUM(Y51:Y62) -> 0
B51: B1 | C51: Example | D51: Text | E51: PIP | F51: 4 | G51: 1600 | H51: 1 | I51: =(F51*G51)+H51 -> 6401 | J51: =I51*$D$20 -> 464.0725 | K51: =SUM(I51:J51)*5% -> 343.25363 | L51: =SUM(I51:K51) -> 7208.3261 | M51: =SUM(N51, O51,P51,Q51,R51,S51,T51,U51,V51,W51,X51,Y51) -> 7208.3261 | N51: =L51 -> 7208.3261
B52: B2 | I52: =(F52*G52)+H52 -> 0 | J52: =I52*$D$20 -> 0 | K52: =SUM(I52:J52)*5% -> 0 | L52: =SUM(I52:K52) -> 0 | M52: =SUM(N52, O52,P52,Q52,R52,S52,T52,U52,V52,W52,X52,Y52) -> 0
B53: B3 | I53: =(F53*G53)+H53 -> 0 | J53: =I53*$D$20 -> 0 | K53: =SUM(I53:J53)*5% -> 0 | L53: =SUM(I53:K53) -> 0 | M53: =SUM(N53, O53,P53,Q53,R53,S53,T53,U53,V53,W53,X53,Y53) -> 0
B54: B4 | I54: =(F54*G54)+H54 -> 0 | J54: =I54*$D$20 -> 0 | K54: =SUM(I54:J54)*5% -> 0 | L54: =SUM(I54:K54) -> 0 | M54: =SUM(N54, O54,P54,Q54,R54,S54,T54,U54,V54,W54,X54,Y54) -> 0
B55: B5 | I55: =(F55*G55)+H55 -> 0 | J55: =I55*$D$20 -> 0 | K55: =SUM(I55:J55)*5% -> 0 | L55: =SUM(I55:K55) -> 0 | M55: =SUM(N55, O55,P55,Q55,R55,S55,T55,U55,V55,W55,X55,Y55) -> 0
B56: B6 | I56: =(F56*G56)+H56 -> 0 | J56: =I56*$D$20 -> 0 | K56: =SUM(I56:J56)*5% -> 0 | L56: =SUM(I56:K56) -> 0 | M56: =SUM(N56, O56,P56,Q56,R56,S56,T56,U56,V56,W56,X56,Y56) -> 0
B57: B7 | I57: =(F57*G57)+H57 -> 0 | J57: =I57*$D$20 -> 0 | K57: =SUM(I57:J57)*5% -> 0 | L57: =SUM(I57:K57) -> 0 | M57: =SUM(N57, O57,P57,Q57,R57,S57,T57,U57,V57,W57,X57,Y57) -> 0
B58: B8 | I58: =(F58*G58)+H58 -> 0 | J58: =I58*$D$20 -> 0 | K58: =SUM(I58:J58)*5% -> 0 | L58: =SUM(I58:K58) -> 0 | M58: =SUM(N58, O58,P58,Q58,R58,S58,T58,U58,V58,W58,X58,Y58) -> 0
...

Sheet 2026 Capex Plan
B2: Instructions
B3: 1. Fill out Property Name, Key Count, State Tax % , and General Manager in the Property Information Box 2. Input budget Total Revenues in row 28 columns I to T 3. Input current FF&E reserve balance in cell F32 4. Fill out all applicable data by hotel departments found in the Hotel Capital Plan section. Only fill in columns C to H and total amounts will calculate in columns I through M. Remember to select from Category dropdown options. 3. Spread the estimated capex amount by month in columns N though Y. 4. Capex plans should be reviewed with Regional VPs and Engineering. Once the plan has been approved, the RVP should initial in the RVP Approval box in the Property Information section. IMPORTANT: Do not add or delete rows or columns from the model.
B17: Property Information
B18: Property Name: | D18: Hotel
B19: Key Count: | D19: 100
B20: State Tax %: | D20: 0.0725
B21: General Manager:
B22: RVP Approval:
B23: Budget Year | D23: 2026
B25: FF&E Reserve Projection
F27: =D23 -> 2026 | I27: January | J27: February | K27: March | L27: April | M27: May | N27: June | O27: July | P27: August | Q27: September | R27: October | S27: November | T27: December
B28: Hotel Revenues | F28: =SUM(I28:T28) -> 1200000 | I28: 100000 | J28: 100000 | K28: 100000 | L28: 100000 | M28: 100000 | N28: 100000 | O28: 100000 | P28: 100000 | Q28: 100000 | R28: 100000 | S28: 100000 | T28: 100000
B29: FF&E Reserve % | F29: 0.04 | I29: =$F$29 -> 0.04 | J29: =$F$29 -> 0.04 | K29: =$F$29 -> 0.04 | L29: =$F$29 -> 0.04 | M29: =$F$29 -> 0.04 | N29: =$F$29 -> 0.04 | O29: =$F$29 -> 0.04 | P29: =$F$29 -> 0.04 | ... T29: =$F$29 -> 0.04
B30: Estimated FF&E Reserve | F30: =F28*F29 -> 48000 | I30: =I28*I29 -> 4000 | J30: =J28*J29 -> 4000 | K30: =K28*K29 -> 4000 | L30: =L28*L29 -> 4000 | M30: =M28*M29 -> 4000 | N30: =N28*N29 -> 4000 | O30: =O28*O29 -> 4000 | P30: =P28*P29 -> 4000 | ... T30: =T28*T29 -> 4000
B31: Total Estimated Capital Expenditures | F31: =SUM(I31:T31) -> 35125.641 | I31: =N121 -> 35125.641 | J31: =O121 -> 0 | K31: =P121 -> 0 | L31: =Q121 -> 0 | M31: =R121 -> 0 | N31: =S121 -> 0 | O31: =T121 -> 0 | P31: =U121 -> 0 | ... T31: =Y121 -> 0
B32: % of Revenue | F32: =F31/F28 -> 0.029271367 | I32: =I31/I28 -> 0.35125641 | J32: =J31/J28 -> 0 | K32: =K31/K28 -> 0 | L32: =L31/L28 -> 0 | M32: =M31/M28 -> 0 | N32: =N31/N28 -> 0 | O32: =O31/O28 -> 0 | P32: =P31/P28 -> 0 | ... T32: =T31/T28 -> 0
B34: =D23&" "& D18 & " " & "Capital Plan" -> 2026 Hotel Capital Plan
B36: Item Description | D36: Comments | E36: Category | F36: Quantity | G36: Unit Price | H36: Freight Cost | I36: Sub Total | J36: Tax | K36: Purchase Fee | L36: Estimate Amount | M36: Budget Amount | N36: January | O36: February | P36: March | Q36: April | R36: May | S36: June | T36: July | U36: August | V36: September | W36: October | X36: November | Y36: December
B37: (A) Guestrooms - Bathroom, Kitchen | H37: =SUM(H38:H49) -> 1 | I37: =SUM(I38:I49) -> 12151 | J37: =SUM(J38:J49) -> 880.9475 | K37: =SUM(K38:K49) -> 651.59738 | L37: =SUM(L38:L49) -> 13683.545 | M37: =SUM(M38:M49) -> 13683.545 | N37: =SUM(N38:N49) -> 13683.545 | O37: =SUM(O38:O49) -> 0 | ... Y37: =SUM(Y38:Y49) -> 0
B38: A1 | C38: Example | D38: Text | E38: QA | F38: 18 | G38: 675 | H38: 1 | I38: =(F38*G38)+H38 -> 12151 | J38: =I38*$D$20 -> 880.9475 | K38: =SUM(I38:J38)*5% -> 651.59738 | L38: =SUM(I38:K38) -> 13683.545 | M38: =SUM(N38, O38,P38,Q38,R38,S38,T38,U38,V38,W38,X38,Y38) -> 13683.545 | N38: =L38 -> 13683.545
B39: A2 | I39: =(F39*G39)+H39 -> 0 | J39: =I39*$D$20 -> 0 | K39: =SUM(I39:J39)*5% -> 0 | L39: =SUM(I39:K39) -> 0 | M39: =SUM(N39, O39,P39,Q39,R39,S39,T39,U39,V39,W39,X39,Y39) -> 0
B40: A3 | I40: =(F40*G40)+H40 -> 0 | J40: =I40*$D$20 -> 0 | K40: =SUM(I40:J40)*5% -> 0 | L40: =SUM(I40:K40) -> 0 | M40: =SUM(N40, O40,P40,Q40,R40,S40,T40,U40,V40,W40,X40,Y40) -> 0
B41: A4 | I41: =(F41*G41)+H41 -> 0 | J41: =I41*$D$20 -> 0 | K41: =SUM(I41:J41)*5% -> 0 | L41: =SUM(I41:K41) -> 0 | M41: =SUM(N41, O41,P41,Q41,R41,S41,T41,U41,V41,W41,X41,Y41) -> 0
B42: A5 | I42: =(F42*G42)+H42 -> 0 | J42: =I42*$D$20 -> 0 | K42: =SUM(I42:J42)*5% -> 0 | L42: =SUM(I42:K42) -> 0 | M42: =SUM(N42, O42,P42,Q42,R42,S42,T42,U42,V42,W42,X42,Y42) -> 0
B43: A6 | I43: =(F43*G43)+H43 -> 0 | J43: =I43*$D$20 -> 0 | K43: =SUM(I43:J43)*5% -> 0 | L43: =SUM(I43:K43) -> 0 | M43: =SUM(N43, O43,P43,Q43,R43,S43,T43,U43,V43,W43,X43,Y43) -> 0
B44: A7 | I44: =(F44*G44)+H44 -> 0 | J44: =I44*$D$20 -> 0 | K44: =SUM(I44:J44)*5% -> 0 | L44: =SUM(I44:K44) -> 0 | M44: =SUM(N44, O44,P44,Q44,R44,S44,T44,U44,V44,W44,X44,Y44) -> 0
B45: A8 | I45: =(F45*G45)+H45 -> 0 | J45: =I45*$D$20 -> 0 | K45: =SUM(I45:J45)*5% -> 0 | L45: =SUM(I45:K45) -> 0 | M45: =SUM(N45, O45,P45,Q45,R45,S45,T45,U45,V45,W45,X45,Y45) -> 0
B46: A9 | I46: =(F46*G46)+H46 -> 0 | J46: =I46*$D$20 -> 0 | K46: =SUM(I46:J46)*5% -> 0 | L46: =SUM(I46:K46) -> 0 | M46: =SUM(N46, O46,P46,Q46,R46,S46,T46,U46,V46,W46,X46,Y46) -> 0
B47: A10 | I47: =(F47*G47)+H47 -> 0 | J47: =I47*$D$20 -> 0 | K47: =SUM(I47:J47)*5% -> 0 | L47: =SUM(I47:K47) -> 0 | M47: =SUM(N47, O47,P47,Q47,R47,S47,T47,U47,V47,W47,X47,Y47) -> 0
B48: A11 | I48: =(F48*G48)+H48 -> 0 | J48: =I48*$D$20 -> 0 | K48: =SUM(I48:J48)*5% -> 0 | L48: =SUM(I48:K48) -> 0 | M48: =SUM(N48, O48,P48,Q48,R48,S48,T48,U48,V48,W48,X48,Y48) -> 0
B49: A12 | I49: =(F49*G49)+H49 -> 0 | J49: =I49*$D$20 -> 0 | K49: =SUM(I49:J49)*5% -> 0 | L49: =SUM(I49:K49) -> 0 | M49: =SUM(N49, O49,P49,Q49,R49,S49,T49,U49,V49,W49,X49,Y49) -> 0
B50: (B) Function Space - Meeting Banquet Space | H50: =SUM(H51:H62) -> 1 | I50: =SUM(I51:I62) -> 6401 | J50: =SUM(J51:J62) -> 464.0725 | K50: =SUM(K51:K62) -> 343.25363 | L50: =SUM(L51:L62) -> 7208.3261 | M50: =SUM(M51:M62) -> 7208.3261 | N50: =SUM(N51:N62) -> 7208.3261 | O50: =SUM(O51:O62) -> 0 | ... Y50: =SUM(Y51:Y62) -> 0
B51: B1 | C51: Example | D51: Text | E51: PIP | F51: 4 | G51: 1600 | H51: 1 | I51: =(F51*G51)+H51 -> 6401 | J51: =I51*$D$20 -> 464.0725 | K51: =SUM(I51:J51)*5% -> 343.25363 | L51: =SUM(I51:K51) -> 7208.3261 | M51: =SUM(N51, O51,P51,Q51,R51,S51,T51,U51,V51,W51,X51,Y51) -> 7208.3261 | N51: =L51 -> 7208.3261
B52: B2 | I52: =(F52*G52)+H52 -> 0 | J52: =I52*$D$20 -> 0 | K52: =SUM(I52:J52)*5% -> 0 | L52: =SUM(I52:K52) -> 0 | M52: =SUM(N52, O52,P52,Q52,R52,S52,T52,U52,V52,W52,X52,Y52) -> 0
B53: B3 | I53: =(F53*G53)+H53 -> 0 | J53: =I53*$D$20 -> 0 | K53: =SUM(I53:J53)*5% -> 0 | L53: =SUM(I53:K53) -> 0 | M53: =SUM(N53, O53,P53,Q53,R53,S53,T53,U53,V53,W53,X53,Y53) -> 0
B54: B4 | I54: =(F54*G54)+H54 -> 0 | J54: =I54*$D$20 -> 0 | K54: =SUM(I54:J54)*5% -> 0 | L54: =SUM(I54:K54) -> 0 | M54: =SUM(N54, O54,P54,Q54,R54,S54,T54,U54,V54,W54,X54,Y54) -> 0
B55: B5 | I55: =(F55*G55)+H55 -> 0 | J55: =I55*$D$20 -> 0 | K55: =SUM(I55:J55)*5% -> 0 | L55: =SUM(I55:K55) -> 0 | M55: =SUM(N55, O55,P55,Q55,R55,S55,T55,U55,V55,W55,X55,Y55) -> 0
B56: B6 | I56: =(F56*G56)+H56 -> 0 | J56: =I56*$D$20 -> 0 | K56: =SUM(I56:J56)*5% -> 0 | L56: =SUM(I56:K56) -> 0 | M56: =SUM(N56, O56,P56,Q56,R56,S56,T56,U56,V56,W56,X56,Y56) -> 0
B57: B7 | I57: =(F57*G57)+H57 -> 0 | J57: =I57*$D$20 -> 0 | K57: =SUM(I57:J57)*5% -> 0 | L57: =SUM(I57:K57) -> 0 | M57: =SUM(N57, O57,P57,Q57,R57,S57,T57,U57,V57,W57,X57,Y57) -> 0
B58: B8 | I58: =(F58*G58)+H58 -> 0 | J58: =I58*$D$20 -> 0 | K58: =SUM(I58:J58)*5% -> 0 | L58: =SUM(I58:K58) -> 0 | M58: =SUM(N58, O58,P58,Q58,R58,S58,T58,U58,V58,W58,X58,Y58) -> 0
...

Sheet 2027 Capex Plan
B2: Instructions
B3: 1. Fill out Property Name, Key Count, State Tax % , and General Manager in the Property Information Box 2. Input budget Total Revenues in row 28 columns I to T 3. Input current FF&E reserve balance in cell F32 4. Fill out all applicable data by hotel departments found in the Hotel Capital Plan section. Only fill in columns C to H and total amounts will calculate in columns I through M. Remember to select from Category dropdown options. 3. Spread the estimated capex amount by month in columns N though Y. 4. Capex plans should be reviewed with Regional VPs and Engineering. Once the plan has been approved, the RVP should initial in the RVP Approval box in the Property Information section. IMPORTANT: Do not add or delete rows or columns from the model.
B17: Property Information
B18: Property Name: | D18: Hotel
B19: Key Count: | D19: 100
B20: State Tax %: | D20: 0.0725
B21: General Manager:
B22: RVP Approval:
B23: Budget Year | D23: 2027
B25: FF&E Reserve Projection
F27: =D23 -> 2027 | I27: January | J27: February | K27: March | L27: April | M27: May | N27: June | O27: July | P27: August | Q27: September | R27: October | S27: November | T27: December
B28: Hotel Revenues | F28: =SUM(I28:T28) -> 1200000 | I28: 100000 | J28: 100000 | K28: 100000 | L28: 100000 | M28: 100000 | N28: 100000 | O28: 100000 | P28: 100000 | Q28: 100000 | R28: 100000 | S28: 100000 | T28: 100000
B29: FF&E Reserve % | F29: 0.04 | I29: =$F$29 -> 0.04 | J29: =$F$29 -> 0.04 | K29: =$F$29 -> 0.04 | L29: =$F$29 -> 0.04 | M29: =$F$29 -> 0.04 | N29: =$F$29 -> 0.04 | O29: =$F$29 -> 0.04 | P29: =$F$29 -> 0.04 | ... T29: =$F$29 -> 0.04
B30: Estimated FF&E Reserve | F30: =F28*F29 -> 48000 | I30: =I28*I29 -> 4000 | J30: =J28*J29 -> 4000 | K30: =K28*K29 -> 4000 | L30: =L28*L29 -> 4000 | M30: =M28*M29 -> 4000 | N30: =N28*N29 -> 4000 | O30: =O28*O29 -> 4000 | P30: =P28*P29 -> 4000 | ... T30: =T28*T29 -> 4000
B31: Total Estimated Capital Expenditures | F31: =SUM(I31:T31) -> 35125.641 | I31: =N121 -> 35125.641 | J31: =O121 -> 0 | K31: =P121 -> 0 | L31: =Q121 -> 0 | M31: =R121 -> 0 | N31: =S121 -> 0 | O31: =T121 -> 0 | P31: =U121 -> 0 | ... T31: =Y121 -> 0
B32: % of Revenue | F32: =F31/F28 -> 0.029271367 | I32: =I31/I28 -> 0.35125641 | J32: =J31/J28 -> 0 | K32: =K31/K28 -> 0 | L32: =L31/L28 -> 0 | M32: =M31/M28 -> 0 | N32: =N31/N28 -> 0 | O32: =O31/O28 -> 0 | P32: =P31/P28 -> 0 | ... T32: =T31/T28 -> 0
B34: =D23&" "& D18 & " " & "Capital Plan" -> 2027 Hotel Capital Plan
B36: Item Description | D36: Comments | E36: Category | F36: Quantity | G36: Unit Price | H36: Freight Cost | I36: Sub Total | J36: Tax | K36: Purchase Fee | L36: Estimate Amount | M36: Budget Amount | N36: January | O36: February | P36: March | Q36: April | R36: May | S36: June | T36: July | U36: August | V36: September | W36: October | X36: November | Y36: December
B37: (A) Guestrooms - Bathroom, Kitchen | H37: =SUM(H38:H49) -> 1 | I37: =SUM(I38:I49) -> 12151 | J37: =SUM(J38:J49) -> 880.9475 | K37: =SUM(K38:K49) -> 651.59738 | L37: =SUM(L38:L49) -> 13683.545 | M37: =SUM(M38:M49) -> 13683.545 | N37: =SUM(N38:N49) -> 13683.545 | O37: =SUM(O38:O49) -> 0 | ... Y37: =SUM(Y38:Y49) -> 0
B38: A1 | C38: Example | D38: Text | E38: QA | F38: 18 | G38: 675 | H38: 1 | I38: =(F38*G38)+H38 -> 12151 | J38: =I38*$D$20 -> 880.9475 | K38: =SUM(I38:J38)*5% -> 651.59738 | L38: =SUM(I38:K38) -> 13683.545 | M38: =SUM(N38, O38,P38,Q38,R38,S38,T38,U38,V38,W38,X38,Y38) -> 13683.545 | N38: =L38 -> 13683.545
B39: A2 | I39: =(F39*G39)+H39 -> 0 | J39: =I39*$D$20 -> 0 | K39: =SUM(I39:J39)*5% -> 0 | L39: =SUM(I39:K39) -> 0 | M39: =SUM(N39, O39,P39,Q39,R39,S39,T39,U39,V39,W39,X39,Y39) -> 0
B40: A3 | I40: =(F40*G40)+H40 -> 0 | J40: =I40*$D$20 -> 0 | K40: =SUM(I40:J40)*5% -> 0 | L40: =SUM(I40:K40) -> 0 | M40: =SUM(N40, O40,P40,Q40,R40,S40,T40,U40,V40,W40,X40,Y40) -> 0
B41: A4 | I41: =(F41*G41)+H41 -> 0 | J41: =I41*$D$20 -> 0 | K41: =SUM(I41:J41)*5% -> 0 | L41: =SUM(I41:K41) -> 0 | M41: =SUM(N41, O41,P41,Q41,R41,S41,T41,U41,V41,W41,X41,Y41) -> 0
B42: A5 | I42: =(F42*G42)+H42 -> 0 | J42: =I42*$D$20 -> 0 | K42: =SUM(I42:J42)*5% -> 0 | L42: =SUM(I42:K42) -> 0 | M42: =SUM(N42, O42,P42,Q42,R42,S42,T42,U42,V42,W42,X42,Y42) -> 0
B43: A6 | I43: =(F43*G43)+H43 -> 0 | J43: =I43*$D$20 -> 0 | K43: =SUM(I43:J43)*5% -> 0 | L43: =SUM(I43:K43) -> 0 | M43: =SUM(N43, O43,P43,Q43,R43,S43,T43,U43,V43,W43,X43,Y43) -> 0
B44: A7 | I44: =(F44*G44)+H44 -> 0 | J44: =I44*$D$20 -> 0 | K44: =SUM(I44:J44)*5% -> 0 | L44: =SUM(I44:K44) -> 0 | M44: =SUM(N44, O44,P44,Q44,R44,S44,T44,U44,V44,W44,X44,Y44) -> 0
B45: A8 | I45: =(F45*G45)+H45 -> 0 | J45: =I45*$D$20 -> 0 | K45: =SUM(I45:J45)*5% -> 0 | L45: =SUM(I45:K45) -> 0 | M45: =SUM(N45, O45,P45,Q45,R45,S45,T45,U45,V45,W45,X45,Y45) -> 0
B46: A9 | I46: =(F46*G46)+H46 -> 0 | J46: =I46*$D$20 -> 0 | K46: =SUM(I46:J46)*5% -> 0 | L46: =SUM(I46:K46) -> 0 | M46: =SUM(N46, O46,P46,Q46,R46,S46,T46,U46,V46,W46,X46,Y46) -> 0
B47: A10 | I47: =(F47*G47)+H47 -> 0 | J47: =I47*$D$20 -> 0 | K47: =SUM(I47:J47)*5% -> 0 | L47: =SUM(I47:K47) -> 0 | M47: =SUM(N47, O47,P47,Q47,R47,S47,T47,U47,V47,W47,X47,Y47) -> 0
B48: A11 | I48: =(F48*G48)+H48 -> 0 | J48: =I48*$D$20 -> 0 | K48: =SUM(I48:J48)*5% -> 0 | L48: =SUM(I48:K48) -> 0 | M48: =SUM(N48, O48,P48,Q48,R48,S48,T48,U48,V48,W48,X48,Y48) -> 0
B49: A12 | I49: =(F49*G49)+H49 -> 0 | J49: =I49*$D$20 -> 0 | K49: =SUM(I49:J49)*5% -> 0 | L49: =SUM(I49:K49) -> 0 | M49: =SUM(N49, O49,P49,Q49,R49,S49,T49,U49,V49,W49,X49,Y49) -> 0
B50: (B) Function Space - Meeting Banquet Space | H50: =SUM(H51:H62) -> 1 | I50: =SUM(I51:I62) -> 6401 | J50: =SUM(J51:J62) -> 464.0725 | K50: =SUM(K51:K62) -> 343.25363 | L50: =SUM(L51:L62) -> 7208.3261 | M50: =SUM(M51:M62) -> 7208.3261 | N50: =SUM(N51:N62) -> 7208.3261 | O50: =SUM(O51:O62) -> 0 | ... Y50: =SUM(Y51:Y62) -> 0
B51: B1 | C51: Example | D51: Text | E51: PIP | F51: 4 | G51: 1600 | H51: 1 | I51: =(F51*G51)+H51 -> 6401 | J51: =I51*$D$20 -> 464.0725 | K51: =SUM(I51:J51)*5% -> 343.25363 | L51: =SUM(I51:K51) -> 7208.3261 | M51: =SUM(N51, O51,P51,Q51,R51,S51,T51,U51,V51,W51,X51,Y51) -> 7208.3261 | N51: =L51 -> 7208.3261
B52: B2 | I52: =(F52*G52)+H52 -> 0 | J52: =I52*$D$20 -> 0 | K52: =SUM(I52:J52)*5% -> 0 | L52: =SUM(I52:K52) -> 0 | M52: =SUM(N52, O52,P52,Q52,R52,S52,T52,U52,V52,W52,X52,Y52) -> 0
B53: B3 | I53: =(F53*G53)+H53 -> 0 | J53: =I53*$D$20 -> 0 | K53: =SUM(I53:J53)*5% -> 0 | L53: =SUM(I53:K53) -> 0 | M53: =SUM(N53, O53,P53,Q53,R53,S53,T53,U53,V53,W53,X53,Y53) -> 0
B54: B4 | I54: =(F54*G54)+H54 -> 0 | J54: =I54*$D$20 -> 0 | K54: =SUM(I54:J54)*5% -> 0 | L54: =SUM(I54:K54) -> 0 | M54: =SUM(N54, O54,P54,Q54,R54,S54,T54,U54,V54,W54,X54,Y54) -> 0
B55: B5 | I55: =(F55*G55)+H55 -> 0 | J55: =I55*$D$20 -> 0 | K55: =SUM(I55:J55)*5% -> 0 | L55: =SUM(I55:K55) -> 0 | M55: =SUM(N55, O55,P55,Q55,R55,S55,T55,U55,V55,W55,X55,Y55) -> 0
B56: B6 | I56: =(F56*G56)+H56 -> 0 | J56: =I56*$D$20 -> 0 | K56: =SUM(I56:J56)*5% -> 0 | L56: =SUM(I56:K56) -> 0 | M56: =SUM(N56, O56,P56,Q56,R56,S56,T56,U56,V56,W56,X56,Y56) -> 0
B57: B7 | I57: =(F57*G57)+H57 -> 0 | J57: =I57*$D$20 -> 0 | K57: =SUM(I57:J57)*5% -> 0 | L57: =SUM(I57:K57) -> 0 | M57: =SUM(N57, O57,P57,Q57,R57,S57,T57,U57,V57,W57,X57,Y57) -> 0
B58: B8 | I58: =(F58*G58)+H58 -> 0 | J58: =I58*$D$20 -> 0 | K58: =SUM(I58:J58)*5% -> 0 | L58: =SUM(I58:K58) -> 0 | M58: =SUM(N58, O58,P58,Q58,R58,S58,T58,U58,V58,W58,X58,Y58) -> 0
...

Sheet 2028 Capex Plan
B2: Instructions
B3: 1. Fill out Property Name, Key Count, State Tax % , and General Manager in the Property Information Box 2. Input budget Total Revenues in row 28 columns I to T 3. Input current FF&E reserve balance in cell F32 4. Fill out all applicable data by hotel departments found in the Hotel Capital Plan section. Only fill in columns C to H and total amounts will calculate in columns I through M. Remember to select from Category dropdown options. 3. Spread the estimated capex amount by month in columns N though Y. 4. Capex plans should be reviewed with Regional VPs and Engineering. Once the plan has been approved, the RVP should initial in the RVP Approval box in the Property Information section. IMPORTANT: Do not add or delete rows or columns from the model.
B17: Property Information
B18: Property Name: | D18: Hotel
B19: Key Count: | D19: 100
B20: State Tax %: | D20: 0.0725
B21: General Manager:
B22: RVP Approval:
B23: Budget Year | D23: 2028
B25: FF&E Reserve Projection
F27: =D23 -> 2028 | I27: January | J27: February | K27: March | L27: April | M27: May | N27: June | O27: July | P27: August | Q27: September | R27: October | S27: November | T27: December
B28: Hotel Revenues | F28: =SUM(I28:T28) -> 1200000 | I28: 100000 | J28: 100000 | K28: 100000 | L28: 100000 | M28: 100000 | N28: 100000 | O28: 100000 | P28: 100000 | Q28: 100000 | R28: 100000 | S28: 100000 | T28: 100000
B29: FF&E Reserve % | F29: 0.04 | I29: =$F$29 -> 0.04 | J29: =$F$29 -> 0.04 | K29: =$F$29 -> 0.04 | L29: =$F$29 -> 0.04 | M29: =$F$29 -> 0.04 | N29: =$F$29 -> 0.04 | O29: =$F$29 -> 0.04 | P29: =$F$29 -> 0.04 | ... T29: =$F$29 -> 0.04
B30: Estimated FF&E Reserve | F30: =F28*F29 -> 48000 | I30: =I28*I29 -> 4000 | J30: =J28*J29 -> 4000 | K30: =K28*K29 -> 4000 | L30: =L28*L29 -> 4000 | M30: =M28*M29 -> 4000 | N30: =N28*N29 -> 4000 | O30: =O28*O29 -> 4000 | P30: =P28*P29 -> 4000 | ... T30: =T28*T29 -> 4000
B31: Total Estimated Capital Expenditures | F31: =SUM(I31:T31) -> 35125.641 | I31: =N121 -> 35125.641 | J31: =O121 -> 0 | K31: =P121 -> 0 | L31: =Q121 -> 0 | M31: =R121 -> 0 | N31: =S121 -> 0 | O31: =T121 -> 0 | P31: =U121 -> 0 | ... T31: =Y121 -> 0
B32: % of Revenue | F32: =F31/F28 -> 0.029271367 | I32: =I31/I28 -> 0.35125641 | J32: =J31/J28 -> 0 | K32: =K31/K28 -> 0 | L32: =L31/L28 -> 0 | M32: =M31/M28 -> 0 | N32: =N31/N28 -> 0 | O32: =O31/O28 -> 0 | P32: =P31/P28 -> 0 | ... T32: =T31/T28 -> 0
B34: =D23&" "& D18 & " " & "Capital Plan" -> 2028 Hotel Capital Plan
B36: Item Description | D36: Comments | E36: Category | F36: Quantity | G36: Unit Price | H36: Freight Cost | I36: Sub Total | J36: Tax | K36: Purchase Fee | L36: Estimate Amount | M36: Budget Amount | N36: January | O36: February | P36: March | Q36: April | R36: May | S36: June | T36: July | U36: August | V36: September | W36: October | X36: November | Y36: December
B37: (A) Guestrooms - Bathroom, Kitchen | H37: =SUM(H38:H49) -> 1 | I37: =SUM(I38:I49) -> 12151 | J37: =SUM(J38:J49) -> 880.9475 | K37: =SUM(K38:K49) -> 651.59738 | L37: =SUM(L38:L49) -> 13683.545 | M37: =SUM(M38:M49) -> 13683.545 | N37: =SUM(N38:N49) -> 13683.545 | O37: =SUM(O38:O49) -> 0 | ... Y37: =SUM(Y38:Y49) -> 0
B38: A1 | C38: Example | D38: Text | E38: QA | F38: 18 | G38: 675 | H38: 1 | I38: =(F38*G38)+H38 -> 12151 | J38: =I38*$D$20 -> 880.9475 | K38: =SUM(I38:J38)*5% -> 651.59738 | L38: =SUM(I38:K38) -> 13683.545 | M38: =SUM(N38, O38,P38,Q38,R38,S38,T38,U38,V38,W38,X38,Y38) -> 13683.545 | N38: =L38 -> 13683.545
B39: A2 | I39: =(F39*G39)+H39 -> 0 | J39: =I39*$D$20 -> 0 | K39: =SUM(I39:J39)*5% -> 0 | L39: =SUM(I39:K39) -> 0 | M39: =SUM(N39, O39,P39,Q39,R39,S39,T39,U39,V39,W39,X39,Y39) -> 0
B40: A3 | I40: =(F40*G40)+H40 -> 0 | J40: =I40*$D$20 -> 0 | K40: =SUM(I40:J40)*5% -> 0 | L40: =SUM(I40:K40) -> 0 | M40: =SUM(N40, O40,P40,Q40,R40,S40,T40,U40,V40,W40,X40,Y40) -> 0
B41: A4 | I41: =(F41*G41)+H41 -> 0 | J41: =I41*$D$20 -> 0 | K41: =SUM(I41:J41)*5% -> 0 | L41: =SUM(I41:K41) -> 0 | M41: =SUM(N41, O41,P41,Q41,R41,S41,T41,U41,V41,W41,X41,Y41) -> 0
B42: A5 | I42: =(F42*G42)+H42 -> 0 | J42: =I42*$D$20 -> 0 | K42: =SUM(I42:J42)*5% -> 0 | L42: =SUM(I42:K42) -> 0 | M42: =SUM(N42, O42,P42,Q42,R42,S42,T42,U42,V42,W42,X42,Y42) -> 0
B43: A6 | I43: =(F43*G43)+H43 -> 0 | J43: =I43*$D$20 -> 0 | K43: =SUM(I43:J43)*5% -> 0 | L43: =SUM(I43:K43) -> 0 | M43: =SUM(N43, O43,P43,Q43,R43,S43,T43,U43,V43,W43,X43,Y43) -> 0
B44: A7 | I44: =(F44*G44)+H44 -> 0 | J44: =I44*$D$20 -> 0 | K44: =SUM(I44:J44)*5% -> 0 | L44: =SUM(I44:K44) -> 0 | M44: =SUM(N44, O44,P44,Q44,R44,S44,T44,U44,V44,W44,X44,Y44) -> 0
B45: A8 | I45: =(F45*G45)+H45 -> 0 | J45: =I45*$D$20 -> 0 | K45: =SUM(I45:J45)*5% -> 0 | L45: =SUM(I45:K45) -> 0 | M45: =SUM(N45, O45,P45,Q45,R45,S45,T45,U45,V45,W45,X45,Y45) -> 0
B46: A9 | I46: =(F46*G46)+H46 -> 0 | J46: =I46*$D$20 -> 0 | K46: =SUM(I46:J46)*5% -> 0 | L46: =SUM(I46:K46) -> 0 | M46: =SUM(N46, O46,P46,Q46,R46,S46,T46,U46,V46,W46,X46,Y46) -> 0
B47: A10 | I47: =(F47*G47)+H47 -> 0 | J47: =I47*$D$20 -> 0 | K47: =SUM(I47:J47)*5% -> 0 | L47: =SUM(I47:K47) -> 0 | M47: =SUM(N47, O47,P47,Q47,R47,S47,T47,U47,V47,W47,X47,Y47) -> 0
B48: A11 | I48: =(F48*G48)+H48 -> 0 | J48: =I48*$D$20 -> 0 | K48: =SUM(I48:J48)*5% -> 0 | L48: =SUM(I48:K48) -> 0 | M48: =SUM(N48, O48,P48,Q48,R48,S48,T48,U48,V48,W48,X48,Y48) -> 0
B49: A12 | I49: =(F49*G49)+H49 -> 0 | J49: =I49*$D$20 -> 0 | K49: =SUM(I49:J49)*5% -> 0 | L49: =SUM(I49:K49) -> 0 | M49: =SUM(N49, O49,P49,Q49,R49,S49,T49,U49,V49,W49,X49,Y49) -> 0
B50: (B) Function Space - Meeting Banquet Space | H50: =SUM(H51:H62) -> 1 | I50: =SUM(I51:I62) -> 6401 | J50: =SUM(J51:J62) -> 464.0725 | K50: =SUM(K51:K62) -> 343.25363 | L50: =SUM(L51:L62) -> 7208.3261 | M50: =SUM(M51:M62) -> 7208.3261 | N50: =SUM(N51:N62) -> 7208.3261 | O50: =SUM(O51:O62) -> 0 | ... Y50: =SUM(Y51:Y62) -> 0
B51: B1 | C51: Example | D51: Text | E51: PIP | F51: 4 | G51: 1600 | H51: 1 | I51: =(F51*G51)+H51 -> 6401 | J51: =I51*$D$20 -> 464.0725 | K51: =SUM(I51:J51)*5% -> 343.25363 | L51: =SUM(I51:K51) -> 7208.3261 | M51: =SUM(N51, O51,P51,Q51,R51,S51,T51,U51,V51,W51,X51,Y51) -> 7208.3261 | N51: =L51 -> 7208.3261
B52: B2 | I52: =(F52*G52)+H52 -> 0 | J52: =I52*$D$20 -> 0 | K52: =SUM(I52:J52)*5% -> 0 | L52: =SUM(I52:K52) -> 0 | M52: =SUM(N52, O52,P52,Q52,R52,S52,T52,U52,V52,W52,X52,Y52) -> 0
B53: B3 | I53: =(F53*G53)+H53 -> 0 | J53: =I53*$D$20 -> 0 | K53: =SUM(I53:J53)*5% -> 0 | L53: =SUM(I53:K53) -> 0 | M53: =SUM(N53, O53,P53,Q53,R53,S53,T53,U53,V53,W53,X53,Y53) -> 0
B54: B4 | I54: =(F54*G54)+H54 -> 0 | J54: =I54*$D$20 -> 0 | K54: =SUM(I54:J54)*5% -> 0 | L54: =SUM(I54:K54) -> 0 | M54: =SUM(N54, O54,P54,Q54,R54,S54,T54,U54,V54,W54,X54,Y54) -> 0
B55: B5 | I55: =(F55*G55)+H55 -> 0 | J55: =I55*$D$20 -> 0 | K55: =SUM(I55:J55)*5% -> 0 | L55: =SUM(I55:K55) -> 0 | M55: =SUM(N55, O55,P55,Q55,R55,S55,T55,U55,V55,W55,X55,Y55) -> 0
B56: B6 | I56: =(F56*G56)+H56 -> 0 | J56: =I56*$D$20 -> 0 | K56: =SUM(I56:J56)*5% -> 0 | L56: =SUM(I56:K56) -> 0 | M56: =SUM(N56, O56,P56,Q56,R56,S56,T56,U56,V56,W56,X56,Y56) -> 0
B57: B7 | I57: =(F57*G57)+H57 -> 0 | J57: =I57*$D$20 -> 0 | K57: =SUM(I57:J57)*5% -> 0 | L57: =SUM(I57:K57) -> 0 | M57: =SUM(N57, O57,P57,Q57,R57,S57,T57,U57,V57,W57,X57,Y57) -> 0
B58: B8 | I58: =(F58*G58)+H58 -> 0 | J58: =I58*$D$20 -> 0 | K58: =SUM(I58:J58)*5% -> 0 | L58: =SUM(I58:K58) -> 0 | M58: =SUM(N58, O58,P58,Q58,R58,S58,T58,U58,V58,W58,X58,Y58) -> 0
...
