Workbook
Name Month: Summary!$V$2
Name Property: Summary!$V$1
Name Property_Code: Summary!$V$1
Name Year: Summary!$V$3
Name YTDMonth: Summary!$V$4

Sheet Summary
V1: ANG | W1: <- Property Code
C2: Angler's | V2: Apr | W2: <- Month
C3: STATEMENT OF INCOME | V3: 2025 | W3: <- Year
C4: ="FOR THE PERIOD ENDING "&UPPER($V$2)&" "&Year -> FOR THE PERIOD ENDING APR 2025 | V4: =Month&"YTD" -> AprYTD
D6: =Year&" "&UPPER(Month)&" - PERIODIC" -> 2025 APR - PERIODIC | M6: =Year&" "&UPPER(Month)&" - YEAR TO DATE" -> 2025 APR - YEAR TO DATE
D7: Actual | F7: Budget | H7: VARIANCE | I7: Actual - Last Year | K7: VARIANCE | M7: Actual | O7: Budget | Q7: VARIANCE | R7: Actual - Last Year | T7: VARIANCE
D8: $ | E8: % | F8: $ | G8: % | H8: $ | I8: Actual | J8: % | K8: $ | M8: $ | N8: % | O8: $ | P8: % | Q8: $ | R8: Actual | S8: % | T8: $
B9: Total Rooms Available - 100 | C9: Available Rooms | D9: 3960 | F9: 3960 | H9: =+D9-F9 -> 0 | I9: 3960 | K9: =+(D9-I9) -> 0 | M9: 15840 | O9: 15840 | Q9: =+M9-O9 -> 0 | R9: 15972 | T9: =+(M9-R9) -> -132
B10: Total Rooms Sold - 100 | C10: Total Rooms Sold | D10: 3684 | F10: 3645 | H10: =+D10-F10 -> 39 | I10: 3692 | K10: =+(D10-I10) -> -8 | M10: 14556 | O10: 14563 | Q10: =+M10-O10 -> -7 | R10: 14696 | T10: =+(M10-R10) -> -140
C11: Occupancy | D11: =D10/D9 -> 0.93030303 | F11: =F10/F9 -> 0.92045455 | H11: =+(D11-F11)*100 -> 0.98484848 | I11: =I10/I9 -> 0.93232323 | K11: =+(D11-I11)*100 -> -0.2020202 | M11: =M10/M9 -> 0.91893939 | O11: =O10/O9 -> 0.91938131 | Q11: =+(M11-O11)*100 -> -0.044191919 | R11: =R10/R9 -> 0.92011019 | T11: =+(M11-R11)*100 -> -0.11707989
C12: Average Daily Rate | D12: =D15/D10 -> 266.56628 | F12: =F15/F10 -> 263.2116 | H12: =+D12-F12 -> 3.3546817 | I12: =I15/I10 -> 258.44728 | K12: =+(D12-I12) -> 8.1190006 | M12: =M15/M10 -> 295.51506 | O12: =O15/O10 -> 307.02472 | Q12: =+M12-O12 -> -11.509669 | R12: =R15/R10 -> 301.98569 | T12: =+(M12-R12) -> -6.4706296
C13: Revenue per Available Room | D13: =D11*D12 -> 247.98742 | F13: =F11*F12 -> 242.27432 | H13: =+D13-F13 -> 5.7131061 | I13: =I11*I12 -> 240.95641 | K13: =+(D13-I13) -> 7.0310152 | M13: =M11*M12 -> 271.56043 | O13: =O11*O12 -> 282.27279 | Q13: =+M13-O13 -> -10.712369 | R13: =R11*R12 -> 277.86011 | T13: =+(M13-R13) -> -6.2996809
C14: Revenues
B15: Total Revenue - 100 | C15: Rooms | D15: 982030.19 | E15: =+IFERROR(D15/D$19,"") -> 0.65086039 | F15: 959406.29 | G15: =+IFERROR(F15/F$19,"") -> 0.631665 | H15: =+D15-F15 -> 22623.9 | I15: 954187.37 | J15: =+IFERROR(I15/I$19,"") -> 0.72319515 | K15: =+(D15-I15) -> 27842.82 | M15: 4301517.2 | N15: =+IFERROR(M15/M$19,"") -> 0.68394804 | O15: 4471201.1 | P15: =+IFERROR(O15/O$19,"") -> 0.66098689 | Q15: =+M15-O15 -> -169683.92 | R15: 4437981.6 | S15: =+IFERROR(R15/R$19,"") -> 0.75674011 | T15: =+(M15-R15) -> -136464.48
B16: Total Revenue - 200 | C16: Food & Beverage | D16: 379131.93 | E16: =+IFERROR(D16/D$19,"") -> 0.25127736 | F16: 437605.85 | G16: =+IFERROR(F16/F$19,"") -> 0.288116 | H16: =+D16-F16 -> -58473.92 | I16: 250971.01 | J16: =+IFERROR(I16/I$19,"") -> 0.19021528 | K16: =+(D16-I16) -> 128160.92 | M16: 1523965.8 | N16: =+IFERROR(M16/M$19,"") -> 0.24231297 | O16: 1792694 | P16: =+IFERROR(O16/O$19,"") -> 0.26501766 | Q16: =+M16-O16 -> -268728.2 | R16: 916590.74 | S16: =+IFERROR(R16/R$19,"") -> 0.15629199 | T16: =+(M16-R16) -> 607375.05
B17: Total Revenue - 300 | C17: Other Operated Departments | D17: 2948.44 | E17: =+IFERROR(D17/D$19,"") -> 0.0019541383 | F17: 1557.87 | G17: =+IFERROR(F17/F$19,"") -> 0.0010256885 | H17: =+D17-F17 -> 1390.57 | I17: 1461.55 | J17: =+IFERROR(I17/I$19,"") -> 0.0011077341 | K17: =+(D17-I17) -> 1486.89 | M17: 9874.14 | N17: =+IFERROR(M17/M$19,"") -> 0.0015700039 | O17: 6224.22 | P17: =+IFERROR(O17/O$19,"") -> 0.0009201393 | Q17: =+M17-O17 -> 3649.92 | R17: 7206.75 | S17: =+IFERROR(R17/R$19,"") -> 0.0012288552 | T17: =+(M17-R17) -> 2667.39
B18: Total Revenue - 400 | C18: Miscellaneous Income | D18: 144707.94 | E18: =+IFERROR(D18/D$19,"") -> 0.095908116 | F18: 120283 | G18: =+IFERROR(F18/F$19,"") -> 0.079193312 | H18: =+D18-F18 -> 24424.94 | I18: 112785.17 | J18: =+IFERROR(I18/I$19,"") -> 0.085481836 | K18: =+(D18-I18) -> 31922.77 | M18: 453888.45 | N18: =+IFERROR(M18/M$19,"") -> 0.072168982 | O18: 494313 | P18: =+IFERROR(O18/O$19,"") -> 0.073075312 | Q18: =+M18-O18 -> -40424.55 | R18: 502825.58 | S18: =+IFERROR(R18/R$19,"") -> 0.085739041 | T18: =+(M18-R18) -> -48937.13
B19: Total Revenue - 000 | C19: Total Revenues | D19: =+SUM(D15:D18) -> 1508818.5 | E19: =+IFERROR(D19/D$19,"") -> 1 | F19: =+SUM(F15:F18) -> 1518853 | G19: =+IFERROR(F19/F$19,"") -> 1 | H19: =+D19-F19 -> -10034.51 | I19: =+SUM(I15:I18) -> 1319405.1 | J19: =+IFERROR(I19/I$19,"") -> 1 | K19: =+(D19-I19) -> 189413.4 | M19: =+SUM(M15:M18) -> 6289245.5 | N19: =+IFERROR(M19/M$19,"") -> 1 | O19: =+SUM(O15:O18) -> 6764432.3 | P19: =+IFERROR(O19/O$19,"") -> 1 | Q19: =+M19-O19 -> -475186.75 | R19: =+SUM(R15:R18) -> 5864604.7 | S19: =+IFERROR(R19/R$19,"") -> 1 | T19: =+(M19-R19) -> 424640.83
E20: TRUE | G20: TRUE | J20: TRUE | N20: TRUE | P20: TRUE | S20: TRUE
C21: Departmental Expense
B22: Total Departmental Expenses - 100 | C22: Rooms | D22: 278444.2 | E22: =+IFERROR(D22/D15,"") -> 0.28353935 | F22: 245118.34 | G22: =+IFERROR(F22/F15,"") -> 0.25548961 | H22: =+D22-F22 -> 33325.86 | I22: 261858.86 | J22: =+IFERROR(I22/I15,"") -> 0.27443128 | K22: =+(D22-I22) -> 16585.34 | M22: 1048369.3 | N22: =+IFERROR(M22/M15,"") -> 0.24372082 | O22: 1019678.2 | P22: =+IFERROR(O22/O15,"") -> 0.22805465 | Q22: =+M22-O22 -> 28691.08 | R22: 1030793.9 | S22: =+IFERROR(R22/R15,"") -> 0.23226638 | T22: =+(M22-R22) -> 17575.33
B23: Total Departmental Expenses - 200 | C23: Food & Beverage | D23: 291396.9 | E23: =+IFERROR(D23/D16,"") -> 0.76858971 | F23: 298555.95 | G23: =+IFERROR(F23/F16,"") -> 0.68224854 | H23: =+D23-F23 -> -7159.054 | I23: 228871.12 | J23: =+IFERROR(I23/I16,"") -> 0.91194246 | K23: =+(D23-I23) -> 62525.78 | M23: 1080000.5 | N23: =+IFERROR(M23/M16,"") -> 0.70867763 | O23: 1223767.9 | P23: =+IFERROR(O23/O16,"") -> 0.68264185 | Q23: =+M23-O23 -> -143767.48 | R23: 774579.62 | S23: =+IFERROR(R23/R16,"") -> 0.84506595 | T23: =+(M23-R23) -> 305420.85
B24: Total Departmental Expenses - 300 | C24: Other Operated Departments | D24: 1105.98 | E24: =+IFERROR(D24/D17,"") -> 0.37510684 | F24: 531.38 | G24: =+IFERROR(F24/F17,"") -> 0.34109393 | H24: =+D24-F24 -> 574.6 | I24: 642.24 | J24: =+IFERROR(I24/I17,"") -> 0.4394239 | K24: =+(D24-I24) -> 463.74 | M24: 5073 | N24: =+IFERROR(M24/M17,"") -> 0.51376626 | O24: 2123.05 | P24: =+IFERROR(O24/O17,"") -> 0.34109495 | Q24: =+M24-O24 -> 2949.95 | R24: 2321.77 | S24: =+IFERROR(R24/R17,"") -> 0.32216602 | T24: =+(M24-R24) -> 2751.23
B25: Total Departmental Expenses - 000 | C25: Total Departmental Expense | D25: =+SUM(D22:D24) -> 570947.08 | E25: =+IFERROR(D25/D$19,"") -> 0.37840673 | F25: =+SUM(F22:F24) -> 544205.67 | G25: =+IFERROR(F25/F$19,"") -> 0.35830042 | H25: =+D25-F25 -> 26741.406 | I25: =+SUM(I22:I24) -> 491372.22 | J25: =+IFERROR(I25/I$19,"") -> 0.37241952 | K25: =+(D25-I25) -> 79574.86 | M25: =+SUM(M22:M24) -> 2133442.7 | N25: =+IFERROR(M25/M$19,"") -> 0.33922077 | O25: =+SUM(O22:O24) -> 2245569.2 | P25: =+IFERROR(O25/O$19,"") -> 0.33196713 | Q25: =+M25-O25 -> -112126.45 | R25: =+SUM(R22:R24) -> 1807695.3 | S25: =+IFERROR(R25/R$19,"") -> 0.30823822 | T25: =+(M25-R25) -> 325747.41
C27: Total Departmental Profit | D27: =+D19-D25 -> 937871.42 | E27: =+IFERROR(D27/D$19,"") -> 0.62159327 | F27: =+F19-F25 -> 974647.34 | G27: =+IFERROR(F27/F$19,"") -> 0.64169958 | H27: =+D27-F27 -> -36775.916 | I27: =+I19-I25 -> 828032.88 | J27: =+IFERROR(I27/I$19,"") -> 0.62758048 | K27: =+(D27-I27) -> 109838.54 | M27: =+M19-M25 -> 4155802.8 | N27: =+IFERROR(M27/M$19,"") -> 0.66077923 | O27: =+O19-O25 -> 4518863.1 | P27: =+IFERROR(O27/O$19,"") -> 0.66803287 | Q27: =+M27-O27 -> -363060.3 | R27: =+R19-R25 -> 4056909.4 | S27: =+IFERROR(R27/R$19,"") -> 0.69176178 | T27: =+(M27-R27) -> 98893.42
E28: TRUE | G28: TRUE | J28: TRUE | N28: TRUE | P28: TRUE | S28: TRUE
C29: Undistributed Expenses
B30: Total Departmental Expenses - 500 | C30: Administrative & General | D30: 133968.94 | E30: =+IFERROR(D30/D$19,"") -> 0.088790627 | F30: 138401.36 | G30: =+IFERROR(F30/F$19,"") -> 0.091122285 | H30: =+D30-F30 -> -4432.4168 | I30: 118161.63 | J30: =+IFERROR(I30/I$19,"") -> 0.089556748 | K30: =+(D30-I30) -> 15807.31 | M30: 495671.28 | N30: =+IFERROR(M30/M$19,"") -> 0.078812519 | O30: 544392.4 | P30: =+IFERROR(O30/O$19,"") -> 0.080478653 | Q30: =+M30-O30 -> -48721.121 | R30: 457549.71 | S30: =+IFERROR(R30/R$19,"") -> 0.078018849 | T30: =+(M30-R30) -> 38121.57
B31: Total Departmental Expenses - 600 | C31: Information & Telecom Systems | D31: 16160.83 | E31: =+IFERROR(D31/D$19,"") -> 0.010710917 | F31: 15681.7 | G31: =+IFERROR(F31/F$19,"") -> 0.010324699 | H31: =+D31-F31 -> 479.13 | I31: 15829.8 | J31: =+IFERROR(I31/I$19,"") -> 0.01199768 | K31: =+(D31-I31) -> 331.03 | M31: 80361.22 | N31: =+IFERROR(M31/M$19,"") -> 0.012777561 | O31: 79636.02 | P31: =+IFERROR(O31/O$19,"") -> 0.011772757 | Q31: =+M31-O31 -> 725.2 | R31: 78045.46 | S31: =+IFERROR(R31/R$19,"") -> 0.013307881 | T31: =+(M31-R31) -> 2315.76
B32: Total Departmental Expenses - 700 | C32: Sales & Marketing | D32: 88393.96 | E32: =+IFERROR(D32/D$19,"") -> 0.058584886 | F32: 104759.66 | G32: =+IFERROR(F32/F$19,"") -> 0.068972876 | H32: =+D32-F32 -> -16365.7 | I32: 115727.72 | J32: =+IFERROR(I32/I$19,"") -> 0.087712045 | K32: =+(D32-I32) -> -27333.76 | M32: 381980.89 | N32: =+IFERROR(M32/M$19,"") -> 0.060735566 | O32: 470940.58 | P32: =+IFERROR(O32/O$19,"") -> 0.069620119 | Q32: =+M32-O32 -> -88959.69 | R32: 417390.76 | S32: =+IFERROR(R32/R$19,"") -> 0.071171167 | T32: =+(M32-R32) -> -35409.87
B33: Total Departmental Expenses - 800 | C33: ANGBF Operation & Maintenance | D33: 57358.85 | E33: =+IFERROR(D33/D$19,"") -> 0.038015739 | F33: 65333.87 | G33: =+IFERROR(F33/F$19,"") -> 0.043015268 | H33: =+D33-F33 -> -7975.0199 | I33: 37576.64 | J33: =+IFERROR(I33/I$19,"") -> 0.028479987 | K33: =+(D33-I33) -> 19782.21 | M33: 220794.79 | N33: =+IFERROR(M33/M$19,"") -> 0.035106721 | O33: 267358.96 | P33: =+IFERROR(O33/O$19,"") -> 0.039524228 | Q33: =+M33-O33 -> -46564.174 | R33: 225470.27 | S33: =+IFERROR(R33/R$19,"") -> 0.038445945 | T33: =+(M33-R33) -> -4675.48
B34: Total Utilities Expense - 810 | C34: Utilities | D34: 24121.87 | E34: =+IFERROR(D34/D$19,"") -> 0.015987258 | F34: 23162.39 | G34: =+IFERROR(F34/F$19,"") -> 0.015249922 | H34: =+D34-F34 -> 959.48 | I34: 25806.47 | J34: =+IFERROR(I34/I$19,"") -> 0.019559171 | K34: =+(D34-I34) -> -1684.6 | M34: 93445.37 | N34: =+IFERROR(M34/M$19,"") -> 0.014857962 | O34: 90217.04 | P34: =+IFERROR(O34/O$19,"") -> 0.013336971 | Q34: =+M34-O34 -> 3228.33 | R34: 95974.61 | S34: =+IFERROR(R34/R$19,"") -> 0.01636506 | T34: =+(M34-R34) -> -2529.24
B35: Total Undistributed Expenses - 000 | C35: Total Undistributed Expenses | D35: =+SUM(D30:D34) -> 320004.45 | E35: =+IFERROR(D35/D$19,"") -> 0.21208943 | F35: =+SUM(F30:F34) -> 347338.98 | G35: =+IFERROR(F35/F$19,"") -> 0.22868505 | H35: =+D35-F35 -> -27334.527 | I35: =+SUM(I30:I34) -> 313102.26 | J35: =+IFERROR(I35/I$19,"") -> 0.23730563 | K35: =+(D35-I35) -> 6902.19 | M35: =+SUM(M30:M34) -> 1272253.5 | N35: =+IFERROR(M35/M$19,"") -> 0.20229033 | O35: =+SUM(O30:O34) -> 1452545 | P35: =+IFERROR(O35/O$19,"") -> 0.21473273 | Q35: =+M35-O35 -> -180291.45 | R35: =+SUM(R30:R34) -> 1274430.8 | S35: =+IFERROR(R35/R$19,"") -> 0.2173089 | T35: =+(M35-R35) -> -2177.26
B37: Total Hotel GOP - 000 | C37: Gross Operating Profit | D37: =+D27-D35 -> 617866.97 | E37: =+IFERROR(D37/D$19,"") -> 0.40950384 | F37: =+F27-F35 -> 627308.36 | G37: =+IFERROR(F37/F$19,"") -> 0.41301453 | H37: =+D37-F37 -> -9441.3894 | I37: =+I27-I35 -> 514930.62 | J37: =+IFERROR(I37/I$19,"") -> 0.39027484 | K37: =+(D37-I37) -> 102936.35 | M37: =+M27-M35 -> 2883549.2 | N37: =+IFERROR(M37/M$19,"") -> 0.4584889 | O37: =+O27-O35 -> 3066318.1 | P37: =+IFERROR(O37/O$19,"") -> 0.45330014 | Q37: =+M37-O37 -> -182768.85 | R37: =+R27-R35 -> 2782478.6 | S37: =+IFERROR(R37/R$19,"") -> 0.47445287 | T37: =+(M37-R37) -> 101070.68
B39: Total Management Fees - 920 | C39: Management Fees | D39: 68430.22 | E39: =+IFERROR(D39/D$19,"") -> 0.045353513 | F39: 70783.77 | G39: =+IFERROR(F39/F$19,"") -> 0.046603437 | H39: =+D39-F39 -> -2353.55 | I39: 56917.53 | J39: =+IFERROR(I39/I$19,"") -> 0.043138783 | K39: =+(D39-I39) -> 11512.69 | M39: 273972.26 | N39: =+IFERROR(M39/M$19,"") -> 0.043562023 | O39: 306966.13 | P39: =+IFERROR(O39/O$19,"") -> 0.045379437 | Q39: =+M39-O39 -> -32993.87 | R39: 243369.3 | S39: =+IFERROR(R39/R$19,"") -> 0.041497989 | T39: =+(M39-R39) -> 30602.96
C40: Income before non-operating inc & expense | D40: =+D37-D39 -> 549436.75 | E40: =+IFERROR(D40/D$19,"") -> 0.36415033 | F40: =+F37-F39 -> 556524.59 | G40: =+IFERROR(F40/F$19,"") -> 0.36641109 | H40: =+D40-F40 -> -7087.8394 | I40: =+I37-I39 -> 458013.09 | J40: =+IFERROR(I40/I$19,"") -> 0.34713606 | K40: =+(D40-I40) -> 91423.66 | M40: =+M37-M39 -> 2609577 | N40: =+IFERROR(M40/M$19,"") -> 0.41492687 | O40: =+O37-O39 -> 2759352 | P40: =+IFERROR(O40/O$19,"") -> 0.4079207 | Q40: =+M40-O40 -> -149774.98 | R40: =+R37-R39 -> 2539109.3 | S40: =+IFERROR(R40/R$19,"") -> 0.43295489 | T40: =+(M40-R40) -> 70467.72
E41: TRUE | G41: TRUE | J41: TRUE | N41: TRUE | P41: TRUE | S41: TRUE
C42: Non-Operating Income & Expenses
B43: Total Non-Operating Income - 900 | C43: Income | D43: 1631.67 | E43: =+IFERROR(D43/D$19,"") -> 0.0010814223 | F43: 2031 | G43: =+IFERROR(F43/F$19,"") -> 0.0013371933 | H43: =+D43-F43 -> -399.33 | I43: 1967.65 | J43: =+IFERROR(I43/I$19,"") -> 0.001491316 | K43: =+(D43-I43) -> -335.98 | M43: 9884.92 | N43: =+IFERROR(M43/M$19,"") -> 0.0015717179 | O43: 8124 | P43: =+IFERROR(O43/O$19,"") -> 0.0012009877 | Q43: =+M43-O43 -> 1760.92 | R43: 7748.25 | S43: =+IFERROR(R43/R$19,"") -> 0.0013211888 | T43: =+(M43-R43) -> 2136.67
B44: Total Rent - 900 | C44: Rent | D44: 277.09 | E44: =+IFERROR(D44/D$19,"") -> 0.00018364701 | F44: 1100.5 | G44: =+IFERROR(F44/F$19,"") -> 0.00072455991 | H44: =+D44-F44 -> -823.41 | I44: -196.17 | J44: =+IFERROR(I44/I$19,"") -> -0.00014868064 | K44: =+(D44-I44) -> 473.26 | M44: 3931.72 | N44: =+IFERROR(M44/M$19,"") -> 0.00062514971 | O44: 4615 | P44: =+IFERROR(O44/O$19,"") -> 0.00068224499 | Q44: =+M44-O44 -> -683.28 | R44: 4172.12 | S44: =+IFERROR(R44/R$19,"") -> 0.00071140686 | T44: =+(M44-R44) -> -240.4
...

Sheet Rooms
V1: ANG
C2: =+Summary!$C$2 -> Angler's | V2: Apr
C3: =+Summary!$C$3 -> STATEMENT OF INCOME
C4: =+Summary!$C$4 -> FOR THE PERIOD ENDING APR 2025
D6: =Year&" "&UPPER(Month)&" - PERIODIC" -> 2025 APR - PERIODIC | M6: =Year&" "&UPPER(Month)&" - YEAR TO DATE" -> 2025 APR - YEAR TO DATE
D7: Actual | F7: Budget | H7: VARIANCE | I7: Actual - Last Year | K7: VARIANCE | M7: Actual | O7: Budget | Q7: VARIANCE | R7: Actual - Last Year | T7: VARIANCE
D8: $ | E8: % | F8: $ | G8: % | H8: $ | I8: Actual | J8: % | K8: $ | M8: $ | N8: % | O8: $ | P8: % | Q8: $ | R8: Actual | S8: % | T8: $
C9: Revenues
C10: Transient Rooms Revenue
B11: Transient Retail - 100 | C11: Retail | D11: 403851.73 | E11: =IFERROR(D11/D$31,"") -> 0.41124166 | F11: 339220 | G11: =IFERROR(F11/F$31,"") -> 0.35357283 | H11: =+D11-F11 -> 64631.73 | I11: 337486.78 | J11: =IFERROR(I11/I$31,"") -> 0.35369026 | K11: =+D11-I11 -> 66364.95 | M11: 1422080.2 | N11: =IFERROR(M11/M$31,"") -> 0.33059969 | O11: 1637641.7 | P11: =IFERROR(O11/O$31,"") -> 0.36626438 | Q11: =+M11-O11 -> -215561.46 | R11: 1558853.7 | S11: =IFERROR(R11/R$31,"") -> 0.35125284 | T11: =+M11-R11 -> -136773.42
B12: Transient Discount - 100 | C12: Discount | D12: 341627.81 | E12: =IFERROR(D12/D$31,"") -> 0.34787913 | F12: 433204.3 | G12: =IFERROR(F12/F$31,"") -> 0.45153373 | H12: =+D12-F12 -> -91576.49 | I12: 425759.58 | J12: =IFERROR(I12/I$31,"") -> 0.44620123 | K12: =+D12-I12 -> -84131.77 | M12: 1630075.8 | N12: =IFERROR(M12/M$31,"") -> 0.3789537 | O12: 1587492.8 | P12: =IFERROR(O12/O$31,"") -> 0.35504841 | Q12: =+M12-O12 -> 42583.02 | R12: 1572469.1 | S12: =IFERROR(R12/R$31,"") -> 0.35432079 | T12: =+M12-R12 -> 57606.7
B13: Transient Negotiated - 100 | C13: Negotiated | D13: 38606.91 | E13: =IFERROR(D13/D$31,"") -> 0.039313364 | F13: 28728.9 | G13: =IFERROR(F13/F$31,"") -> 0.029944457 | H13: =+D13-F13 -> 9878.01 | I13: 23549.12 | J13: =IFERROR(I13/I$31,"") -> 0.024679765 | K13: =+D13-I13 -> 15057.79 | M13: 171189.25 | N13: =IFERROR(M13/M$31,"") -> 0.039797412 | O13: 194782.3 | P13: =IFERROR(O13/O$31,"") -> 0.043563753 | Q13: =+M13-O13 -> -23593.05 | R13: 272607.32 | S13: =IFERROR(R13/R$31,"") -> 0.061425969 | T13: =+M13-R13 -> -101418.07
B14: Transient Qualified - 100 | C14: Qualified | D14: 24633.45 | E14: =IFERROR(D14/D$31,"") -> 0.025084208 | F14: 28222.09 | G14: =IFERROR(F14/F$31,"") -> 0.029416203 | H14: =+D14-F14 -> -3588.64 | I14: 35901.32 | J14: =IFERROR(I14/I$31,"") -> 0.037625021 | K14: =+D14-I14 -> -11267.87 | M14: 95191.05 | N14: =IFERROR(M14/M$31,"") -> 0.022129646 | O14: 104260.69 | P14: =IFERROR(O14/O$31,"") -> 0.023318274 | Q14: =+M14-O14 -> -9069.64 | R14: 129886.92 | S14: =IFERROR(R14/R$31,"") -> 0.029267115 | T14: =+M14-R14 -> -34695.87
B15: Transient Wholesale - 100 | C15: Wholesale | D15: 53616.2 | E15: =IFERROR(D15/D$31,"") -> 0.054597303 | F15: 82110 | G15: =IFERROR(F15/F$31,"") -> 0.085584179 | H15: =+D15-F15 -> -28493.8 | I15: 91534.72 | J15: =IFERROR(I15/I$31,"") -> 0.095929503 | K15: =+D15-I15 -> -37918.52 | M15: 217306.6 | N15: =IFERROR(M15/M$31,"") -> 0.050518594 | O15: 304824.8 | P15: =IFERROR(O15/O$31,"") -> 0.068175149 | Q15: =+M15-O15 -> -87518.2 | R15: 302662.4 | S15: =IFERROR(R15/R$31,"") -> 0.068198209 | T15: =+M15-R15 -> -85355.8
B16: Transient Rebates and Subsidies - 100 | C16: Rebates | D16: 0 | E16: =IFERROR(D16/D$31,"") -> 0 | F16: 0 | G16: =IFERROR(F16/F$31,"") -> 0 | H16: =+D16-F16 -> 0 | I16: 0 | J16: =IFERROR(I16/I$31,"") -> 0 | K16: =+D16-I16 -> 0 | M16: 0 | N16: =IFERROR(M16/M$31,"") -> 0 | O16: 0 | P16: =IFERROR(O16/O$31,"") -> 0 | Q16: =+M16-O16 -> 0 | R16: 0 | S16: =IFERROR(R16/R$31,"") -> 0 | T16: =+M16-R16 -> 0
B17: Transient Rooms Revenue - 100 | C17: Total Transient Room Rev | D17: =SUM(D11:D16) -> 862336.1 | E17: =IFERROR(D17/D$31,"") -> 0.87811567 | F17: =SUM(F11:F16) -> 911485.29 | G17: =IFERROR(F17/F$31,"") -> 0.9500514 | H17: =+D17-F17 -> -49149.19 | I17: =SUM(I11:I16) -> 914231.52 | J17: =IFERROR(I17/I$31,"") -> 0.95812578 | K17: =+D17-I17 -> -51895.42 | M17: =SUM(M11:M16) -> 3535843 | N17: =IFERROR(M17/M$31,"") -> 0.82199904 | O17: =SUM(O11:O16) -> 3829002.3 | P17: =IFERROR(O17/O$31,"") -> 0.85636997 | Q17: =+M17-O17 -> -293159.33 | R17: =SUM(R11:R16) -> 3836479.4 | S17: =IFERROR(R17/R$31,"") -> 0.86446492 | T17: =+M17-R17 -> -300636.46
C19: Group Rooms Revenue
B20: Group Corporate - 100 | C20: Corporate | D20: 69181.6 | E20: =IFERROR(D20/D$31,"") -> 0.070447529 | F20: 38440 | G20: =IFERROR(F20/F$31,"") -> 0.040066446 | H20: =+D20-F20 -> 30741.6 | I20: 25733 | J20: =IFERROR(I20/I$31,"") -> 0.026968498 | K20: =+D20-I20 -> 43448.6 | M20: 623870.28 | N20: =IFERROR(M20/M$31,"") -> 0.14503494 | O20: 563653.26 | P20: =IFERROR(O20/O$31,"") -> 0.12606305 | Q20: =+M20-O20 -> 60217.02 | R20: 545977 | S20: =IFERROR(R20/R$31,"") -> 0.12302372 | T20: =+M20-R20 -> 77893.28
B21: Group Association/Convention - 100 | C21: Association/Convention | D21: 50749 | E21: =IFERROR(D21/D$31,"") -> 0.051677637 | F21: 0 | G21: =IFERROR(F21/F$31,"") -> 0 | H21: =+D21-F21 -> 50749 | I21: 0.05 | J21: =IFERROR(I21/I$31,"") -> 5.240061e-08 | K21: =+D21-I21 -> 50748.95 | M21: 101354.42 | N21: =IFERROR(M21/M$31,"") -> 0.023562482 | O21: 28090.56 | P21: =IFERROR(O21/O$31,"") -> 0.0062825535 | Q21: =+M21-O21 -> 73263.86 | R21: 8802.7 | S21: =IFERROR(R21/R$31,"") -> 0.0019834918 | T21: =+M21-R21 -> 92551.72
B22: Group Government - 100 | C22: Government | D22: 0 | E22: =IFERROR(D22/D$31,"") -> 0 | F22: 0 | G22: =IFERROR(F22/F$31,"") -> 0 | H22: =+D22-F22 -> 0 | I22: 0 | J22: =IFERROR(I22/I$31,"") -> 0 | K22: =+D22-I22 -> 0 | M22: 0 | N22: =IFERROR(M22/M$31,"") -> 0 | O22: 0 | P22: =IFERROR(O22/O$31,"") -> 0 | Q22: =+M22-O22 -> 0 | R22: 0 | S22: =IFERROR(R22/R$31,"") -> 0 | T22: =+M22-R22 -> 0
B23: Group Tour/Wholesalers - 100 | C23: Tour/Wholesalers | D23: 0 | E23: =IFERROR(D23/D$31,"") -> 0 | F23: 0 | G23: =IFERROR(F23/F$31,"") -> 0 | H23: =+D23-F23 -> 0 | I23: 0 | J23: =IFERROR(I23/I$31,"") -> 0 | K23: =+D23-I23 -> 0 | M23: 2640 | N23: =IFERROR(M23/M$31,"") -> 0.00061373695 | O23: 6077.94 | P23: =IFERROR(O23/O$31,"") -> 0.0013593529 | Q23: =+M23-O23 -> -3437.94 | R23: 6229 | S23: =IFERROR(R23/R$31,"") -> 0.001403566 | T23: =+M23-R23 -> -3589
B24: Group SMERF - 100 | C24: SMERF | D24: -0.02 | E24: =IFERROR(D24/D$31,"") -> -2.0365973e-08 | F24: 5980 | G24: =IFERROR(F24/F$31,"") -> 0.0062330215 | H24: =+D24-F24 -> -5980.02 | I24: 10825 | J24: =IFERROR(I24/I$31,"") -> 0.011344732 | K24: =+D24-I24 -> -10825.02 | M24: 19434.98 | N24: =IFERROR(M24/M$31,"") -> 0.0045181687 | O24: 13815 | P24: =IFERROR(O24/O$31,"") -> 0.0030897738 | Q24: =+M24-O24 -> 5619.98 | R24: 10825 | S24: =IFERROR(R24/R$31,"") -> 0.0024391719 | T24: =+M24-R24 -> 8609.98
B25: Group Other - 100 | C25: Other Group | D25: 0 | E25: =IFERROR(D25/D$31,"") -> 0 | F25: 0 | G25: =IFERROR(F25/F$31,"") -> 0 | H25: =+D25-F25 -> 0 | I25: 0 | J25: =IFERROR(I25/I$31,"") -> 0 | K25: =+D25-I25 -> 0 | M25: 0 | N25: =IFERROR(M25/M$31,"") -> 0 | O25: 0 | P25: =IFERROR(O25/O$31,"") -> 0 | Q25: =+M25-O25 -> 0 | R25: 0 | S25: =IFERROR(R25/R$31,"") -> 0 | T25: =+M25-R25 -> 0
B26: Group Rebates and Subsidies - 100 | C26: Group Rebates | D26: 0 | E26: =IFERROR(D26/D$31,"") -> 0 | F26: 0 | G26: =IFERROR(F26/F$31,"") -> 0 | H26: =+D26-F26 -> 0 | I26: 0 | J26: =IFERROR(I26/I$31,"") -> 0 | K26: =+D26-I26 -> 0 | M26: 0 | N26: =IFERROR(M26/M$31,"") -> 0 | O26: 0 | P26: =IFERROR(O26/O$31,"") -> 0 | Q26: =+M26-O26 -> 0 | R26: 0 | S26: =IFERROR(R26/R$31,"") -> 0 | T26: =+M26-R26 -> 0
B27: Group Rooms Revenue - 100 | C27: Total Group Room Rev | D27: =SUM(D20:D26) -> 119930.58 | E27: =IFERROR(D27/D$31,"") -> 0.12212515 | F27: =SUM(F20:F26) -> 44420 | G27: =IFERROR(F27/F$31,"") -> 0.046299467 | H27: =+D27-F27 -> 75510.58 | I27: =SUM(I20:I26) -> 36558.05 | J27: =IFERROR(I27/I$31,"") -> 0.038313282 | K27: =+D27-I27 -> 83372.53 | M27: =SUM(M20:M26) -> 747299.68 | N27: =IFERROR(M27/M$31,"") -> 0.17372933 | O27: =SUM(O20:O26) -> 611636.76 | P27: =IFERROR(O27/O$31,"") -> 0.13679473 | Q27: =+M27-O27 -> 135662.92 | R27: =SUM(R20:R26) -> 571833.7 | S27: =IFERROR(R27/R$31,"") -> 0.12884995 | T27: =+M27-R27 -> 175465.98
B28: Contract Rooms Revenue - 100 | C28: Contract Rooms Revenue | D28: 0 | E28: =IFERROR(D28/D$31,"") -> 0 | F28: 0 | G28: =IFERROR(F28/F$31,"") -> 0 | H28: =+D28-F28 -> 0 | I28: 0 | J28: =IFERROR(I28/I$31,"") -> 0 | K28: =+D28-I28 -> 0 | M28: 0 | N28: =IFERROR(M28/M$31,"") -> 0 | O28: 0 | P28: =IFERROR(O28/O$31,"") -> 0 | Q28: =+M28-O28 -> 0 | R28: 0 | S28: =IFERROR(R28/R$31,"") -> 0 | T28: =+M28-R28 -> 0
B29: Other Rooms Revenue - 100 | C29: Other Rooms Revenue | D29: -236.49 | E29: =IFERROR(D29/D$31,"") -> -0.00024081744 | F29: 3501 | G29: =IFERROR(F29/F$31,"") -> 0.0036491318 | H29: =+D29-F29 -> -3737.49 | I29: 5024.12 | J29: =IFERROR(I29/I$31,"") -> 0.005265339 | K29: =+D29-I29 -> -5260.61 | M29: 18374.49 | N29: =IFERROR(M29/M$31,"") -> 0.0042716301 | O29: 30562 | P29: =IFERROR(O29/O$31,"") -> 0.0068352998 | Q29: =+M29-O29 -> -12187.51 | R29: 35119.86 | S29: =IFERROR(R29/R$31,"") -> 0.0079134757 | T29: =+M29-R29 -> -16745.37
B30: Allowances - 100 | C30: Rooms: Allowances | D30: 0 | E30: =IFERROR(D30/D$31,"") -> 0 | F30: 0 | G30: =IFERROR(F30/F$31,"") -> 0 | H30: =+D30-F30 -> 0 | I30: -1626.32 | J30: =IFERROR(I30/I$31,"") -> -0.0017044032 | K30: =+D30-I30 -> 1626.32 | M30: 0 | N30: =IFERROR(M30/M$31,"") -> 0 | O30: 0 | P30: =IFERROR(O30/O$31,"") -> 0 | Q30: =+M30-O30 -> 0 | R30: -5451.37 | S30: =IFERROR(R30/R$31,"") -> -0.0012283444 | T30: =+M30-R30 -> 5451.37
B31: Total Revenue - 100 | C31: Total Rooms Revenue | D31: =+D17+D27+SUM(D28:D30) -> 982030.19 | E31: =IFERROR(D31/D$31,"") -> 1 | F31: =+F17+F27+SUM(F28:F30) -> 959406.29 | G31: =IFERROR(F31/F$31,"") -> 1 | H31: =+D31-F31 -> 22623.9 | I31: =+I17+I27+SUM(I28:I30) -> 954187.37 | J31: =IFERROR(I31/I$31,"") -> 1 | K31: =+D31-I31 -> 27842.82 | M31: =+M17+M27+SUM(M28:M30) -> 4301517.2 | N31: =IFERROR(M31/M$31,"") -> 1 | O31: =+O17+O27+SUM(O28:O30) -> 4471201.1 | P31: =IFERROR(O31/O$31,"") -> 1 | Q31: =+M31-O31 -> -169683.92 | R31: =+R17+R27+SUM(R28:R30) -> 4437981.6 | S31: =IFERROR(R31/R$31,"") -> 1 | T31: =+M31-R31 -> -136464.48
C33: Labor & Related Expenses
B34: S&W Management - 100 | C34: Salaries & Wages
B35: Housekeeping Management Reg S&W - 100 | C35: Housekeeping Mgmt | D35: 0 | E35: =IFERROR(D35/D$31,"") -> 0 | F35: 0 | G35: =IFERROR(F35/F$31,"") -> 0 | H35: =+D35-F35 -> 0 | I35: 0 | J35: =IFERROR(I35/I$31,"") -> 0 | K35: =+D35-I35 -> 0 | M35: 0 | N35: =IFERROR(M35/M$31,"") -> 0 | O35: 0 | P35: =IFERROR(O35/O$31,"") -> 0 | Q35: =+M35-O35 -> 0 | R35: 0 | S35: =IFERROR(R35/R$31,"") -> 0 | T35: =+M35-R35 -> 0
B36: Front Desk Management Reg S&W - 100 | C36: Front Desk Mgmt | D36: 0 | E36: =IFERROR(D36/D$31,"") -> 0 | F36: 0 | G36: =IFERROR(F36/F$31,"") -> 0 | H36: =+D36-F36 -> 0 | I36: 0 | J36: =IFERROR(I36/I$31,"") -> 0 | K36: =+D36-I36 -> 0 | M36: 0 | N36: =IFERROR(M36/M$31,"") -> 0 | O36: 0 | P36: =IFERROR(O36/O$31,"") -> 0 | Q36: =+M36-O36 -> 0 | R36: 0 | S36: =IFERROR(R36/R$31,"") -> 0 | T36: =+M36-R36 -> 0
B37: Unassigned Management Reg S&W - 100 | C37: Management | D37: 13751.46 | E37: =IFERROR(D37/D$31,"") -> 0.014003093 | F37: 12527.78 | G37: =IFERROR(F37/F$31,"") -> 0.013057846 | H37: =+D37-F37 -> 1223.68 | I37: 12785.27 | J37: =IFERROR(I37/I$31,"") -> 0.013399119 | K37: =+D37-I37 -> 966.19 | M37: 48557.38 | N37: =IFERROR(M37/M$31,"") -> 0.011288431 | O37: 47981.36 | P37: =IFERROR(O37/O$31,"") -> 0.010731202 | Q37: =+M37-O37 -> 576.02 | R37: 34728.11 | S37: =IFERROR(R37/R$31,"") -> 0.0078252036 | T37: =+M37-R37 -> 13829.27
B38: S&W Non-Management - 100 | C38: Non-Management
B39: Front Desk Reg S&W - 100 | C39: Front Office | D39: 14600.75 | E39: =IFERROR(D39/D$31,"") -> 0.014867924 | F39: 17168.31 | G39: =IFERROR(F39/F$31,"") -> 0.017894723 | H39: =+D39-F39 -> -2567.56 | I39: 14397.6 | J39: =IFERROR(I39/I$31,"") -> 0.01508886 | K39: =+D39-I39 -> 203.15 | M39: 53276.41 | N39: =IFERROR(M39/M$31,"") -> 0.012385493 | O39: 67417.02 | P39: =IFERROR(O39/O$31,"") -> 0.015078056 | Q39: =+M39-O39 -> -14140.61 | R39: 37882.2 | S39: =IFERROR(R39/R$31,"") -> 0.0085359073 | T39: =+M39-R39 -> 15394.21
B40: Housekeeping Reg S&W - 100 | C40: Housekeeping | D40: 43562.57 | E40: =IFERROR(D40/D$31,"") -> 0.044359705 | F40: 46054.89 | G40: =IFERROR(F40/F$31,"") -> 0.048003531 | H40: =+D40-F40 -> -2492.32 | I40: 44186.67 | J40: =IFERROR(I40/I$31,"") -> 0.046308169 | K40: =+D40-I40 -> -624.1 | M40: 174126.5 | N40: =IFERROR(M40/M$31,"") -> 0.040480252 | O40: 180684.69 | P40: =IFERROR(O40/O$31,"") -> 0.040410773 | Q40: =+M40-O40 -> -6558.19 | R40: 150761.34 | S40: =IFERROR(R40/R$31,"") -> 0.033970699 | T40: =+M40-R40 -> 23365.16
B41: Reservations Reg S&W - 100 | C41: Reservations | D41: 0 | E41: =IFERROR(D41/D$31,"") -> 0 | F41: 0 | G41: =IFERROR(F41/F$31,"") -> 0 | H41: =+D41-F41 -> 0 | I41: 0 | J41: =IFERROR(I41/I$31,"") -> 0 | K41: =+D41-I41 -> 0 | M41: 0 | N41: =IFERROR(M41/M$31,"") -> 0 | O41: 0 | P41: =IFERROR(O41/O$31,"") -> 0 | Q41: =+M41-O41 -> 0 | R41: 0 | S41: =IFERROR(R41/R$31,"") -> 0 | T41: =+M41-R41 -> 0
B42: Comp F&B Reg S&W - 100 | C42: Comp F&B | D42: 0 | E42: =IFERROR(D42/D$31,"") -> 0 | F42: 0 | G42: =IFERROR(F42/F$31,"") -> 0 | H42: =+D42-F42 -> 0 | I42: 0 | J42: =IFERROR(I42/I$31,"") -> 0 | K42: =+D42-I42 -> 0 | M42: 0 | N42: =IFERROR(M42/M$31,"") -> 0 | O42: 0 | P42: =IFERROR(O42/O$31,"") -> 0 | Q42: =+M42-O42 -> 0 | R42: 0 | S42: =IFERROR(R42/R$31,"") -> 0 | T42: =+M42-R42 -> 0
B43: Rooms Unassigned Reg S&W - 100 | C43: Unassigned | D43: 0 | E43: =IFERROR(D43/D$31,"") -> 0 | F43: 0 | G43: =IFERROR(F43/F$31,"") -> 0 | H43: =+D43-F43 -> 0 | I43: 0 | J43: =IFERROR(I43/I$31,"") -> 0 | K43: =+D43-I43 -> 0 | M43: 0 | N43: =IFERROR(M43/M$31,"") -> 0 | O43: 0 | P43: =IFERROR(O43/O$31,"") -> 0 | Q43: =+M43-O43 -> 0 | R43: 0 | S43: =IFERROR(R43/R$31,"") -> 0 | T43: =+M43-R43 -> 0
...

Sheet F&B_CONS
V1: ANG
C2: =+Summary!$C$2 -> Angler's | V2: Apr
C3: =+Summary!$C$3 -> STATEMENT OF INCOME
C4: =+Summary!$C$4 -> FOR THE PERIOD ENDING APR 2025
D6: =Year&" "&UPPER(Month)&" - PERIODIC" -> 2025 APR - PERIODIC | M6: =Year&" "&UPPER(Month)&" - YEAR TO DATE" -> 2025 APR - YEAR TO DATE
D7: Actual | F7: Budget | H7: VARIANCE | I7: Actual - Last Year | K7: VARIANCE | M7: Actual | O7: Budget | Q7: VARIANCE | R7: Actual - Last Year | T7: VARIANCE
D8: $ | E8: % | F8: $ | G8: % | H8: $ | I8: Actual | J8: % | K8: $ | M8: $ | N8: % | O8: $ | P8: % | Q8: $ | R8: Actual | S8: % | T8: $
C9: Revenues
C10: Food Revenue
B11: Venues Food - 200 | C11: Venues Food Rev | D11: 226705.51 | E11: =IFERROR(D11/D$35,"") -> 0.59795942 | F11: 219945 | G11: =IFERROR(F11/F$35,"") -> 0.50260983 | H11: =+D11-F11 -> 6760.51 | I11: 133831.43 | J11: =IFERROR(I11/I$35,"") -> 0.53325454 | K11: =+D11-I11 -> 92874.08 | M11: 905806.53 | N11: =IFERROR(M11/M$35,"") -> 0.59437458 | O11: 901635 | P11: =IFERROR(O11/O$35,"") -> 0.50294975 | Q11: =+M11-O11 -> 4171.53 | R11: 497713.29 | S11: =IFERROR(R11/R$35,"") -> 0.54294023 | T11: =+M11-R11 -> 408093.24
B12: Venue Food - Minibar Revenue - 200 | C12: Mini Bar Food Rev | D12: 2867.56 | E12: =IFERROR(D12/D$35,"") -> 0.0075634885 | F12: 2587.95 | G12: =IFERROR(F12/F$35,"") -> 0.0059138835 | H12: =+D12-F12 -> 279.61 | I12: 2434 | J12: =IFERROR(I12/I$35,"") -> 0.0096983313 | K12: =+D12-I12 -> 433.56 | M12: 12080.25 | N12: =IFERROR(M12/M$35,"") -> 0.0079268512 | O12: 10339.73 | P12: =IFERROR(O12/O$35,"") -> 0.005767705 | Q12: =+M12-O12 -> 1740.52 | R12: 10012.09 | S12: =IFERROR(R12/R$35,"") -> 0.010921883 | T12: =+M12-R12 -> 2068.16
B13: Food Revenue - 205 | C13: Pool Bar Food Rev | D13: 0 | E13: =IFERROR(D13/D$35,"") -> 0 | F13: 0 | G13: =IFERROR(F13/F$35,"") -> 0 | H13: =+D13-F13 -> 0 | I13: 0 | J13: =IFERROR(I13/I$35,"") -> 0 | K13: =+D13-I13 -> 0 | M13: 0 | N13: =IFERROR(M13/M$35,"") -> 0 | O13: 0 | P13: =IFERROR(O13/O$35,"") -> 0 | Q13: =+M13-O13 -> 0 | R13: 0 | S13: =IFERROR(R13/R$35,"") -> 0 | T13: =+M13-R13 -> 0
B14: Food Revenue - 204 | C14: Market Bar Food Rev | D14: 0 | E14: =IFERROR(D14/D$35,"") -> 0 | F14: 0 | G14: =IFERROR(F14/F$35,"") -> 0 | H14: =+D14-F14 -> 0 | I14: 0 | J14: =IFERROR(I14/I$35,"") -> 0 | K14: =+D14-I14 -> 0 | M14: 0 | N14: =IFERROR(M14/M$35,"") -> 0 | O14: 0 | P14: =IFERROR(O14/O$35,"") -> 0 | Q14: =+M14-O14 -> 0 | R14: 0 | S14: =IFERROR(R14/R$35,"") -> 0 | T14: =+M14-R14 -> 0
B15: Room Service Food - 200 | C15: In Room Dining Food Rev | D15: 0 | E15: =IFERROR(D15/D$35,"") -> 0 | F15: 0 | G15: =IFERROR(F15/F$35,"") -> 0 | H15: =+D15-F15 -> 0 | I15: 0 | J15: =IFERROR(I15/I$35,"") -> 0 | K15: =+D15-I15 -> 0 | M15: 0 | N15: =IFERROR(M15/M$35,"") -> 0 | O15: 0 | P15: =IFERROR(O15/O$35,"") -> 0 | Q15: =+M15-O15 -> 0 | R15: 0 | S15: =IFERROR(R15/R$35,"") -> 0 | T15: =+M15-R15 -> 0
B16: Total Banquets Food - 200 | C16: Banquet-Catering & CS Food Rev | D16: 0 | E16: =IFERROR(D16/D$35,"") -> 0 | F16: 0 | G16: =IFERROR(F16/F$35,"") -> 0 | H16: =+D16-F16 -> 0 | I16: 0 | J16: =IFERROR(I16/I$35,"") -> 0 | K16: =+D16-I16 -> 0 | M16: 0 | N16: =IFERROR(M16/M$35,"") -> 0 | O16: 0 | P16: =IFERROR(O16/O$35,"") -> 0 | Q16: =+M16-O16 -> 0 | R16: 8277.21 | S16: =IFERROR(R16/R$35,"") -> 0.0090293557 | T16: =+M16-R16 -> -8277.21
B17: Total Food Revenue - 200 | C17: Total Food Revenue | D17: =SUM(D11:D16) -> 229573.07 | E17: =IFERROR(D17/D$35,"") -> 0.60552291 | F17: =SUM(F11:F16) -> 222532.95 | G17: =IFERROR(F17/F$35,"") -> 0.50852371 | H17: =+D17-F17 -> 7040.12 | I17: =SUM(I11:I16) -> 136265.43 | J17: =IFERROR(I17/I$35,"") -> 0.54295287 | K17: =+D17-I17 -> 93307.64 | M17: =SUM(M11:M16) -> 917886.78 | N17: =IFERROR(M17/M$35,"") -> 0.60230143 | O17: =SUM(O11:O16) -> 911974.73 | P17: =IFERROR(O17/O$35,"") -> 0.50871746 | Q17: =+M17-O17 -> 5912.05 | R17: =SUM(R11:R16) -> 516002.59 | S17: =IFERROR(R17/R$35,"") -> 0.56289147 | T17: =+M17-R17 -> 401884.19
C18: Beverage Revenue
B19: Venues Beverage - 200 | C19: Venues Beverage Rev | D19: 85269.01 | E19: =IFERROR(D19/D$35,"") -> 0.22490591 | F19: 134805 | G19: =IFERROR(F19/F$35,"") -> 0.30805118 | H19: =+D19-F19 -> -49535.99 | I19: 76097.09 | J19: =IFERROR(I19/I$35,"") -> 0.30321068 | K19: =+D19-I19 -> 9171.92 | M19: 346194.51 | N19: =IFERROR(M19/M$35,"") -> 0.22716685 | O19: 552615 | P19: =IFERROR(O19/O$35,"") -> 0.30825953 | Q19: =+M19-O19 -> -206420.49 | R19: 235369.46 | S19: =IFERROR(R19/R$35,"") -> 0.25675736 | T19: =+M19-R19 -> 110825.05
B20: Venue Beverage - Minibar Revenue - 200 | C20: Mini Bar Beverage Rev | D20: 2343.12 | E20: =IFERROR(D20/D$35,"") -> 0.0061802233 | F20: 2879.55 | G20: =IFERROR(F20/F$35,"") -> 0.0065802365 | H20: =+D20-F20 -> -536.43 | I20: 2374 | J20: =IFERROR(I20/I$35,"") -> 0.0094592599 | K20: =+D20-I20 -> -30.88 | M20: 11789.51 | N20: =IFERROR(M20/M$35,"") -> 0.0077360726 | O20: 11504.77 | P20: =IFERROR(O20/O$35,"") -> 0.0064175872 | Q20: =+M20-O20 -> 284.74 | R20: 12103.67 | S20: =IFERROR(R20/R$35,"") -> 0.013203524 | T20: =+M20-R20 -> -314.16
B21: Beverage Revenue - 205 | C21: Pool Bar Beverage Rev | D21: 0 | E21: =IFERROR(D21/D$35,"") -> 0 | F21: 0 | G21: =IFERROR(F21/F$35,"") -> 0 | H21: =+D21-F21 -> 0 | I21: 0 | J21: =IFERROR(I21/I$35,"") -> 0 | K21: =+D21-I21 -> 0 | M21: 0 | N21: =IFERROR(M21/M$35,"") -> 0 | O21: 0 | P21: =IFERROR(O21/O$35,"") -> 0 | Q21: =+M21-O21 -> 0 | R21: 0 | S21: =IFERROR(R21/R$35,"") -> 0 | T21: =+M21-R21 -> 0
B22: Beverage Revenue - 204 | C22: Market Bar Beverage Rev | D22: 0 | E22: =IFERROR(D22/D$35,"") -> 0 | F22: 0 | G22: =IFERROR(F22/F$35,"") -> 0 | H22: =+D22-F22 -> 0 | I22: 0 | J22: =IFERROR(I22/I$35,"") -> 0 | K22: =+D22-I22 -> 0 | M22: 0 | N22: =IFERROR(M22/M$35,"") -> 0 | O22: 0 | P22: =IFERROR(O22/O$35,"") -> 0 | Q22: =+M22-O22 -> 0 | R22: 0 | S22: =IFERROR(R22/R$35,"") -> 0 | T22: =+M22-R22 -> 0
B23: Room Service Beverage - 200 | C23: In Room Dining Beverage Rev | D23: 0 | E23: =IFERROR(D23/D$35,"") -> 0 | F23: 0 | G23: =IFERROR(F23/F$35,"") -> 0 | H23: =+D23-F23 -> 0 | I23: 0 | J23: =IFERROR(I23/I$35,"") -> 0 | K23: =+D23-I23 -> 0 | M23: 0 | N23: =IFERROR(M23/M$35,"") -> 0 | O23: 0 | P23: =IFERROR(O23/O$35,"") -> 0 | Q23: =+M23-O23 -> 0 | R23: 0 | S23: =IFERROR(R23/R$35,"") -> 0 | T23: =+M23-R23 -> 0
B24: Total Banquets Beverage- 200 | C24: Banquet-Catering & CS Beverage Rev | D24: 0 | E24: =IFERROR(D24/D$35,"") -> 0 | F24: 0 | G24: =IFERROR(F24/F$35,"") -> 0 | H24: =+D24-F24 -> 0 | I24: 0 | J24: =IFERROR(I24/I$35,"") -> 0 | K24: =+D24-I24 -> 0 | M24: 0 | N24: =IFERROR(M24/M$35,"") -> 0 | O24: 0 | P24: =IFERROR(O24/O$35,"") -> 0 | Q24: =+M24-O24 -> 0 | R24: 0 | S24: =IFERROR(R24/R$35,"") -> 0 | T24: =+M24-R24 -> 0
B25: Total Beverage Revenue - 200 | C25: Total Beverage Revenue | D25: =SUM(D19:D24) -> 87612.13 | E25: =IFERROR(D25/D$35,"") -> 0.23108613 | F25: =SUM(F19:F24) -> 137684.55 | G25: =IFERROR(F25/F$35,"") -> 0.31463142 | H25: =+D25-F25 -> -50072.42 | I25: =SUM(I19:I24) -> 78471.09 | J25: =IFERROR(I25/I$35,"") -> 0.31266994 | K25: =+D25-I25 -> 9141.04 | M25: =SUM(M19:M24) -> 357984.02 | N25: =IFERROR(M25/M$35,"") -> 0.23490292 | O25: =SUM(O19:O24) -> 564119.77 | P25: =IFERROR(O25/O$35,"") -> 0.31467711 | Q25: =+M25-O25 -> -206135.75 | R25: =SUM(R19:R24) -> 247473.13 | S25: =IFERROR(R25/R$35,"") -> 0.26996088 | T25: =+M25-R25 -> 110510.89
B26: Other - Allowances - 200 | C26: Food & Beverage: Allowances | D26: -38 | E26: =IFERROR(D26/D$35,"") -> -0.00010022896 | F26: 0 | G26: =IFERROR(F26/F$35,"") -> 0 | H26: =+D26-F26 -> -38 | I26: 0 | J26: =IFERROR(I26/I$35,"") -> 0 | K26: =+D26-I26 -> -38 | M26: -727.2 | N26: =IFERROR(M26/M$35,"") -> -0.00047717607 | O26: 0 | P26: =IFERROR(O26/O$35,"") -> 0 | Q26: =+M26-O26 -> -727.2 | R26: -43.18 | S26: =IFERROR(R26/R$35,"") -> -4.7103744e-05 | T26: =+M26-R26 -> -684.02
B27: Total F&B Division Revenue - 200 | C27: Total Food & Beverage Revenue | D27: =+D17+D25+D26 -> 317147.2 | E27: =IFERROR(D27/D$35,"") -> 0.83650881 | F27: =F17+F25+F26 -> 360217.5 | G27: =IFERROR(F27/F$35,"") -> 0.82315513 | H27: =+D27-F27 -> -43070.3 | I27: =I17+I25+I26 -> 214736.52 | J27: =IFERROR(I27/I$35,"") -> 0.85562281 | K27: =+D27-I27 -> 102410.68 | M27: =+M17+M25+M26 -> 1275143.6 | N27: =IFERROR(M27/M$35,"") -> 0.83672718 | O27: =O17+O25+O26 -> 1476094.5 | P27: =IFERROR(O27/O$35,"") -> 0.82339457 | Q27: =+M27-O27 -> -200950.9 | R27: =R17+R25+R26 -> 763432.54 | S27: =IFERROR(R27/R$35,"") -> 0.83280525 | T27: =+M27-R27 -> 511711.06
C28: Other Revenue
B29: Other - Audiovisual Revenue - 200 | C29: Audio/Visual Rentals | D29: 9457 | E29: =IFERROR(D29/D$35,"") -> 0.024943824 | F29: 6000 | G29: =IFERROR(F29/F$35,"") -> 0.013710968 | H29: =+D29-F29 -> 3457 | I29: 1062 | J29: =IFERROR(I29/I$35,"") -> 0.0042315644 | K29: =+D29-I29 -> 8395 | M29: 37729 | N29: =IFERROR(M29/M$35,"") -> 0.024757117 | O29: 24000 | P29: =IFERROR(O29/O$35,"") -> 0.013387672 | Q29: =+M29-O29 -> 13729 | R29: 26047 | S29: =IFERROR(R29/R$35,"") -> 0.028413877 | T29: =+M29-R29 -> 11682
B30: Other - Function Room Rental & Setup Charges - 200 | C30: Public Room Rental | D30: 0 | E30: =IFERROR(D30/D$35,"") -> 0 | F30: 0 | G30: =IFERROR(F30/F$35,"") -> 0 | H30: =+D30-F30 -> 0 | I30: 0 | J30: =IFERROR(I30/I$35,"") -> 0 | K30: =+D30-I30 -> 0 | M30: 0 | N30: =IFERROR(M30/M$35,"") -> 0 | O30: 0 | P30: =IFERROR(O30/O$35,"") -> 0 | Q30: =+M30-O30 -> 0 | R30: 1000 | S30: =IFERROR(R30/R$35,"") -> 0.0010908695 | T30: =+M30-R30 -> -1000
B31: Other - Surcharges & Service Charges - 200 | C31: Surcharges & Services Charges | D31: 60636.74 | E31: =IFERROR(D31/D$35,"") -> 0.15993572 | F31: 70950 | G31: =IFERROR(F31/F$35,"") -> 0.1621322 | H31: =+D31-F31 -> -10313.26 | I31: 37778.19 | J31: =IFERROR(I31/I$35,"") -> 0.1505281 | K31: =+D31-I31 -> 22858.55 | M31: 244198.1 | N31: =IFERROR(M31/M$35,"") -> 0.16023857 | O31: 290850 | P31: =IFERROR(O31/O$35,"") -> 0.16224186 | Q31: =+M31-O31 -> -46651.9 | R31: 130447.39 | S31: =IFERROR(R31/R$35,"") -> 0.14230108 | T31: =+M31-R31 -> 113750.71
B32: Other - Other Revenue - 200 | C32: Miscellaneous Other Revenue | D32: -8109.01 | E32: =IFERROR(D32/D$35,"") -> -0.021388359 | F32: 438.35 | G32: =IFERROR(F32/F$35,"") -> 0.0010017005 | H32: =+D32-F32 -> -8547.36 | I32: -2605.7 | J32: =IFERROR(I32/I$35,"") -> -0.010382474 | K32: =+D32-I32 -> -5503.31 | M32: -33104.91 | N32: =IFERROR(M32/M$35,"") -> -0.02172287 | O32: 1749.49 | P32: =IFERROR(O32/O$35,"") -> 0.00097589996 | Q32: =+M32-O32 -> -34854.4 | R32: -4226.97 | S32: =IFERROR(R32/R$35,"") -> -0.0046110725 | T32: =+M32-R32 -> -28877.94
B33: Total Other F&B Revenue - 200 | C33: Total Other Revenue | D33: =SUM(D29:D32) -> 61984.73 | E33: =IFERROR(D33/D$35,"") -> 0.16349119 | F33: =SUM(F29:F32) -> 77388.35 | G33: =IFERROR(F33/F$35,"") -> 0.17684487 | H33: =+D33-F33 -> -15403.62 | I33: =SUM(I29:I32) -> 36234.49 | J33: =IFERROR(I33/I$35,"") -> 0.14437719 | K33: =+D33-I33 -> 25750.24 | M33: =SUM(M29:M32) -> 248822.19 | N33: =IFERROR(M33/M$35,"") -> 0.16327282 | O33: =SUM(O29:O32) -> 316599.49 | P33: =IFERROR(O33/O$35,"") -> 0.17660543 | Q33: =+M33-O33 -> -67777.3 | R33: =SUM(R29:R32) -> 153267.42 | S33: =IFERROR(R33/R$35,"") -> 0.16719475 | T33: =+M33-R33 -> 95554.77
B35: Total Revenue - 200 | C35: Total Revenue | D35: =+D27+D33 -> 379131.93 | E35: =IFERROR(D35/D$35,"") -> 1 | F35: =+F27+F33 -> 437605.85 | G35: =IFERROR(F35/F$35,"") -> 1 | H35: =+D35-F35 -> -58473.92 | I35: =+I27+I33 -> 250971.01 | J35: =IFERROR(I35/I$35,"") -> 1 | K35: =+D35-I35 -> 128160.92 | M35: =+M27+M33 -> 1523965.8 | N35: =IFERROR(M35/M$35,"") -> 1 | O35: =+O27+O33 -> 1792694 | P35: =IFERROR(O35/O$35,"") -> 1 | Q35: =+M35-O35 -> -268728.2 | R35: =+R27+R33 -> 916699.96 | S35: =IFERROR(R35/R$35,"") -> 1 | T35: =+M35-R35 -> 607265.83
C37: Cost of Sales
C38: Cost of Food & Beverage Sales
B39: Cost of Food Sales - 200 | C39: Cost of Food Sales | D39: 65514.91 | E39: =IFERROR(D39/D$17,"") -> 0.28537716 | F39: 66687.42 | G39: =IFERROR(F39/F$17,"") -> 0.29967436 | H39: =+D39-F39 -> -1172.51 | I39: 55246.67 | J39: =IFERROR(I39/I$17,"") -> 0.40543423 | K39: =+D39-I39 -> 10268.24 | M39: 262051.14 | N39: =IFERROR(M39/M$17,"") -> 0.28549397 | O39: 273302.9 | P39: =IFERROR(O39/O$17,"") -> 0.29968254 | Q39: =+M39-O39 -> -11251.76 | R39: 172398.03 | S39: =IFERROR(R39/R$17,"") -> 0.33410303 | T39: =+M39-R39 -> 89653.11
B40: Cost of Beverage Sales - 200 | C40: Cost of Beverage Sales | D40: 21381.25 | E40: =+IFERROR(D40/D$25,"") -> 0.2440444 | F40: 24975.35 | G40: =+IFERROR(F40/F$25,"") -> 0.18139544 | H40: =+D40-F40 -> -3594.1 | I40: 23380.27 | J40: =+IFERROR(I40/I$25,"") -> 0.29794756 | K40: =+D40-I40 -> -1999.02 | M40: 63521.14 | N40: =+IFERROR(M40/M$25,"") -> 0.17744127 | O40: 102294.42 | P40: =+IFERROR(O40/O$25,"") -> 0.18133458 | Q40: =+M40-O40 -> -38773.28 | R40: 62470.6 | S40: =+IFERROR(R40/R$25,"") -> 0.25243387 | T40: =+M40-R40 -> 1050.54
B41: Cost of Food & Beverage Sales - 200 | C41: Total Cost of Food & Beverage Sales | D41: =+SUM(D39:D40) -> 86896.16 | E41: =+IFERROR(D41/D$27,"") -> 0.27399315 | F41: =+SUM(F39:F40) -> 91662.77 | G41: =+IFERROR(F41/F$27,"") -> 0.25446507 | H41: =+D41-F41 -> -4766.61 | I41: =+SUM(I39:I40) -> 78626.94 | J41: =+IFERROR(I41/I$27,"") -> 0.36615542 | K41: =+D41-I41 -> 8269.22 | M41: =+SUM(M39:M40) -> 325572.28 | N41: =+IFERROR(M41/M$27,"") -> 0.25532205 | O41: =+SUM(O39:O40) -> 375597.32 | P41: =+IFERROR(O41/O$27,"") -> 0.25445344 | Q41: =+M41-O41 -> -50025.04 | R41: =+SUM(R39:R40) -> 234868.63 | S41: =+IFERROR(R41/R$27,"") -> 0.30764818 | T41: =+M41-R41 -> 90703.65
C42: Cost of Other Revenue
B43: Cost of Other Sales - 200 | C43: Total Cost of Other Revenue | D43: 2090.84 | E43: =+IFERROR(D43/D$33,"") -> 0.033731534 | F43: 474.51 | G43: =+IFERROR(F43/F$33,"") -> 0.0061315431 | H43: =+D43-F43 -> 1616.33 | I43: 1545.89 | J43: =+IFERROR(I43/I$33,"") -> 0.042663495 | K43: =+D43-I43 -> 544.95 | M43: 11058.76 | N43: =+IFERROR(M43/M$33,"") -> 0.044444428 | O43: 1895.82 | P43: =+IFERROR(O43/O$33,"") -> 0.0059880703 | Q43: =+M43-O43 -> 9162.94 | R43: 8297.37 | S43: =+IFERROR(R43/R$33,"") -> 0.054136554 | T43: =+M43-R43 -> 2761.39
...

Sheet OTH_OP
V1: ANG
C2: =+Summary!$C$2 -> Angler's | V2: Apr
C3: =+Summary!$C$3 -> STATEMENT OF INCOME
C4: =+Summary!$C$4 -> FOR THE PERIOD ENDING APR 2025
D6: =Year&" "&UPPER(Month)&" - PERIODIC" -> 2025 APR - PERIODIC | M6: =Year&" "&UPPER(Month)&" - YEAR TO DATE" -> 2025 APR - YEAR TO DATE
D7: Actual | F7: Budget | H7: VARIANCE | I7: Actual - Last Year | K7: VARIANCE | M7: Actual | O7: Budget | Q7: VARIANCE | R7: Actual - Last Year | T7: VARIANCE
D8: $ | E8: % | F8: $ | G8: % | H8: $ | I8: Actual | J8: % | K8: $ | M8: $ | N8: % | O8: $ | P8: % | Q8: $ | R8: Actual | S8: % | T8: $
C9: Revenues
B10: Total Guest Communications Revenue - 350 | C10: Guest Communications | D10: 79.07 | E10: =+IFERROR(D10/D$17,"") -> 0.026817571 | F10: 88.94 | G10: =+IFERROR(F10/F$17,"") -> 0.057090405 | H10: =+D10-F10 -> -9.87 | I10: 49.53 | J10: =+IFERROR(I10/I$17,"") -> 0.03388868 | K10: =+D10-I10 -> 29.54 | M10: 388.26 | N10: =+IFERROR(M10/M$17,"") -> 0.039320893 | O10: 355.33 | P10: =+IFERROR(O10/O$17,"") -> 0.057088278 | Q10: =+M10-O10 -> 32.93 | R10: 149.69 | S10: =+IFERROR(R10/R$17,"") -> 0.020770805 | T10: =+M10-R10 -> 238.57
B11: Total Health Club/Spa Revenue - 310 | C11: Health Club/Spa | D11: 0 | E11: =+IFERROR(D11/D$17,"") -> 0 | F11: 0 | G11: =+IFERROR(F11/F$17,"") -> 0 | H11: =+D11-F11 -> 0 | I11: 0 | J11: =+IFERROR(I11/I$17,"") -> 0 | K11: =+D11-I11 -> 0 | M11: 0 | N11: =+IFERROR(M11/M$17,"") -> 0 | O11: 0 | P11: =+IFERROR(O11/O$17,"") -> 0 | Q11: =+M11-O11 -> 0 | R11: 0 | S11: =+IFERROR(R11/R$17,"") -> 0 | T11: =+M11-R11 -> 0
B12: Total Parking Revenue - 320 | C12: Parking | D12: 0 | E12: =+IFERROR(D12/D$17,"") -> 0 | F12: 0 | G12: =+IFERROR(F12/F$17,"") -> 0 | H12: =+D12-F12 -> 0 | I12: 0 | J12: =+IFERROR(I12/I$17,"") -> 0 | K12: =+D12-I12 -> 0 | M12: 0 | N12: =+IFERROR(M12/M$17,"") -> 0 | O12: 0 | P12: =+IFERROR(O12/O$17,"") -> 0 | Q12: =+M12-O12 -> 0 | R12: 0 | S12: =+IFERROR(R12/R$17,"") -> 0 | T12: =+M12-R12 -> 0
B13: Total Laundry & Dry Cleaning Revenue - 360 | C13: Laundry & Dry Cleaning | D13: 1605.37 | E13: =+IFERROR(D13/D$17,"") -> 0.54448115 | F13: 583.2 | G13: =+IFERROR(F13/F$17,"") -> 0.37435489 | H13: =+D13-F13 -> 1022.17 | I13: 764.02 | J13: =+IFERROR(I13/I$17,"") -> 0.5227464 | K13: =+D13-I13 -> 841.35 | M13: 6304.88 | N13: =+IFERROR(M13/M$17,"") -> 0.63852447 | O13: 2330.08 | P13: =+IFERROR(O13/O$17,"") -> 0.37435695 | Q13: =+M13-O13 -> 3974.8 | R13: 2717.06 | S13: =+IFERROR(R13/R$17,"") -> 0.37701599 | T13: =+M13-R13 -> 3587.82
B14: Total Retail Revenue - 340 | C14: Retail Shop | D14: 0 | E14: =+IFERROR(D14/D$17,"") -> 0 | F14: 0 | G14: =+IFERROR(F14/F$17,"") -> 0 | H14: =+D14-F14 -> 0 | I14: 0 | J14: =+IFERROR(I14/I$17,"") -> 0 | K14: =+D14-I14 -> 0 | M14: 0 | N14: =+IFERROR(M14/M$17,"") -> 0 | O14: 0 | P14: =+IFERROR(O14/O$17,"") -> 0 | Q14: =+M14-O14 -> 0 | R14: 0 | S14: =+IFERROR(R14/R$17,"") -> 0 | T14: =+M14-R14 -> 0
B15: Total Minor Operated Department-3 Revenue - 370 | C15: Misc. Minor Operated Departments | D15: 0 | E15: =+IFERROR(D15/D$17,"") -> 0 | F15: 0 | G15: =+IFERROR(F15/F$17,"") -> 0 | H15: =+D15-F15 -> 0 | I15: 0 | J15: =+IFERROR(I15/I$17,"") -> 0 | K15: =+D15-I15 -> 0 | M15: 0 | N15: =+IFERROR(M15/M$17,"") -> 0 | O15: 0 | P15: =+IFERROR(O15/O$17,"") -> 0 | Q15: =+M15-O15 -> 0 | R15: 0 | S15: =+IFERROR(R15/R$17,"") -> 0 | T15: =+M15-R15 -> 0
B16: Total Minor Operated Department-4 Revenue - 380 | C16: Minor Other Operated Departments | D16: 1264 | E16: =+IFERROR(D16/D$17,"") -> 0.42870128 | F16: 885.74 | G16: =+IFERROR(F16/F$17,"") -> 0.5685547 | H16: =+D16-F16 -> 378.26 | I16: 648 | J16: =+IFERROR(I16/I$17,"") -> 0.44336492 | K16: =+D16-I16 -> 616 | M16: 3181 | N16: =+IFERROR(M16/M$17,"") -> 0.32215464 | O16: 3538.81 | P16: =+IFERROR(O16/O$17,"") -> 0.56855477 | Q16: =+M16-O16 -> -357.81 | R16: 4340 | S16: =+IFERROR(R16/R$17,"") -> 0.6022132 | T16: =+M16-R16 -> -1159
B17: Total Revenue - 300 | C17: Total Departmental Revenues | D17: =SUM(D10:D16) -> 2948.44 | E17: =+IFERROR(D17/D$17,"") -> 1 | F17: =SUM(F10:F16) -> 1557.88 | G17: =+IFERROR(F17/F$17,"") -> 1 | H17: =+D17-F17 -> 1390.56 | I17: =SUM(I10:I16) -> 1461.55 | J17: =+IFERROR(I17/I$17,"") -> 1 | K17: =+D17-I17 -> 1486.89 | M17: =SUM(M10:M16) -> 9874.14 | N17: =+IFERROR(M17/M$17,"") -> 1 | O17: =SUM(O10:O16) -> 6224.22 | P17: =+IFERROR(O17/O$17,"") -> 1 | Q17: =+M17-O17 -> 3649.92 | R17: =SUM(R10:R16) -> 7206.75 | S17: =+IFERROR(R17/R$17,"") -> 1 | T17: =+M17-R17 -> 2667.39
C19: Departmental Expenses (Incl COS)
B20: Total Departmental Expenses - 350 | C20: Guest Communications | D20: 36 | E20: =+IFERROR(D20/D10,"") -> 0.45529278 | F20: 40.91 | G20: =+IFERROR(F20/F10,"") -> 0.45997302 | H20: =+D20-F20 -> -4.91 | I20: 23 | J20: =+IFERROR(I20/I10,"") -> 0.46436503 | K20: =+D20-I20 -> 13 | M20: 178 | N20: =+IFERROR(M20/M10,"") -> 0.45845567 | O20: 163.45 | P20: =+IFERROR(O20/O10,"") -> 0.45999493 | Q20: =+M20-O20 -> 14.55 | R20: 71 | S20: =+IFERROR(R20/R10,"") -> 0.47431358 | T20: =+M20-R20 -> 107
B21: Total Departmental Expenses - 310 | C21: Health Club/Spa | D21: 0 | E21: =+IFERROR(D21/D11,"") | F21: 0 | G21: =+IFERROR(F21/F11,"") | H21: =+D21-F21 -> 0 | I21: 0 | J21: =+IFERROR(I21/I11,"") | K21: =+D21-I21 -> 0 | M21: 0 | N21: =+IFERROR(M21/M11,"") | O21: 0 | P21: =+IFERROR(O21/O11,"") | Q21: =+M21-O21 -> 0 | R21: 0 | S21: =+IFERROR(R21/R11,"") | T21: =+M21-R21 -> 0
B22: Total Departmental Expenses - 320 | C22: Parking | D22: 0 | E22: =+IFERROR(D22/D12,"") | F22: 0 | G22: =+IFERROR(F22/F12,"") | H22: =+D22-F22 -> 0 | I22: 0 | J22: =+IFERROR(I22/I12,"") | K22: =+D22-I22 -> 0 | M22: 0 | N22: =+IFERROR(M22/M12,"") | O22: 0 | P22: =+IFERROR(O22/O12,"") | Q22: =+M22-O22 -> 0 | R22: 0 | S22: =+IFERROR(R22/R12,"") | T22: =+M22-R22 -> 0
B23: Total Departmental Expenses - 360 | C23: Laundry & Dry Cleaning | D23: 1069.98 | E23: =+IFERROR(D23/D13,"") -> 0.66650056 | F23: 490.47 | G23: =+IFERROR(F23/F13,"") -> 0.84099794 | H23: =+D23-F23 -> 579.51 | I23: 619.24 | J23: =+IFERROR(I23/I13,"") -> 0.81050234 | K23: =+D23-I23 -> 450.74 | M23: 4895 | N23: =+IFERROR(M23/M13,"") -> 0.77638274 | O23: 1959.6 | P23: =+IFERROR(O23/O13,"") -> 0.84100117 | Q23: =+M23-O23 -> 2935.4 | R23: 2250.77 | S23: =+IFERROR(R23/R13,"") -> 0.82838436 | T23: =+M23-R23 -> 2644.23
B24: Total Departmental Expenses - 340 | C24: Retail Shop | D24: 0 | E24: =+IFERROR(D24/D14,"") | F24: 0 | G24: =+IFERROR(F24/F14,"") | H24: =+D24-F24 -> 0 | I24: 0 | J24: =+IFERROR(I24/I14,"") | K24: =+D24-I24 -> 0 | M24: 0 | N24: =+IFERROR(M24/M14,"") | O24: 0 | P24: =+IFERROR(O24/O14,"") | Q24: =+M24-O24 -> 0 | R24: 0 | S24: =+IFERROR(R24/R14,"") | T24: =+M24-R24 -> 0
B25: Total Departmental Expenses - 370 | C25: Misc. Minor Operated Departments | D25: 0 | E25: =+IFERROR(D25/D15,"") | F25: 0 | G25: =+IFERROR(F25/F15,"") | H25: =+D25-F25 -> 0 | I25: 0 | J25: =+IFERROR(I25/I15,"") | K25: =+D25-I25 -> 0 | M25: 0 | N25: =+IFERROR(M25/M15,"") | O25: 0 | P25: =+IFERROR(O25/O15,"") | Q25: =+M25-O25 -> 0 | R25: 0 | S25: =+IFERROR(R25/R15,"") | T25: =+M25-R25 -> 0
B26: Total Departmental Expenses - 380 | C26: Minor Other Operated Departments | D26: 0 | E26: =+IFERROR(D26/D16,"") -> 0 | F26: 0 | G26: =+IFERROR(F26/F16,"") -> 0 | H26: =+D26-F26 -> 0 | I26: 0 | J26: =+IFERROR(I26/I16,"") -> 0 | K26: =+D26-I26 -> 0 | M26: 0 | N26: =+IFERROR(M26/M16,"") -> 0 | O26: 0 | P26: =+IFERROR(O26/O16,"") -> 0 | Q26: =+M26-O26 -> 0 | R26: 0 | S26: =+IFERROR(R26/R16,"") -> 0 | T26: =+M26-R26 -> 0
B27: Total Departmental Expenses - 300 | C27: Total Departmental Expenses | D27: =SUM(D20:D26) -> 1105.98 | E27: =+IFERROR(D27/D17,"") -> 0.37510684 | F27: =SUM(F20:F26) -> 531.38 | G27: =+IFERROR(F27/F17,"") -> 0.34109174 | H27: =+D27-F27 -> 574.6 | I27: =SUM(I20:I26) -> 642.24 | J27: =+IFERROR(I27/I17,"") -> 0.4394239 | K27: =+D27-I27 -> 463.74 | M27: =SUM(M20:M26) -> 5073 | N27: =+IFERROR(M27/M17,"") -> 0.51376626 | O27: =SUM(O20:O26) -> 2123.05 | P27: =+IFERROR(O27/O17,"") -> 0.34109495 | Q27: =+M27-O27 -> 2949.95 | R27: =SUM(R20:R26) -> 2321.77 | S27: =+IFERROR(R27/R17,"") -> 0.32216602 | T27: =+M27-R27 -> 2751.23
C29: Department Profit (Loss)
C30: Guest Communications | D30: 0 | E30: =+IFERROR(D30/D10,"") -> 0 | F30: 0 | G30: =+IFERROR(F30/F10,"") -> 0 | H30: =+D30-F30 -> 0 | I30: 0 | J30: =+IFERROR(I30/I10,"") -> 0 | K30: =+D30-I30 -> 0 | M30: 0 | N30: =+IFERROR(M30/M10,"") -> 0 | O30: 0 | P30: =+IFERROR(O30/O10,"") -> 0 | Q30: =+M30-O30 -> 0 | R30: 0 | S30: =+IFERROR(R30/R10,"") -> 0 | T30: =+M30-R30 -> 0
C31: Health Club/Spa | D31: 0 | E31: =+IFERROR(D31/D11,"") | F31: 0 | G31: =+IFERROR(F31/F11,"") | H31: =+D31-F31 -> 0 | I31: 0 | J31: =+IFERROR(I31/I11,"") | K31: =+D31-I31 -> 0 | M31: 0 | N31: =+IFERROR(M31/M11,"") | O31: 0 | P31: =+IFERROR(O31/O11,"") | Q31: =+M31-O31 -> 0 | R31: 0 | S31: =+IFERROR(R31/R11,"") | T31: =+M31-R31 -> 0
C32: Parking | D32: 0 | E32: =+IFERROR(D32/D12,"") | F32: 0 | G32: =+IFERROR(F32/F12,"") | H32: =+D32-F32 -> 0 | I32: 0 | J32: =+IFERROR(I32/I12,"") | K32: =+D32-I32 -> 0 | M32: 0 | N32: =+IFERROR(M32/M12,"") | O32: 0 | P32: =+IFERROR(O32/O12,"") | Q32: =+M32-O32 -> 0 | R32: 0 | S32: =+IFERROR(R32/R12,"") | T32: =+M32-R32 -> 0
C33: Laundry & Dry Cleaning | D33: 0 | E33: =+IFERROR(D33/D13,"") -> 0 | F33: 0 | G33: =+IFERROR(F33/F13,"") -> 0 | H33: =+D33-F33 -> 0 | I33: 0 | J33: =+IFERROR(I33/I13,"") -> 0 | K33: =+D33-I33 -> 0 | M33: 0 | N33: =+IFERROR(M33/M13,"") -> 0 | O33: 0 | P33: =+IFERROR(O33/O13,"") -> 0 | Q33: =+M33-O33 -> 0 | R33: 0 | S33: =+IFERROR(R33/R13,"") -> 0 | T33: =+M33-R33 -> 0
C34: Retail Shop | D34: 0 | E34: =+IFERROR(D34/D14,"") | F34: 0 | G34: =+IFERROR(F34/F14,"") | H34: =+D34-F34 -> 0 | I34: 0 | J34: =+IFERROR(I34/I14,"") | K34: =+D34-I34 -> 0 | M34: 0 | N34: =+IFERROR(M34/M14,"") | O34: 0 | P34: =+IFERROR(O34/O14,"") | Q34: =+M34-O34 -> 0 | R34: 0 | S34: =+IFERROR(R34/R14,"") | T34: =+M34-R34 -> 0
C35: Misc. Minor Operated Departments | D35: 0 | E35: =+IFERROR(D35/D15,"") | F35: 0 | G35: =+IFERROR(F35/F15,"") | H35: =+D35-F35 -> 0 | I35: 0 | J35: =+IFERROR(I35/I15,"") | K35: =+D35-I35 -> 0 | M35: 0 | N35: =+IFERROR(M35/M15,"") | O35: 0 | P35: =+IFERROR(O35/O15,"") | Q35: =+M35-O35 -> 0 | R35: 0 | S35: =+IFERROR(R35/R15,"") | T35: =+M35-R35 -> 0
C36: Minor Other Operated Departments | D36: 0 | E36: =+IFERROR(D36/D16,"") -> 0 | F36: 0 | G36: =+IFERROR(F36/F16,"") -> 0 | H36: =+D36-F36 -> 0 | I36: 0 | J36: =+IFERROR(I36/I16,"") -> 0 | K36: =+D36-I36 -> 0 | M36: 0 | N36: =+IFERROR(M36/M16,"") -> 0 | O36: 0 | P36: =+IFERROR(O36/O16,"") -> 0 | Q36: =+M36-O36 -> 0 | R36: 0 | S36: =+IFERROR(R36/R16,"") -> 0 | T36: =+M36-R36 -> 0
C37: Total Departmental Profit | D37: =+D17-D27 -> 1842.46 | E37: =+IFERROR(D37/D17,"") -> 0.62489316 | F37: =+F17-F27 -> 1026.5 | G37: =+IFERROR(F37/F17,"") -> 0.65890826 | H37: =+D37-F37 -> 815.96 | I37: =+I17-I27 -> 819.31 | J37: =+IFERROR(I37/I17,"") -> 0.5605761 | K37: =+D37-I37 -> 1023.15 | M37: =+M17-M27 -> 4801.14 | N37: =+IFERROR(M37/M17,"") -> 0.48623374 | O37: =+O17-O27 -> 4101.17 | P37: =+IFERROR(O37/O17,"") -> 0.65890505 | Q37: =+M37-O37 -> 699.97 | R37: =+R17-R27 -> 4884.98 | S37: =+IFERROR(R37/R17,"") -> 0.67783398 | T37: =+M37-R37 -> -83.84
B39: Dept Profit - 300 | C39: Department Profit (Loss) | D39: =D37 -> 1842.46 | E39: =+IFERROR(D39/D17,"") -> 0.62489316 | F39: =F37 -> 1026.5 | G39: =+IFERROR(F39/F17,"") -> 0.65890826 | H39: =+D39-F39 -> 815.96 | I39: =I37 -> 819.31 | J39: =+IFERROR(I39/I17,"") -> 0.5605761 | K39: =+D39-I39 -> 1023.15 | M39: =M37 -> 4801.14 | N39: =+IFERROR(M39/M17,"") -> 0.48623374 | O39: =O37 -> 4101.17 | P39: =+IFERROR(O39/O17,"") -> 0.65890505 | Q39: =+M39-O39 -> 699.97 | R39: =R37 -> 4884.98 | S39: =+IFERROR(R39/R17,"") -> 0.67783398 | T39: =+M39-R39 -> -83.84

Sheet MISC_INC
V1: ANG
C2: =+Summary!$C$2 -> Angler's | V2: Apr
C3: =+Summary!$C$3 -> STATEMENT OF INCOME
C4: =+Summary!$C$4 -> FOR THE PERIOD ENDING APR 2025
D6: =Year&" "&UPPER(Month)&" - PERIODIC" -> 2025 APR - PERIODIC | M6: =Year&" "&UPPER(Month)&" - YEAR TO DATE" -> 2025 APR - YEAR TO DATE
D7: Actual | F7: Budget | H7: VARIANCE | I7: Actual - Last Year | K7: VARIANCE | M7: Actual | O7: Budget | Q7: VARIANCE | R7: Actual - Last Year | T7: VARIANCE
D8: $ | E8: % | F8: $ | G8: % | H8: $ | I8: Actual | J8: % | K8: $ | M8: $ | N8: % | O8: $ | P8: % | Q8: $ | R8: Actual | S8: % | T8: $
C9: Revenues
B10: Misc. Space Rental & Concessions - 400 | C10: Space Rent & Concessions | D10: 0 | E10: =IFERROR(D10/D$22,"") -> 0 | F10: 0 | G10: =IFERROR(F10/F$22,"") -> 0 | H10: =D10-F10 -> 0 | I10: 0 | J10: =IFERROR(I10/I$22,"") -> 0 | K10: =D10-I10 -> 0 | M10: 0 | N10: =IFERROR(M10/M$22,"") -> 0 | O10: 0 | P10: =IFERROR(O10/O$22,"") -> 0 | Q10: =M10-O10 -> 0 | R10: 0 | S10: =IFERROR(R10/R$22,"") -> 0 | T10: =M10-R10 -> 0
B11: Misc. Commissions - 400 | C11: Commissions | D11: 12790.04 | E11: =IFERROR(D11/D$22,"") -> 0.088385198 | F11: 7700 | G11: =IFERROR(F11/F$22,"") -> 0.064015696 | H11: =D11-F11 -> 5090.04 | I11: 930.4 | J11: =IFERROR(I11/I$22,"") -> 0.0076556599 | K11: =D11-I11 -> 11859.64 | M11: 19344.7 | N11: =IFERROR(M11/M$22,"") -> 0.039018402 | O11: 30800 | P11: =IFERROR(O11/O$22,"") -> 0.062308699 | Q11: =M11-O11 -> -11455.3 | R11: -1144.7 | S11: =IFERROR(R11/R$22,"") -> -0.0026171359 | T11: =M11-R11 -> 20489.4
B12: Misc. Cash Discounts Earned - 400 | C12: Cash Discounts Earned | D12: 0 | E12: =IFERROR(D12/D$22,"") -> 0 | F12: 0 | G12: =IFERROR(F12/F$22,"") -> 0 | H12: =D12-F12 -> 0 | I12: 0 | J12: =IFERROR(I12/I$22,"") -> 0 | K12: =D12-I12 -> 0 | M12: 0 | N12: =IFERROR(M12/M$22,"") -> 0 | O12: 0 | P12: =IFERROR(O12/O$22,"") -> 0 | Q12: =M12-O12 -> 0 | R12: 0 | S12: =IFERROR(R12/R$22,"") -> 0 | T12: =M12-R12 -> 0
B13: Misc. Attrition Fees - 400 | C13: Attrition Penalties | D13: 27727 | E13: =IFERROR(D13/D$22,"") -> 0.19160663 | F13: 0 | G13: =IFERROR(F13/F$22,"") -> 0 | H13: =D13-F13 -> 27727 | I13: 0 | J13: =IFERROR(I13/I$22,"") -> 0 | K13: =D13-I13 -> 27727 | M13: 32135.3 | N13: =IFERROR(M13/M$22,"") -> 0.064817137 | O13: 1950 | P13: =IFERROR(O13/O$22,"") -> 0.0039448689 | Q13: =M13-O13 -> 30185.3 | R13: 1946.8 | S13: =IFERROR(R13/R$22,"") -> 0.004450983 | T13: =M13-R13 -> 30188.5
B14: Misc. Cancellation Fees - 400 | C14: Cancellation Penalties | D14: 611.42 | E14: =IFERROR(D14/D$22,"") -> 0.0042252001 | F14: 6592 | G14: =IFERROR(F14/F$22,"") -> 0.054804087 | H14: =D14-F14 -> -5980.58 | I14: 6592.02 | J14: =IFERROR(I14/I$22,"") -> 0.054241469 | K14: =D14-I14 -> -5980.6 | M14: 6891.75 | N14: =IFERROR(M14/M$22,"") -> 0.013900711 | O14: 38093 | P14: =IFERROR(O14/O$22,"") -> 0.077062509 | Q14: =M14-O14 -> -31201.25 | R14: 38092.61 | S14: =IFERROR(R14/R$22,"") -> 0.087091411 | T14: =M14-R14 -> -31200.86
B15: Misc. Guest Laundry & Dry Cleaning - 400 | C15: Guest Laundry & Dry Cleaning | D15: 0 | E15: =IFERROR(D15/D$22,"") -> 0 | F15: 0 | G15: =IFERROR(F15/F$22,"") -> 0 | H15: =D15-F15 -> 0 | I15: 0 | J15: =IFERROR(I15/I$22,"") -> 0 | K15: =D15-I15 -> 0 | M15: 0 | N15: =IFERROR(M15/M$22,"") -> 0 | O15: 0 | P15: =IFERROR(O15/O$22,"") -> 0 | Q15: =M15-O15 -> 0 | R15: 0 | S15: =IFERROR(R15/R$22,"") -> 0 | T15: =M15-R15 -> 0
B16: Misc. Interest Income - 400 | C16: Interest Income | D16: 0 | E16: =IFERROR(D16/D$22,"") -> 0 | F16: 0 | G16: =IFERROR(F16/F$22,"") -> 0 | H16: =D16-F16 -> 0 | I16: 8745.83 | J16: =IFERROR(I16/I$22,"") -> 0.071963779 | K16: =D16-I16 -> -8745.83 | M16: 41895.56 | N16: =IFERROR(M16/M$22,"") -> 0.084503653 | O16: 0 | P16: =IFERROR(O16/O$22,"") -> 0 | Q16: =M16-O16 -> 41895.56 | R16: 34560.95 | S16: =IFERROR(R16/R$22,"") -> 0.079016951 | T16: =M16-R16 -> 7334.61
B17: Misc. Other Breakage - 400 | C17: Other Breakage | D17: 0 | E17: =IFERROR(D17/D$22,"") -> 0 | F17: 0 | G17: =IFERROR(F17/F$22,"") -> 0 | H17: =D17-F17 -> 0 | I17: 0 | J17: =IFERROR(I17/I$22,"") -> 0 | K17: =D17-I17 -> 0 | M17: 0 | N17: =IFERROR(M17/M$22,"") -> 0 | O17: 0 | P17: =IFERROR(O17/O$22,"") -> 0 | Q17: =M17-O17 -> 0 | R17: 0 | S17: =IFERROR(R17/R$22,"") -> 0 | T17: =M17-R17 -> 0
B18: Misc. Package Breakage - 400 | C18: Package Breakage | D18: 0 | E18: =IFERROR(D18/D$22,"") -> 0 | F18: 0 | G18: =IFERROR(F18/F$22,"") -> 0 | H18: =D18-F18 -> 0 | I18: 0 | J18: =IFERROR(I18/I$22,"") -> 0 | K18: =D18-I18 -> 0 | M18: 0 | N18: =IFERROR(M18/M$22,"") -> 0 | O18: 0 | P18: =IFERROR(O18/O$22,"") -> 0 | Q18: =M18-O18 -> 0 | R18: 0 | S18: =IFERROR(R18/R$22,"") -> 0 | T18: =M18-R18 -> 0
B19: Misc. Resort Fees - 400 | C19: Resort Fees | D19: 103437.12 | E19: =IFERROR(D19/D$22,"") -> 0.7147992 | F19: 105991 | G19: =IFERROR(F19/F$22,"") -> 0.88118022 | H19: =D19-F19 -> -2553.88 | I19: 105262.75 | J19: =IFERROR(I19/I$22,"") -> 0.86613909 | K19: =D19-I19 -> -1825.63 | M19: 395156.87 | N19: =IFERROR(M19/M$22,"") -> 0.79703432 | O19: 423470 | P19: =IFERROR(O19/O$22,"") -> 0.85668392 | Q19: =M19-O19 -> -28313.13 | R19: 363930.87 | S19: =IFERROR(R19/R$22,"") -> 0.83205779 | T19: =M19-R19 -> 31226
B20: Misc. Proceeds from Business Interruption Insurance - 400 | C20: Proceeds from BI Insurance | D20: 0 | E20: =IFERROR(D20/D$22,"") -> 0 | F20: 0 | G20: =IFERROR(F20/F$22,"") -> 0 | H20: =D20-F20 -> 0 | I20: 0 | J20: =IFERROR(I20/I$22,"") -> 0 | K20: =D20-I20 -> 0 | M20: 0 | N20: =IFERROR(M20/M$22,"") -> 0 | O20: 0 | P20: =IFERROR(O20/O$22,"") -> 0 | Q20: =M20-O20 -> 0 | R20: 0 | S20: =IFERROR(R20/R$22,"") -> 0 | T20: =M20-R20 -> 0
