Workbook
Name _________________________________old2: {#N/A,#N/A,FALSE,"Chart 2 by Prop Type"}
Name _______________________________old2: {#N/A,#N/A,FALSE,"Chart 2 by Prop Type"}
Name _____________________________old2: {#N/A,#N/A,FALSE,"Chart 2 by Prop Type"}
Name _____________________________old2: {#N/A,#N/A,FALSE,"Chart 2 by Prop Type"}
Name _____________________________old2: {#N/A,#N/A,FALSE,"Chart 2 by Prop Type"}
Name ____________________________old2: {#N/A,#N/A,FALSE,"Chart 2 by Prop Type"}
Name ____________________________old2: {#N/A,#N/A,FALSE,"Chart 2 by Prop Type"}
Name ____________________________old2: {#N/A,#N/A,FALSE,"Chart 2 by Prop Type"}
Name ___________________________old2: {#N/A,#N/A,FALSE,"Chart 2 by Prop Type"}
Name ___________________________old2: {#N/A,#N/A,FALSE,"Chart 2 by Prop Type"}
Name ___________________________old2: {#N/A,#N/A,FALSE,"Chart 2 by Prop Type"}
Name __________________________old2: {#N/A,#N/A,FALSE,"Chart 2 by Prop Type"}
Name __________________________old2: {#N/A,#N/A,FALSE,"Chart 2 by Prop Type"}
Name __________________________old2: {#N/A,#N/A,FALSE,"Chart 2 by Prop Type"}
Name _________________________old2: {#N/A,#N/A,FALSE,"Chart 2 by Prop Type"}
Name _________________________old2: {#N/A,#N/A,FALSE,"Chart 2 by Prop Type"}
Name _________________________old2: {#N/A,#N/A,FALSE,"Chart 2 by Prop Type"}
Name ________________________old2: {#N/A,#N/A,FALSE,"Chart 2 by Prop Type"}
Name ________________________old2: {#N/A,#N/A,FALSE,"Chart 2 by Prop Type"}
Name ________________________old2: {#N/A,#N/A,FALSE,"Chart 2 by Prop Type"}
Name _______________________old2: {#N/A,#N/A,FALSE,"Chart 2 by Prop Type"}
Name _______________________old2: {#N/A,#N/A,FALSE,"Chart 2 by Prop Type"}
Name _______________________old2: {#N/A,#N/A,FALSE,"Chart 2 by Prop Type"}
Name ______________________old2: {#N/A,#N/A,FALSE,"Chart 2 by Prop Type"}
Name ______________________old2: {#N/A,#N/A,FALSE,"Chart 2 by Prop Type"}
Name ______________________old2: {#N/A,#N/A,FALSE,"Chart 2 by Prop Type"}
Name _____________________old2: {#N/A,#N/A,FALSE,"Chart 2 by Prop Type"}
Name _____________________old2: {#N/A,#N/A,FALSE,"Chart 2 by Prop Type"}
Name _____________________old2: {#N/A,#N/A,FALSE,"Chart 2 by Prop Type"}
Name ____________________old2: {#N/A,#N/A,FALSE,"Chart 2 by Prop Type"}
Name ____________________old2: {#N/A,#N/A,FALSE,"Chart 2 by Prop Type"}
Name ____________________old2: {#N/A,#N/A,FALSE,"Chart 2 by Prop Type"}
Name ___________________old2: {#N/A,#N/A,FALSE,"Chart 2 by Prop Type"}
Name ___________________old2: {#N/A,#N/A,FALSE,"Chart 2 by Prop Type"}
Name ___________________old2: {#N/A,#N/A,FALSE,"Chart 2 by Prop Type"}
Name __________________old2: {#N/A,#N/A,FALSE,"Chart 2 by Prop Type"}
Name __________________old2: {#N/A,#N/A,FALSE,"Chart 2 by Prop Type"}
Name __________________old2: {#N/A,#N/A,FALSE,"Chart 2 by Prop Type"}
Name _________________old2: {#N/A,#N/A,FALSE,"Chart 2 by Prop Type"}
Name _________________old2: {#N/A,#N/A,FALSE,"Chart 2 by Prop Type"}
Name _________________old2: {#N/A,#N/A,FALSE,"Chart 2 by Prop Type"}
Name ________________a1: {"Assump",#N/A,TRUE,"Proforma";"first",#N/A,TRUE,"Proforma";"second",#N/A,TRUE,"Proforma";"lease1",#N/A,TRUE,"Proforma";"lease2",#N/A,TRUE,"Proforma"}
Name ________________jo2: {#N/A,#N/A,FALSE,"DCF-COM";#N/A,#N/A,FALSE,"VAC-COM"}
Name ________________jo3: {"CASHFLOW",#N/A,FALSE,"Northpointe"}
Name ________________jo4: {#N/A,#N/A,FALSE,"SHEET1";#N/A,#N/A,FALSE,"SHEET2";#N/A,#N/A,FALSE,"SHEET3";#N/A,#N/A,FALSE,"SHEET4"}
Name ________________old2: {#N/A,#N/A,FALSE,"Chart 2 by Prop Type"}
Name ________________old2: {#N/A,#N/A,FALSE,"Chart 2 by Prop Type"}
Name ________________old2: {#N/A,#N/A,FALSE,"Chart 2 by Prop Type"}
Name _______________a1: {"Assump",#N/A,TRUE,"Proforma";"first",#N/A,TRUE,"Proforma";"second",#N/A,TRUE,"Proforma";"lease1",#N/A,TRUE,"Proforma";"lease2",#N/A,TRUE,"Proforma"}
Name _______________jo2: {#N/A,#N/A,FALSE,"DCF-COM";#N/A,#N/A,FALSE,"VAC-COM"}
Name _______________jo3: {"CASHFLOW",#N/A,FALSE,"Northpointe"}
Name _______________jo4: {#N/A,#N/A,FALSE,"SHEET1";#N/A,#N/A,FALSE,"SHEET2";#N/A,#N/A,FALSE,"SHEET3";#N/A,#N/A,FALSE,"SHEET4"}
Name _______________old2: {#N/A,#N/A,FALSE,"Chart 2 by Prop Type"}
Name _______________old2: {#N/A,#N/A,FALSE,"Chart 2 by Prop Type"}
Name _______________old2: {#N/A,#N/A,FALSE,"Chart 2 by Prop Type"}
Name ______________a1: {"Assump",#N/A,TRUE,"Proforma";"first",#N/A,TRUE,"Proforma";"second",#N/A,TRUE,"Proforma";"lease1",#N/A,TRUE,"Proforma";"lease2",#N/A,TRUE,"Proforma"}
Name ______________jo2: {#N/A,#N/A,FALSE,"DCF-COM";#N/A,#N/A,FALSE,"VAC-COM"}
Name ______________jo3: {"CASHFLOW",#N/A,FALSE,"Northpointe"}
Name ______________jo4: {#N/A,#N/A,FALSE,"SHEET1";#N/A,#N/A,FALSE,"SHEET2";#N/A,#N/A,FALSE,"SHEET3";#N/A,#N/A,FALSE,"SHEET4"}
Name ______________old2: {#N/A,#N/A,FALSE,"Chart 2 by Prop Type"}

Sheet Summary
B3: Sources | H3: Uses | O3: Proforma Operating Summary
D4: % of | L4: % of | T4: Renovation
B5: Investment | C5: Amount | D5: Category | E5: Per Room | F5: LTC | H5: Category | I5: Amount | J5: Per Room | K5: Per SF | L5: Category | T5: Complete
B6: First Mortgage | C6: =Model!I16 -> 23187000 | D6: =C6/$C$8 -> 1 | E6: =C6/Model!$C$10 -> 175659.09 | F6: =C6/$I$19 -> #ERROR! | H6: Historic Building Acquisition | I6: =Model!N4 -> 36436802 | J6: =I6/Model!$C$10 -> 276036.38 | K6: =I6/Model!$C$14 -> 259.54541 | L6: =I6/$I$17 -> #ERROR! | R6: CY | S6: CY | T6: CY | U6: CY | V6: CY | W6: CY | X6: CY | Y6: CY | AA6: CAGR
B7: C-PACE Financing | C7: =Model!J54 | D7: =C7/$C$8 -> 0 | E7: =C7/Model!$C$10 -> 0 | F7: =C7/$I$19 -> #ERROR! | H7: Working Capital First Year | I7: =Model!N6 -> 0 | J7: =I7/Model!$C$10 -> 0 | K7: =I7/Model!$C$14 -> 0 | L7: =I7/$I$17 -> #ERROR! | R7: 2026 | S7: =+R7+1 -> 2027 | T7: =+S7+1 -> 2028 | U7: =+T7+1 -> 2029 | V7: =+U7+1 -> 2030 | W7: =+V7+1 -> 2031 | X7: =+W7+1 -> 2032 | Y7: =+X7+1 -> 2033 | AA7: 26-'33
B8: Total Debt | C8: =SUM(C6:C7) -> 23187000 | D8: =SUM(D6:D7) -> 1 | E8: =C8/Model!$C$10 -> 175659.09 | F8: =C8/$I$19 -> #ERROR! | H8: Premiere Advisory Group Fees | I8: =Model!#REF! -> #ERROR! | J8: =I8/Model!$C$10 -> #ERROR! | K8: =I8/Model!$C$14 -> #ERROR! | L8: =I8/$I$17 -> #ERROR! | O8: OCC | R8: n/a | S8: n/a | T8: {=INDEX('Index Analysis'!$C$12:$R$12,MATCH(Summary!T$7,'Index Analysis'!$C$6:$R$6))} -> 0.74594 | U8: {=INDEX('Index Analysis'!$C$12:$R$12,MATCH(Summary!U$7,'Index Analysis'!$C$6:$R$6))} -> 0.7683182 | V8: {=INDEX('Index Analysis'!$C$12:$R$12,MATCH(Summary!V$7,'Index Analysis'!$C$6:$R$6))} -> 0.77215979 | W8: {=INDEX('Index Analysis'!$C$12:$R$12,MATCH(Summary!W$7,'Index Analysis'!$C$6:$R$6))} -> 0.77215979 | X8: {=INDEX('Index Analysis'!$C$12:$R$12,MATCH(Summary!X$7,'Index Analysis'!$C$6:$R$6))} -> 0.77215979 | Y8: {=INDEX('Index Analysis'!$C$12:$R$12,MATCH(Summary!Y$7,'Index Analysis'!$C$6:$R$6))} -> 0.77215979 | AA8: =IFERROR(+(Y8/T8)^(1/(Y$7-T$7))-1,0) -> 0.0069331928
H9: Development | I9: 3142555.3 | J9: =I9/Model!$C$10 -> 23807.237 | K9: =I9/Model!$C$14 -> 22.384945 | L9: =I9/$I$17 -> #ERROR! | O9: ADR | R9: n/a | S9: n/a | T9: {=INDEX('Index Analysis'!$C$13:$R$13,MATCH(Summary!T$7,'Index Analysis'!$C$6:$R$6))} -> 311.09861 | U9: {=INDEX('Index Analysis'!$C$13:$R$13,MATCH(Summary!U$7,'Index Analysis'!$C$6:$R$6))} -> 323.03977 | V9: {=INDEX('Index Analysis'!$C$13:$R$13,MATCH(Summary!V$7,'Index Analysis'!$C$6:$R$6))} -> 329.50056 | W9: {=INDEX('Index Analysis'!$C$13:$R$13,MATCH(Summary!W$7,'Index Analysis'!$C$6:$R$6))} -> 343.50434 | X9: {=INDEX('Index Analysis'!$C$13:$R$13,MATCH(Summary!X$7,'Index Analysis'!$C$6:$R$6))} -> 357.24451 | Y9: {=INDEX('Index Analysis'!$C$13:$R$13,MATCH(Summary!Y$7,'Index Analysis'!$C$6:$R$6))} -> 364.3894 | AA9: =IFERROR(+(Y9/T9)^(1/(Y$7-T$7))-1,0) -> 0.032127937
B10: LP Members | C10: =D10*C12 -> #ERROR! | D10: 0.9 | E10: =C10/Model!$C$10 -> #ERROR! | F10: =C10/$I$19 -> #ERROR! | H10: Design | I10: 2694240.1 | J10: =I10/Model!$C$10 -> 20410.91 | K10: =I10/Model!$C$14 -> 19.191521 | L10: =I10/$I$17 -> #ERROR! | O10: RevPAR | R10: n/a | S10: n/a | T10: {=INDEX('Index Analysis'!$C$14:$R$14,MATCH(Summary!T$7,'Index Analysis'!$C$6:$R$6))} -> 232.0609 | U10: {=INDEX('Index Analysis'!$C$14:$R$14,MATCH(Summary!U$7,'Index Analysis'!$C$6:$R$6))} -> 248.19733 | V10: {=INDEX('Index Analysis'!$C$14:$R$14,MATCH(Summary!V$7,'Index Analysis'!$C$6:$R$6))} -> 254.42709 | W10: {=INDEX('Index Analysis'!$C$14:$R$14,MATCH(Summary!W$7,'Index Analysis'!$C$6:$R$6))} -> 265.24024 | X10: {=INDEX('Index Analysis'!$C$14:$R$14,MATCH(Summary!X$7,'Index Analysis'!$C$6:$R$6))} -> 275.84985 | Y10: {=INDEX('Index Analysis'!$C$14:$R$14,MATCH(Summary!Y$7,'Index Analysis'!$C$6:$R$6))} -> 281.36684 | AA10: =IFERROR(+(Y10/T10)^(1/(Y$7-T$7))-1,0) -> 0.039283879
B11: GP | C11: =D11*C12 -> #ERROR! | D11: 0.1 | E11: =C11/Model!$C$10 -> #ERROR! | F11: =C11/$I$19 -> #ERROR! | H11: Construction | I11: 57063595 | J11: =I11/Model!$C$10 -> 432299.96 | K11: =I11/Model!$C$14 -> 406.4735 | L11: =I11/$I$17 -> #ERROR! | O11: RevPAR Growth | R11: n/a | S11: n/a | T11: n/a | U11: =+U10/T10-1 -> 0.069535354 | V11: =+V10/U10-1 -> 0.0251 | W11: =+W10/V10-1 -> 0.0425 | X11: =+X10/W10-1 -> 0.04 | Y11: =+Y10/X10-1 -> 0.02
B12: Total Equity | C12: =I17-C8 -> #ERROR! | D12: =SUM(D10:D11) -> 1 | E12: =C12/Model!$C$10 -> #ERROR! | F12: =C12/$I$19 -> #ERROR! | H12: FF&E | I12: 5241613.1 | J12: =I12/Model!$C$10 -> 39709.19 | K12: =I12/Model!$C$14 -> 37.336884 | L12: =I12/$I$17 -> #ERROR! | O12: RevPAR Index | R12: n/a | S12: n/a | T12: {=INDEX('Index Analysis'!$C$33:$R$33,MATCH(Summary!T$7,'Index Analysis'!$C$6:$R$6))} -> 0.99 | U12: {=INDEX('Index Analysis'!$C$33:$R$33,MATCH(Summary!U$7,'Index Analysis'!$C$6:$R$6))} -> 1 | V12: {=INDEX('Index Analysis'!$C$33:$R$33,MATCH(Summary!V$7,'Index Analysis'!$C$6:$R$6))} -> 1 | W12: {=INDEX('Index Analysis'!$C$33:$R$33,MATCH(Summary!W$7,'Index Analysis'!$C$6:$R$6))} -> 1 | X12: {=INDEX('Index Analysis'!$C$33:$R$33,MATCH(Summary!X$7,'Index Analysis'!$C$6:$R$6))} -> 1 | Y12: {=INDEX('Index Analysis'!$C$33:$R$33,MATCH(Summary!Y$7,'Index Analysis'!$C$6:$R$6))} -> 1 | AA12: =IFERROR(+(Y12/T12)^(1/(Y$7-T$7))-1,0) -> 0.0020120887
H13: OS&E and Systems | I13: 1893105.1 | J13: =I13/Model!$C$10 -> 14341.705 | K13: =I13/Model!$C$14 -> 13.484903 | L13: =I13/$I$17 -> #ERROR!
H14: Pre-Opening | I14: 1896183.6 | J14: =I14/Model!$C$10 -> 14365.027 | K14: =I14/Model!$C$14 -> 13.506832 | L14: =I14/$I$17 -> #ERROR! | O14: $000's
H15: Contingencies | I15: =Model!E42+I23 -> 323653.8 | J15: =I15/Model!$C$10 -> 2451.9227 | K15: =I15/Model!$C$14 -> 2.30544 | L15: =I15/$I$17 -> #ERROR!
H16: Financing Costs & Int. Reserves | I16: =SUM(Model!#REF!,Model!N8,Model!N13) -> #ERROR! | J16: =I16/Model!$C$10 -> #ERROR! | K16: =I16/Model!$C$14 -> #ERROR! | L16: =I16/$I$17 -> #ERROR! | O16: Rooms | R16: n/a | S16: n/a | T16: {=INDEX(Proforma!$J$22:$AL$22,MATCH(Summary!T$7,Proforma!$J$6:$AL$6))/1000} -> 11180.694 | U16: {=INDEX(Proforma!$J$22:$AL$22,MATCH(Summary!U$7,Proforma!$J$6:$AL$6))/1000} -> 11990.91 | V16: {=INDEX(Proforma!$J$22:$AL$22,MATCH(Summary!V$7,Proforma!$J$6:$AL$6))/1000} -> 12258.297 | W16: {=INDEX(Proforma!$J$22:$AL$22,MATCH(Summary!W$7,Proforma!$J$6:$AL$6))/1000} -> 12258.297 | X16: {=INDEX(Proforma!$J$22:$AL$22,MATCH(Summary!X$7,Proforma!$J$6:$AL$6))/1000} -> 12258.297 | Y16: {=INDEX(Proforma!$J$22:$AL$22,MATCH(Summary!Y$7,Proforma!$J$6:$AL$6))/1000} -> 12258.297 | AA16: =IFERROR(+(Y16/T16)^(1/(Y$7-T$7))-1,0) -> 0.018573272
H17: Total Debt | I17: =SUM(I6:I16) -> #ERROR! | J17: =I17/Model!$C$10 -> #ERROR! | K17: =I17/Model!$C$14 -> #ERROR! | L17: =SUM(L6:L16) -> #ERROR! | O17: Food & Beverage | R17: n/a | S17: n/a | T17: {=INDEX(Proforma!$J$23:$AL$23,MATCH(Summary!T$7,Proforma!$J$6:$AL$6))/1000} -> 3382.2938 | U17: {=INDEX(Proforma!$J$23:$AL$23,MATCH(Summary!U$7,Proforma!$J$6:$AL$6))/1000} -> 3545.7068 | V17: {=INDEX(Proforma!$J$23:$AL$23,MATCH(Summary!V$7,Proforma!$J$6:$AL$6))/1000} -> 3607.0046 | W17: {=INDEX(Proforma!$J$23:$AL$23,MATCH(Summary!W$7,Proforma!$J$6:$AL$6))/1000} -> 3607.0046 | X17: {=INDEX(Proforma!$J$23:$AL$23,MATCH(Summary!X$7,Proforma!$J$6:$AL$6))/1000} -> 3607.0046 | Y17: {=INDEX(Proforma!$J$23:$AL$23,MATCH(Summary!Y$7,Proforma!$J$6:$AL$6))/1000} -> 3607.0046 | AA17: =IFERROR(+(Y17/T17)^(1/(Y$7-T$7))-1,0) -> 0.01294782
O18: Parking | T18: {=INDEX(Proforma!$J$24:$AL$24,MATCH(Summary!T$7,Proforma!$J$6:$AL$6))/1000} -> 0 | U18: {=INDEX(Proforma!$J$24:$AL$24,MATCH(Summary!U$7,Proforma!$J$6:$AL$6))/1000} -> 0 | V18: {=INDEX(Proforma!$J$24:$AL$24,MATCH(Summary!V$7,Proforma!$J$6:$AL$6))/1000} -> 0 | W18: {=INDEX(Proforma!$J$24:$AL$24,MATCH(Summary!W$7,Proforma!$J$6:$AL$6))/1000} -> 0 | X18: {=INDEX(Proforma!$J$24:$AL$24,MATCH(Summary!X$7,Proforma!$J$6:$AL$6))/1000} -> 0 | Y18: {=INDEX(Proforma!$J$24:$AL$24,MATCH(Summary!Y$7,Proforma!$J$6:$AL$6))/1000} -> 0 | AA18: =IFERROR(+(Y18/T18)^(1/(Y$7-T$7))-1,0) -> 0
B19: Total | C19: =SUM(C12,C8) -> #ERROR! | D19: =SUM(C8,C12)/C19 -> #ERROR! | E19: =C19/Model!$C$10 -> #ERROR! | F19: =C19/$I$19 -> #ERROR! | H19: Total | I19: =I17 -> #ERROR! | J19: =I19/Model!$C$10 -> #ERROR! | K19: =I19/Model!$C$14 -> #ERROR! | L19: =I19/$I$17 -> #ERROR! | O19: Misc. Income | T19: {=INDEX(Proforma!$J$25:$AL$25,MATCH(Summary!T$7,Proforma!$J$6:$AL$6))/1000} -> 150.32417 | U19: {=INDEX(Proforma!$J$25:$AL$25,MATCH(Summary!U$7,Proforma!$J$6:$AL$6))/1000} -> 157.58697 | V19: {=INDEX(Proforma!$J$25:$AL$25,MATCH(Summary!V$7,Proforma!$J$6:$AL$6))/1000} -> 160.31132 | W19: {=INDEX(Proforma!$J$25:$AL$25,MATCH(Summary!W$7,Proforma!$J$6:$AL$6))/1000} -> 160.31132 | X19: {=INDEX(Proforma!$J$25:$AL$25,MATCH(Summary!X$7,Proforma!$J$6:$AL$6))/1000} -> 160.31132 | Y19: {=INDEX(Proforma!$J$25:$AL$25,MATCH(Summary!Y$7,Proforma!$J$6:$AL$6))/1000} -> 160.31132 | AA19: =IFERROR(+(Y19/T19)^(1/(Y$7-T$7))-1,0) -> 0.01294782
O20: Resort Fees | T20: {=INDEX(Proforma!$J$26:$AL$26,MATCH(Summary!T$7,Proforma!$J$6:$AL$6))/1000} -> 1352.9175 | U20: {=INDEX(Proforma!$J$26:$AL$26,MATCH(Summary!U$7,Proforma!$J$6:$AL$6))/1000} -> 1418.2827 | V20: {=INDEX(Proforma!$J$26:$AL$26,MATCH(Summary!V$7,Proforma!$J$6:$AL$6))/1000} -> 1442.8018 | W20: {=INDEX(Proforma!$J$26:$AL$26,MATCH(Summary!W$7,Proforma!$J$6:$AL$6))/1000} -> 1442.8018 | X20: {=INDEX(Proforma!$J$26:$AL$26,MATCH(Summary!X$7,Proforma!$J$6:$AL$6))/1000} -> 1442.8018 | Y20: {=INDEX(Proforma!$J$26:$AL$26,MATCH(Summary!Y$7,Proforma!$J$6:$AL$6))/1000} -> 1442.8018 | AA20: =IFERROR(+(Y20/T20)^(1/(Y$7-T$7))-1,0) -> 0.01294782
I21: =ROUND(I19,-3) -> #ERROR! | O21: Meetings & Events | T21: {=INDEX(Proforma!$J$27:$AL$27,MATCH(Summary!T$7,Proforma!$J$6:$AL$6))/1000} -> 503.80784 | U21: {=INDEX(Proforma!$J$27:$AL$27,MATCH(Summary!U$7,Proforma!$J$6:$AL$6))/1000} -> 512.76596 | V21: {=INDEX(Proforma!$J$27:$AL$27,MATCH(Summary!V$7,Proforma!$J$6:$AL$6))/1000} -> 519.03543 | W21: {=INDEX(Proforma!$J$27:$AL$27,MATCH(Summary!W$7,Proforma!$J$6:$AL$6))/1000} -> 519.03543 | X21: {=INDEX(Proforma!$J$27:$AL$27,MATCH(Summary!X$7,Proforma!$J$6:$AL$6))/1000} -> 519.03543 | Y21: {=INDEX(Proforma!$J$27:$AL$27,MATCH(Summary!Y$7,Proforma!$J$6:$AL$6))/1000} -> 519.03543 | AA21: =IFERROR(+(Y21/T21)^(1/(Y$7-T$7))-1,0) -> 0.0059732139
O22: Rent & Other (8th Floor 1,685 SF) | T22: {=INDEX(Proforma!$J$28:$AL$28,MATCH(Summary!T$7,Proforma!$J$6:$AL$6))/1000} -> 23.664806 | U22: {=INDEX(Proforma!$J$28:$AL$28,MATCH(Summary!U$7,Proforma!$J$6:$AL$6))/1000} -> 24.37475 | V22: {=INDEX(Proforma!$J$28:$AL$28,MATCH(Summary!V$7,Proforma!$J$6:$AL$6))/1000} -> 25.105993 | W22: {=INDEX(Proforma!$J$28:$AL$28,MATCH(Summary!W$7,Proforma!$J$6:$AL$6))/1000} -> 25.105993 | X22: {=INDEX(Proforma!$J$28:$AL$28,MATCH(Summary!X$7,Proforma!$J$6:$AL$6))/1000} -> 25.105993 | Y22: {=INDEX(Proforma!$J$28:$AL$28,MATCH(Summary!Y$7,Proforma!$J$6:$AL$6))/1000} -> 25.105993 | AA22: =IFERROR(+(Y22/T22)^(1/(Y$7-T$7))-1,0) -> 0.011893695
I23: 253.80117 | O23: Total Revenue | R23: n/a | S23: n/a | T23: {=INDEX(Proforma!$J$29:$AL$29,MATCH(Summary!T$7,Proforma!$J$6:$AL$6))/1000} -> 16593.702 | U23: {=INDEX(Proforma!$J$29:$AL$29,MATCH(Summary!U$7,Proforma!$J$6:$AL$6))/1000} -> 17649.627 | V23: {=INDEX(Proforma!$J$29:$AL$29,MATCH(Summary!V$7,Proforma!$J$6:$AL$6))/1000} -> 18012.556 | W23: {=INDEX(Proforma!$J$29:$AL$29,MATCH(Summary!W$7,Proforma!$J$6:$AL$6))/1000} -> 18012.556 | X23: {=INDEX(Proforma!$J$29:$AL$29,MATCH(Summary!X$7,Proforma!$J$6:$AL$6))/1000} -> 18012.556 | Y23: {=INDEX(Proforma!$J$29:$AL$29,MATCH(Summary!Y$7,Proforma!$J$6:$AL$6))/1000} -> 18012.556 | AA23: =IFERROR(+(Y23/T23)^(1/(Y$7-T$7))-1,0) -> 0.01654454
T24: =SUM(T16:T22)=T23 -> TRUE | U24: =SUM(U16:U22)=U23 -> TRUE | V24: =SUM(V16:V22)=V23 -> TRUE | W24: =SUM(W16:W22)=W23 -> TRUE | X24: =SUM(X16:X22)=X23 -> TRUE | Y24: =SUM(Y16:Y22)=Y23 -> TRUE
O26: GOP | R26: n/a | S26: n/a | T26: {=INDEX(Proforma!$J$63:$AL$63,MATCH(Summary!T$7,Proforma!$J$6:$AL$6))/1000} -> 7452.9547 | U26: {=INDEX(Proforma!$J$63:$AL$63,MATCH(Summary!U$7,Proforma!$J$6:$AL$6))/1000} -> 8063.7005 | V26: {=INDEX(Proforma!$J$63:$AL$63,MATCH(Summary!V$7,Proforma!$J$6:$AL$6))/1000} -> 8258.1976 | W26: {=INDEX(Proforma!$J$63:$AL$63,MATCH(Summary!W$7,Proforma!$J$6:$AL$6))/1000} -> 8258.1976 | X26: {=INDEX(Proforma!$J$63:$AL$63,MATCH(Summary!X$7,Proforma!$J$6:$AL$6))/1000} -> 8258.1976 | Y26: {=INDEX(Proforma!$J$63:$AL$63,MATCH(Summary!Y$7,Proforma!$J$6:$AL$6))/1000} -> 8258.1976 | AA26: =IFERROR(+(Y26/T26)^(1/(Y$7-T$7))-1,0) -> 0.020731126
O27: EBITDA | R27: n/a | S27: n/a | T27: {=INDEX(Proforma!$J$77:$AL$77,MATCH(Summary!T$7,Proforma!$J$6:$AL$6))/1000} -> 5056.307 | U27: {=INDEX(Proforma!$J$77:$AL$77,MATCH(Summary!U$7,Proforma!$J$6:$AL$6))/1000} -> 5577.0147 | V27: {=INDEX(Proforma!$J$77:$AL$77,MATCH(Summary!V$7,Proforma!$J$6:$AL$6))/1000} -> 5702.3244 | W27: {=INDEX(Proforma!$J$77:$AL$77,MATCH(Summary!W$7,Proforma!$J$6:$AL$6))/1000} -> 5702.3244 | X27: {=INDEX(Proforma!$J$77:$AL$77,MATCH(Summary!X$7,Proforma!$J$6:$AL$6))/1000} -> 5702.3244 | Y27: {=INDEX(Proforma!$J$77:$AL$77,MATCH(Summary!Y$7,Proforma!$J$6:$AL$6))/1000} -> 5702.3244 | AA27: =IFERROR(+(Y27/T27)^(1/(Y$7-T$7))-1,0) -> 0.024338975
O28: FF&E Reserve | T28: {=INDEX(Proforma!$J$79:$AL$79,MATCH(Summary!T$7,Proforma!$J$6:$AL$6))/1000} -> 663.74809 | U28: {=INDEX(Proforma!$J$79:$AL$79,MATCH(Summary!U$7,Proforma!$J$6:$AL$6))/1000} -> 705.98507 | V28: {=INDEX(Proforma!$J$79:$AL$79,MATCH(Summary!V$7,Proforma!$J$6:$AL$6))/1000} -> 720.50225 | W28: {=INDEX(Proforma!$J$79:$AL$79,MATCH(Summary!W$7,Proforma!$J$6:$AL$6))/1000} -> 720.50225 | X28: {=INDEX(Proforma!$J$79:$AL$79,MATCH(Summary!X$7,Proforma!$J$6:$AL$6))/1000} -> 720.50225 | Y28: {=INDEX(Proforma!$J$79:$AL$79,MATCH(Summary!Y$7,Proforma!$J$6:$AL$6))/1000} -> 720.50225 | AA28: =IFERROR(+(Y28/T28)^(1/(Y$7-T$7))-1,0) -> 0.01654454
O30: NOI | R30: n/a | S30: n/a | T30: {=INDEX(Proforma!$J$81:$AL$81,MATCH(Summary!T$7,Proforma!$J$6:$AL$6))/1000} -> 4392.5589 | U30: {=INDEX(Proforma!$J$81:$AL$81,MATCH(Summary!U$7,Proforma!$J$6:$AL$6))/1000} -> 4871.0297 | V30: {=INDEX(Proforma!$J$81:$AL$81,MATCH(Summary!V$7,Proforma!$J$6:$AL$6))/1000} -> 4981.8222 | W30: {=INDEX(Proforma!$J$81:$AL$81,MATCH(Summary!W$7,Proforma!$J$6:$AL$6))/1000} -> 4981.8222 | X30: {=INDEX(Proforma!$J$81:$AL$81,MATCH(Summary!X$7,Proforma!$J$6:$AL$6))/1000} -> 4981.8222 | Y30: {=INDEX(Proforma!$J$81:$AL$81,MATCH(Summary!Y$7,Proforma!$J$6:$AL$6))/1000} -> 4981.8222 | AA30: =IFERROR(+(Y30/T30)^(1/(Y$7-T$7))-1,0) -> 0.025496364
O31: Yield-On-Cost | T31: =+(T30*1000)/Model!$N$14 -> 0.10317789 | U31: =+(U30*1000)/Model!$N$14 -> 0.1144168 | V31: =+(V30*1000)/Model!$N$14 -> 0.11701924 | W31: =+(W30*1000)/Model!$N$14 -> 0.11701924 | X31: =+(X30*1000)/Model!$N$14 -> 0.11701924 | Y31: =+(Y30*1000)/Model!$N$14 -> 0.11701924

Sheet Model
B2: Property Overview | G2: Senior Loan Financing Assumptions | K2: Transaction Uses
B3: Name | C3: Kimpton Anglers | G3: Month Funding | I3: =O27 -> 0 | N3: Amount | O3: Per Key | P3: %
B4: Type | C4: Hotel | G4: Start Date | I4: =$P$27 -> 45930 | K4: Hotel Purchase Price | N4: =$C$21 -> 36436802 | O4: =N4/$C$10 -> 276036.38 | P4: =N4/$N$14 -> 0.85587291
B5: Location | C5: Miami, FL | G5: Term | I5: =4*12 -> 48 | K5: DD Closing Costs | M5: =$I$24 -> 0.02 | N5: =M5*N4 -> 728736.03 | O5: =N5/$C$10 -> 5520.7275 | P5: =N5/$N$14 -> 0.017117458
B6: Labor | C6: Non-Union | G6: Maturity Date | I6: =EOMONTH(I4,I5) -> 47391 | K6: Working Capital First Year | N6: =M6*N5 -> 0 | O6: =N6/$C$10 -> 0 | P6: =N6/$N$14 -> 0
B7: Title | C7: Fee-Simple | G7: Senior Acq. Cost | I7: =($N$4+$N$5+$N$6+$N$7+$N$10+$N$12) -> 42392979 | K7: Renovation Expense | N7: =E43 -> 4943400 | O7: =N7/$C$10 -> 37450 | P7: =N7/$N$14 -> 0.11611673
B8: Year Built | C8: 2027 | G8: LTC Amount | I8: =I9*I7 -> 27555436 | K8: Senior Loan Total Costs | N8: =SUM(N9) -> 463740 | O8: =N8/$C$10 -> 3513.1818 | P8: =N8/$N$14 -> 0.010892902
B9: Pre-Renovation Keys | C9: 132 | G9: LTC | I9: 0.65 | K9: Orgination Fee | M9: =$I$24 -> 0.02 | N9: =M9*$I$16 -> 463740 | O9: =N9/$C$10 -> 3513.1818 | P9: =N9/$N$14 -> 0.010892902
B10: Post-Renovation Keys | C10: 132 | G10: LTV Amount | I10: =$C$21*I11 -> 23683921 | K10: Tax Reserve - 6 Months of Year 1 | N10: =Proforma!O70/12*6 -> 284041.1 | O10: =N10/$C$10 -> 2151.8265 | P10: =N10/$N$14 -> 0.0066719107
B11: Pre-Renovation Floors | C11: 1 | G11: LTV Amount | I11: 0.65 | K11: Insurance Reserve - 3 Months of Year 1 | N11: =Proforma!O71/12*3 -> 299057.14 | O11: =N11/$C$10 -> 2265.5844 | P11: =N11/$N$14 -> 0.0070246262
B12: Post-Renovation Floors | C12: 5 | G12: DY Amount | I12: =I14/I15 -> 23187056 | K12: Capex Reserve | N12: 0 | O12: =N12/$C$10 -> 0 | P12: =N12/$N$14 -> 0
B13: Pre-Renovation Total SF | C13: 0 | G13: DY Date | I13: =C20 -> 45930 | K13: Senior Loan Cap. Interest Reserve | N13: 0 | O13: =N13/$C$10 -> 0 | P13: =N13/$N$14 -> 0 | Q13: ='Debt & Refi'!E23 -> 980000
B14: Post-Renovation Total SF | C14: 140387 | G14: DY NOI | I14: {=INDEX(Proforma!$AR$83:$DK$83,MATCH($I$13,Proforma!$AR$25:$DK$25))} -> 2550576.1 | K14: Total Uses | N14: =SUM(N4:N7,N8,N13) -> 42572678 | O14: =N14/$C$10 -> 322520.28 | P14: =SUM(P4:P7,P8,P13) -> 1
G15: DY % | I15: 0.11
B16: Entry Valuation | G16: Loan Amount | I16: =ROUND(MIN(I10,I12),-3) -> 23187000 | K16: Transaction Sources
B17: NOI | C17: 7620000 | G17: Variable (1) or Fixed (2) | I17: 1 | N17: Amount | O17: Per Key | P17: %
B18: Entry Cap Rate | C18: 0.07 | G18: Spread over SOFR | I18: 0.035 | K18: Debt | N18: =SUM(N19) -> 23187000 | O18: =N18/$C$10 -> 175659.09 | P18: =N18/$N$23 -> 0.54464509
B19: 2025 Run-Rate NOI | C19: {=INDEX(Proforma!$AR$83:$DK$83,MATCH($C$20,Proforma!$AR$25:$DK$25))} -> 2550576.1 | G19: SOFR Rate | I19: {=INDEX('1-month SOFR - UST '!$Q$9:$Q$1048576,MATCH(I$4,'1-month SOFR - UST '!$O$9:$O$1048576,0))} -> 0.0415518 | K19: Senior Loan | M19: =I18 -> 0.035 | N19: =I16 -> 23187000 | O19: =N19/$C$10 -> 175659.09 | P19: =N19/$N$23 -> 0.54464509
B20: FTM Date | C20: =I4 -> 45930 | G20: SOFR Floor | I20: 0 | K20: Tax Incentive Financing | N20: 0 | O20: =N20/$C$10 -> 0 | P20: =N20/$N$23 -> 0
B21: Hotel Purchase Price | C21: =C19/C18 -> 36436802 | G21: SOFR Ceiling | I21: 1 | K21: Key Money | N21: 0 | O21: =N21/$C$10 -> 0 | P21: =N21/$N$23 -> 0
B22: Per Key | C22: =$C$21/$C$9 -> 276036.38 | G22: Interest Only Period | I22: =4*12 -> 48 | K22: Equity | N22: =N14-SUM(N18,N20,N21) -> 19385678 | O22: =N22/$C$10 -> 146861.19 | P22: =N22/$N$23 -> 0.45535491
G23: Amortization Period | I23: 30 | K23: Total Sources | N23: =SUM(N18,N20:N22) -> 42572678 | O23: =N23/$C$10 -> 322520.28 | P23: =+N23/$N$23 -> 1
B24: Exit Valuation | G24: Origination Fee | I24: 0.02 | N24: =SUM(N18,N20:N22) -> 42572678
B25: Exit Month | C25: =O37 -> 52 | G25: Interest Only | I25: 1 | K25: Transaction Timeline
B26: Exit Date | C26: =$P$37 -> 47514 | N26: Start | O26: Duration | P26: Finish
B27: Fwd. 12 Months NOI | C27: =N39 -> 4440847.5 | G27: Senior Loan Refinancing Metrics | K27: Hotel Purchase | N27: 45930 | O27: 0 | P27: =+EOMONTH(N27,O27) -> 45930
B28: Exit Cap Rate | C28: 0.065 | G28: Month Funding | I28: =O29 -> 30 | K28: Senior Loan Interest-Only Period | N28: =P27 -> 45930 | O28: =I22 -> 48 | P28: =+EOMONTH(N28,O28) -> 47391
B29: Gross Exit Value | C29: =$C$27/$C$28 -> 68320731 | G29: Start Date | I29: =$P$35 -> 46843 | K29: Senior Loan Perm Loan Payoff | N29: =N27 -> 45930 | O29: =DATEDIF(N29,P29,"M") -> 30 | P29: =P35 -> 46843
B30: Per Key | C30: =$C$29/$C$10 -> 517581.3 | G30: Refi Term | I30: 360 | K30: Acq. To Renovation | N30: =P27 -> 45930 | P30: =+EOMONTH(N30,O30-1) -> 45900
B31: Exit Sales Cost | C31: 0.015 | G31: Maturity Date | I31: =EOMONTH(I29,I30) -> 57800 | K31: Renovation | N31: 46053 | O31: 8 | P31: =+EOMONTH(N31,O31-1) -> 46265
B32: Transfer Tax | C32: 0.5 | G32: LTV Amount | I32: =$I$33*O39 -> 51240548 | K32: Completed Renovation | N32: =+EOMONTH(P31,0) -> 46265 | O32: 0 | P32: =+EOMONTH(N32,O32) -> 46265
B33: Hold Years | C33: =$O$37/12 -> 4.3333333 | G33: LTV | I33: 0.75 | K33: Receive Key Money | N33: =+EOMONTH(P32,0) -> 46265 | O33: 2 | P33: =+EOMONTH(N33,O33) -> 46326
G34: Loan Proceeds | I34: =MIN('Debt & Refi'!$E$34:$E$36) -> 40371341 | K34: Ramp-Up Period | N34: =P32 -> 46265 | O34: 12 | P34: =+EOMONTH(N34,O34) -> 46630
G35: Loan Payoff | I35: =-I34 -> -40371341 | K35: Senior Loan Refi | N35: =+EOMONTH(P34,3) -> 46721 | O35: 4 | P35: =+EOMONTH(N35,O35) -> 46843
B36: Renovation Budget | G36: Cash Pulled Out | I36: =SUM(I34:I35) -> 0 | K36: Disposition After Refi | N36: =+EOMONTH(P35,0)+1 -> 46844 | O36: 8 | P36: =+EOMONTH(N36,O36) -> 47118
B37: =35000*C9 -> 4620000 | C37: Per Key | D37: Per SF | E37: Total | G37: Variable (1) or Fixed (2) | I37: 1 | K37: Investment Hold Period | N37: =N27 -> 45930 | O37: =DATEDIF(N37,P37,"M") -> 52 | P37: 47514
B38: Renovation | C38: =E38/$C$10 -> 35000 | D38: =E38/$C$14 -> 32.90903 | E38: =SUM(E39:E41) -> 4620000 | G38: Spread over SOFR | I38: 0.04 | K38: Practical Completion (FTM NOI, Value) | N38: {=INDEX(Proforma!$AR$83:$DK$83,MATCH(Model!$P$38,Proforma!$AR$25:$DK$25))} -> 4440847.5 | O38: {=INDEX(Proforma!$AR$83:$DK$83,MATCH(Model!$P$38,Proforma!$AR$25:$DK$25))/$C$28} -> 68320731 | P38: =EOMONTH(P27,36) -> 47026
B39: Hard Costs (75%) | C39: =E39/$C$10 -> 26250 | D39: =E39/$C$14 -> 24.681773 | E39: =75%*$B$37 -> 3465000 | G39: Interest Rate Type | I39: Floating | K39: Stabilized (FTM NOI, Value) | N39: {=INDEX(Proforma!$AR$83:$DK$83,MATCH(Model!$P$39,Proforma!$AR$25:$DK$25))} -> 4440847.5 | O39: =C29 -> 68320731 | P39: 47026
B40: Soft Costs (20%) | C40: =E40/$C$10 -> 7000 | D40: =E40/$C$14 -> 6.581806 | E40: =20%*$B$37 -> 924000 | G40: SOFR Rate | I40: {=INDEX('1-month SOFR - UST '!$Q$9:$Q$1048576,MATCH(I$29,'1-month SOFR - UST '!$O$9:$O$1048576,0))} -> 0.0327905
B41: Professional Fees (5%) | C41: =E41/$C$10 -> 1750 | D41: =E41/$C$14 -> 1.6454515 | E41: =5%*$B$37 -> 231000 | G41: SOFR Floor | I41: 0
...

Sheet Debt & Refi
B2: Senior Loan Financing | G2: Year | I2: =ROUNDUP(I3,12) -> 0 | J2: =ROUNDUP(J3/12,0) -> 1 | K2: =ROUNDUP(K3/12,0) -> 1 | L2: =ROUNDUP(L3/12,0) -> 1 | M2: =ROUNDUP(M3/12,0) -> 1 | N2: =ROUNDUP(N3/12,0) -> 1 | O2: =ROUNDUP(O3/12,0) -> 1 | P2: =ROUNDUP(P3/12,0) -> 1 | Q2: =ROUNDUP(Q3/12,0) -> 1 | ... NH2: =ROUNDUP(NH3/12,0) -> 31
B3: Funding Date | C3: Month | D3: =Model!I3 -> 0 | E3: {=(INDEX(Model!$S$71:$EU$71,MATCH($D$3,Model!$S$70:$EU$70,0)))} -> 45930 | G3: Month | I3: 0 | J3: =I3+1 -> 1 | K3: =J3+1 -> 2 | L3: =K3+1 -> 3 | M3: =L3+1 -> 4 | N3: =M3+1 -> 5 | O3: =N3+1 -> 6 | P3: =O3+1 -> 7 | Q3: =P3+1 -> 8 | ... NH3: =NG3+1 -> 363
B4: Development Cost | G4: Date | I4: =$E$3 -> 45930 | J4: =EOMONTH(I4,1) -> 45961 | K4: =EOMONTH(J4,1) -> 45991 | L4: =EOMONTH(K4,1) -> 46022 | M4: =EOMONTH(L4,1) -> 46053 | N4: =EOMONTH(M4,1) -> 46081 | O4: =EOMONTH(N4,1) -> 46112 | P4: =EOMONTH(O4,1) -> 46142 | Q4: =EOMONTH(P4,1) -> 46173 | ... NH4: =EOMONTH(NG4,1) -> 56979
B5: Stablized Value | E5: =Model!$O$39 -> 68320731 | G5: Senior Debt
G6: Interest Rate
B7: Senior Debt | G7: SOFR Ceiling | I7: =$E$14/12 -> 0.083333333 | J7: =$E$14/12 -> 0.083333333 | K7: =$E$14/12 -> 0.083333333 | L7: =$E$14/12 -> 0.083333333 | M7: =$E$14/12 -> 0.083333333 | N7: =$E$14/12 -> 0.083333333 | O7: =$E$14/12 -> 0.083333333 | P7: =$E$14/12 -> 0.083333333 | ... NH7: =$E$14/12 -> 0.083333333 | NI7: x
B8: New (1) or Assuming Loan (2) | E8: 1 | G8: Floating SOFR | I8: {=INDEX('1-month SOFR - UST '!$Q$9:$Q$1048576,MATCH(I$4,'1-month SOFR - UST '!$O$9:$O$1048576,0))/12} -> 0.00346265 | J8: {=INDEX('1-month SOFR - UST '!$Q$9:$Q$1048576,MATCH(J$4,'1-month SOFR - UST '!$O$9:$O$1048576,0))/12} -> 0.0033381417 | K8: {=INDEX('1-month SOFR - UST '!$Q$9:$Q$1048576,MATCH(K$4,'1-month SOFR - UST '!$O$9:$O$1048576,0))/12} -> 0.0033019167 | L8: {=INDEX('1-month SOFR - UST '!$Q$9:$Q$1048576,MATCH(L$4,'1-month SOFR - UST '!$O$9:$O$1048576,0))/12} -> 0.00312115 | M8: {=INDEX('1-month SOFR - UST '!$Q$9:$Q$1048576,MATCH(M$4,'1-month SOFR - UST '!$O$9:$O$1048576,0))/12} -> 0.0030814667 | N8: {=INDEX('1-month SOFR - UST '!$Q$9:$Q$1048576,MATCH(N$4,'1-month SOFR - UST '!$O$9:$O$1048576,0))/12} -> 0.0030439083 | O8: {=INDEX('1-month SOFR - UST '!$Q$9:$Q$1048576,MATCH(O$4,'1-month SOFR - UST '!$O$9:$O$1048576,0))/12} -> 0.0030013 | P8: {=INDEX('1-month SOFR - UST '!$Q$9:$Q$1048576,MATCH(P$4,'1-month SOFR - UST '!$O$9:$O$1048576,0))/12} -> 0.0029483583 | ... NH8: {=INDEX('1-month SOFR - UST '!$Q$9:$Q$1048576,MATCH(NH$4,'1-month SOFR - UST '!$O$9:$O$1048576,0))/12} -> #N/A | NI8: x
B9: Amount | C9: =$E$9/$E$4 -> #DIV/0! | D9: =$E$9/$E$5 -> 0.3466579 | E9: =MAX(Model!$I$10,Model!$I$12) -> 23683921 | G9: Spread over SOFR | I9: =$E$13/12 -> 0.0029166667 | J9: =$E$13/12 -> 0.0029166667 | K9: =$E$13/12 -> 0.0029166667 | L9: =$E$13/12 -> 0.0029166667 | M9: =$E$13/12 -> 0.0029166667 | N9: =$E$13/12 -> 0.0029166667 | O9: =$E$13/12 -> 0.0029166667 | P9: =$E$13/12 -> 0.0029166667 | ... NH9: =$E$13/12 -> 0.0029166667 | NI9: x
B10: Requested Amount | E10: =Model!$I$16 -> 23187000 | G10: SOFR Floor | I10: =$E$15/12 -> 0 | J10: =$E$15/12 -> 0 | K10: =$E$15/12 -> 0 | L10: =$E$15/12 -> 0 | M10: =$E$15/12 -> 0 | N10: =$E$15/12 -> 0 | O10: =$E$15/12 -> 0 | P10: =$E$15/12 -> 0 | ... NH10: =$E$15/12 -> 0 | NI10: x
B11: Loan Fees | C11: =Model!$I$24 -> 0.02 | E11: =$E$9*C11 -> 473678.42 | G11: Interest Rate Used | I11: =IF(C12=2,$E$12/12,MIN(MAX(I10,I8),I7)+I9) -> 0.0063793167 | J11: =IF(D12=2,$E$12/12,MIN(MAX(J10,J8),J7)+J9) -> 0.0062548083 | K11: =IF(E12=2,$E$12/12,MIN(MAX(K10,K8),K7)+K9) -> 0.0062185833 | L11: =IF(F12=2,$E$12/12,MIN(MAX(L10,L8),L7)+L9) -> 0.0060378167 | M11: =IF(G18=2,$E$12/12,MIN(MAX(M10,M8),M7)+M9) -> 0.0059981333 | N11: =IF(H18=2,$E$12/12,MIN(MAX(N10,N8),N7)+N9) -> 0.005960575 | O11: =IF(I18=2,$E$12/12,MIN(MAX(O10,O8),O7)+O9) -> 0.0059179667 | P11: =IF(J18=2,$E$12/12,MIN(MAX(P10,P8),P7)+P9) -> 0.005865025 | Q11: =IF(K18=2,$E$12/12,MIN(MAX(Q10,Q8),Q7)+Q9) -> 0.0058334167 | R11: =IF(L18=2,$E$12/12,MIN(MAX(R10,R8),R7)+R9) -> 0.0057108 | S11: =IF(M18=2,$E$12/12,MIN(MAX(S10,S8),S7)+S9) -> 0.0056870167 | T11: =IF(N18=2,$E$12/12,MIN(MAX(T10,T8),T7)+T9) -> 0.005687275 | ... NH11: =IF(NB18=2,$E$12/12,MIN(MAX(NH10,NH8),NH7)+NH9) -> #N/A | NI11: x
B12: Variable (1) or Fixed (2) | C12: =Model!$I$17 -> 1 | E12: =Model!$I$19 -> 0.0415518 | NI12: x
B13: Spread over SOFR | E13: =Model!$I$18 -> 0.035 | G13: Beginning Balance | I13: =H20 | J13: =I20 -> 23187000 | K13: =J20 -> 23187000 | L13: =K20 -> 23187000 | M13: =L20 -> 23187000 | N13: =M20 -> 23187000 | O13: =N20 -> 23187000 | P13: =O20 -> 23187000 | ... NH13: =NG20 -> #N/A | NI13: x
B14: SOFR Ceiling | E14: =Model!$I$21 -> 1 | G14: Payment | I14: =IF(I3="","",AND(I3>$E$17,I3<=$E$18)*((I3<=$E$19)*I13*I16+(I3>$E$19)*PMT(I16,$E$16,-$E$9))) -> 0 | J14: =IF(J3="","",AND(J3>$E$17,J3<=$E$18)*((J3<=$E$19)*J13*J16+(J3>$E$19)*PMT(J16,$E$16,-$E$9))) -> 145030.24 | K14: =IF(K3="","",AND(K3>$E$17,K3<=$E$18)*((K3<=$E$19)*K13*K16+(K3>$E$19)*PMT(K16,$E$16,-$E$9))) -> 144190.29 | L14: =IF(L3="","",AND(L3>$E$17,L3<=$E$18)*((L3<=$E$19)*L13*L16+(L3>$E$19)*PMT(L16,$E$16,-$E$9))) -> 139998.86 | M14: =IF(M3="","",AND(M3>$E$17,M3<=$E$18)*((M3<=$E$19)*M13*M16+(M3>$E$19)*PMT(M16,$E$16,-$E$9))) -> 139078.72 | N14: =IF(N3="","",AND(N3>$E$17,N3<=$E$18)*((N3<=$E$19)*N13*N16+(N3>$E$19)*PMT(N16,$E$16,-$E$9))) -> 138207.85 | O14: =IF(O3="","",AND(O3>$E$17,O3<=$E$18)*((O3<=$E$19)*O13*O16+(O3>$E$19)*PMT(O16,$E$16,-$E$9))) -> 137219.89 | P14: =IF(P3="","",AND(P3>$E$17,P3<=$E$18)*((P3<=$E$19)*P13*P16+(P3>$E$19)*PMT(P16,$E$16,-$E$9))) -> 135992.33 | ... NH14: =IF(NH3="","",AND(NH3>$E$17,NH3<=$E$18)*((NH3<=$E$19)*NH13*NH16+(NH3>$E$19)*PMT(NH16,$E$16,-$E$9))) -> #N/A | NI14: x
B15: SOFR Floor | E15: =Model!$I$20 -> 0 | G15: Interest | I15: =I13*I16 -> 0 | J15: =J13*J16 -> 145030.24 | K15: =K13*K16 -> 144190.29 | L15: =L13*L16 -> 139998.86 | M15: =M13*M16 -> 139078.72 | N15: =N13*N16 -> 138207.85 | O15: =O13*O16 -> 137219.89 | P15: =P13*P16 -> 135992.33 | ... NH15: =NH13*NH16 -> #N/A | NI15: x
B16: Amortization | D16: =$E$16/12 -> 30 | E16: =Model!$I$23*12 -> 360 | G16: Rate (Monthly) | I16: =I11 -> 0.0063793167 | J16: =J11 -> 0.0062548083 | K16: =K11 -> 0.0062185833 | L16: =L11 -> 0.0060378167 | M16: =M11 -> 0.0059981333 | N16: =N11 -> 0.005960575 | O16: =O11 -> 0.0059179667 | P16: =P11 -> 0.005865025 | ... NG16: =NG11 -> #N/A | NH16: =IF($C$12=1,NH6,$E$12/12) | NI16: x
B17: Funding Month | E17: =$D$3 -> 0 | G17: Principal | I17: =I14-I15 -> 0 | J17: =J14-J15 -> 0 | K17: =K14-K15 -> 0 | L17: =L14-L15 -> 0 | M17: =M14-M15 -> 0 | N17: =N14-N15 -> 0 | O17: =O14-O15 -> 0 | P17: =P14-P15 -> 0 | ... NH17: =NH14-NH15 -> #N/A | NI17: x
B18: Payoff Month | E18: =Model!$O$29 -> 30 | G18: Loan Funding | I18: =IF(I3=$D$3,$E$10,0) -> 23187000 | J18: =IF(J3=$D$3,$E$10,0) -> 0 | K18: =IF(K3=$D$3,$E$10,0) -> 0 | L18: =IF(L3=$D$3,$E$10,0) -> 0 | M18: =IF(M3=$D$3,$E$10,0) -> 0 | N18: =IF(N3=$D$3,$E$10,0) -> 0 | O18: =IF(O3=$D$3,$E$10,0) -> 0 | P18: =IF(P3=$D$3,$E$10,0) -> 0 | ... NH18: =IF(NH3=$D$3,$E$10,0) -> 0 | NI18: x
B19: Interest-Only Period | D19: =$E$19/12 -> 4 | E19: =Model!$O$28 -> 48 | G19: Loan Payoff | I19: =IF(I3=$E$18,H20-I17,0) -> 0 | J19: =IF(J3=$E$18,I20-J17,0) -> 0 | K19: =IF(K3=$E$18,J20-K17,0) -> 0 | L19: =IF(L3=$E$18,K20-L17,0) -> 0 | M19: =IF(M3=$E$18,L20-M17,0) -> 0 | N19: =IF(N3=$E$18,M20-N17,0) -> 0 | O19: =IF(O3=$E$18,N20-O17,0) -> 0 | P19: =IF(P3=$E$18,O20-P17,0) -> 0 | ... NH19: =IF(NH3=$E$18,NG20-NH17,0) -> 0 | NI19: x
B20: Fixed Amort. Payments (Monthly) | E20: =PMT(E12/12,E16,-E9) -> 115199.73 | G20: Ending Balance | I20: =I13-I17+I18-I19 -> 23187000 | J20: =J13-J17+J18-J19 -> 23187000 | K20: =K13-K17+K18-K19 -> 23187000 | L20: =L13-L17+L18-L19 -> 23187000 | M20: =M13-M17+M18-M19 -> 23187000 | N20: =N13-N17+N18-N19 -> 23187000 | O20: =O13-O17+O18-O19 -> 23187000 | P20: =P13-P17+P18-P19 -> 23187000 | ... NH20: =NH13-NH17+NH18-NH19 -> #N/A | NI20: x
B21: Fixed IO Payments (Monthly) | E21: =E9*(E12/12) -> 82009.129
B22: Payoff @ Loan Maturity | E22: =MAX(I19:DY19) -> 23187000
B23: Capitalized Interest - 6 Months Opening | E23: =ROUND(SUM(I14:P14),-3) -> 980000
B28: Senior Loan (Refinance) Financing | G28: Senior Debt (Refinance) | NI28: x
B29: Funding Date | C29: Month | D29: =Model!$I$28 -> 30 | E29: =Model!$P$35 -> 46843 | G29: Interest Rate | NI29: x
G30: SOFR Ceiling | I30: =$E$40/12 -> 0.083333333 | J30: =$E$40/12 -> 0.083333333 | K30: =$E$40/12 -> 0.083333333 | L30: =$E$40/12 -> 0.083333333 | M30: =$E$40/12 -> 0.083333333 | N30: =$E$40/12 -> 0.083333333 | O30: =$E$40/12 -> 0.083333333 | P30: =$E$40/12 -> 0.083333333 | ... NH30: =$E$40/12 -> 0.083333333 | NI30: x
G31: Floating SOFR | I31: {=INDEX('1-month SOFR - UST '!$Q$9:$Q$1048576,MATCH(I$4,'1-month SOFR - UST '!$O$9:$O$1048576,0))/12} -> 0.00346265 | J31: {=INDEX('1-month SOFR - UST '!$Q$9:$Q$1048576,MATCH(J$4,'1-month SOFR - UST '!$O$9:$O$1048576,0))/12} -> 0.0033381417 | K31: {=INDEX('1-month SOFR - UST '!$Q$9:$Q$1048576,MATCH(K$4,'1-month SOFR - UST '!$O$9:$O$1048576,0))/12} -> 0.0033019167 | L31: {=INDEX('1-month SOFR - UST '!$Q$9:$Q$1048576,MATCH(L$4,'1-month SOFR - UST '!$O$9:$O$1048576,0))/12} -> 0.00312115 | M31: {=INDEX('1-month SOFR - UST '!$Q$9:$Q$1048576,MATCH(M$4,'1-month SOFR - UST '!$O$9:$O$1048576,0))/12} -> 0.0030814667 | N31: {=INDEX('1-month SOFR - UST '!$Q$9:$Q$1048576,MATCH(N$4,'1-month SOFR - UST '!$O$9:$O$1048576,0))/12} -> 0.0030439083 | O31: {=INDEX('1-month SOFR - UST '!$Q$9:$Q$1048576,MATCH(O$4,'1-month SOFR - UST '!$O$9:$O$1048576,0))/12} -> 0.0030013 | P31: {=INDEX('1-month SOFR - UST '!$Q$9:$Q$1048576,MATCH(P$4,'1-month SOFR - UST '!$O$9:$O$1048576,0))/12} -> 0.0029483583 | ... NH31: {=INDEX('1-month SOFR - UST '!$Q$9:$Q$1048576,MATCH(NH$4,'1-month SOFR - UST '!$O$9:$O$1048576,0))/12} -> #N/A | NI31: {=INDEX('1-month SOFR - UST '!$Q$9:$Q$1048576,MATCH(NI$6,'1-month SOFR - UST '!$O$9:$O$1048576,0))} -> #N/A
B32: Senior Debt (Refinance) | G32: Spread over SOFR | I32: =$E$39/12 -> 0.0033333333 | J32: =$E$39/12 -> 0.0033333333 | K32: =$E$39/12 -> 0.0033333333 | L32: =$E$39/12 -> 0.0033333333 | M32: =$E$39/12 -> 0.0033333333 | N32: =$E$39/12 -> 0.0033333333 | O32: =$E$39/12 -> 0.0033333333 | P32: =$E$39/12 -> 0.0033333333 | ... NH32: =$E$39/12 -> 0.0033333333 | NI32: x
B33: Refinance | E33: =$E$18<(Model!$O$37) -> TRUE | G33: SOFR Floor | I33: =$E$15/12 -> 0 | J33: =$E$15/12 -> 0 | K33: =$E$15/12 -> 0 | L33: =$E$15/12 -> 0 | M33: =$E$15/12 -> 0 | N33: =$E$15/12 -> 0 | O33: =$E$15/12 -> 0 | P33: =$E$15/12 -> 0 | ... NH33: =$E$15/12 -> 0 | NI33: x
B34: Amount | E34: =E36 -> 51240548 | G34: Interest Rate Used | I34: =IF(C37=2,$E$12/12,MIN(MAX(I33,I31),I30)+I32) -> 0.0067959833 | J34: =IF(D37=2,$E$12/12,MIN(MAX(J33,J31),J30)+J32) -> 0.006671475 | K34: =IF(E37=2,$E$12/12,MIN(MAX(K33,K31),K30)+K32) -> 0.00663525 | L34: =IF(F36=2,$E$12/12,MIN(MAX(L33,L31),L30)+L32) -> 0.0064544833 | M34: =IF(G42=2,$E$12/12,MIN(MAX(M33,M31),M30)+M32) -> 0.0064148 | N34: =IF(H42=2,$E$12/12,MIN(MAX(N33,N31),N30)+N32) -> 0.0063772417 | O34: =IF(I42=2,$E$12/12,MIN(MAX(O33,O31),O30)+O32) -> 0.0063346333 | P34: =IF(J42=2,$E$12/12,MIN(MAX(P33,P31),P30)+P32) -> 0.0062816917 | Q34: =IF(K42=2,$E$12/12,MIN(MAX(Q33,Q31),Q30)+Q32) -> 0.0062500833 | R34: =IF(L42=2,$E$12/12,MIN(MAX(R33,R31),R30)+R32) -> 0.0061274667 | S34: =IF(M42=2,$E$12/12,MIN(MAX(S33,S31),S30)+S32) -> 0.0061036833 | T34: =IF(N42=2,$E$12/12,MIN(MAX(T33,T31),T30)+T32) -> 0.0061039417 | ... NH34: =IF(NB42=2,$E$12/12,MIN(MAX(NH33,NH31),NH30)+NH32) -> #N/A | NI34: x
B35: DY FTM NOI | C35: 0.11 | D35: =Model!$N$39 -> 4440847.5 | E35: =$D$35/$C$35 -> 40371341
B36: Stabilized Value | C36: =Model!I33 -> 0.75 | D36: =Model!$O$39 -> 68320731 | E36: =$C$36*$D$36 -> 51240548 | G36: Beginning Balance | I36: =H43 | J36: =I43 -> 0 | K36: =J43 -> 0 | L36: =K43 -> 0 | M36: =L43 -> 0 | N36: =M43 -> 0 | O36: =N43 -> 0 | P36: =O43 -> 0 | ... NH36: =NG43 -> #N/A | NI36: x
B37: Loan Fees | C37: =Model!$I$45 -> 0.01 | E37: =E34*'Debt & Refi'!$C$37 -> 512405.48 | G37: Payment | I37: =IF(I3="","",AND(I3>$E$43,I3<=$E$44)*((I3<=$E$45)*I36*I39+(I3>$E$45)*PMT(I39,$E$42,-$E$34))) -> 0 | J37: =IF(J3="","",AND(J3>$E$43,J3<=$E$44)*((J3<=$E$45)*J36*J39+(J3>$E$45)*PMT(J39,$E$42,-$E$34))) -> 0 | K37: =IF(K3="","",AND(K3>$E$43,K3<=$E$44)*((K3<=$E$45)*K36*K39+(K3>$E$45)*PMT(K39,$E$42,-$E$34))) -> 0 | L37: =IF(L3="","",AND(L3>$E$43,L3<=$E$44)*((L3<=$E$45)*L36*L39+(L3>$E$45)*PMT(L39,$E$42,-$E$34))) -> 0 | M37: =IF(M3="","",AND(M3>$E$43,M3<=$E$44)*((M3<=$E$45)*M36*M39+(M3>$E$45)*PMT(M39,$E$42,-$E$34))) -> 0 | N37: =IF(N3="","",AND(N3>$E$43,N3<=$E$44)*((N3<=$E$45)*N36*N39+(N3>$E$45)*PMT(N39,$E$42,-$E$34))) -> 0 | O37: =IF(O3="","",AND(O3>$E$43,O3<=$E$44)*((O3<=$E$45)*O36*O39+(O3>$E$45)*PMT(O39,$E$42,-$E$34))) -> 0 | P37: =IF(P3="","",AND(P3>$E$43,P3<=$E$44)*((P3<=$E$45)*P36*P39+(P3>$E$45)*PMT(P39,$E$42,-$E$34))) -> 0 | ... NH37: =IF(NH3="","",AND(NH3>$E$43,NH3<=$E$44)*((NH3<=$E$45)*NH36*NH39+(NH3>$E$45)*PMT(NH39,$E$42,-$E$34))) -> #N/A | NI37: =IF(NI22="","",AND(NI22>$E$43,NI22<=$E$44)*((NI22<=$E$45)*NI36*NI39+(NI22>$E$45)*PMT(NI39,$E$42,-$E$34)))
B38: Variable (1) or Fixed (2) | C38: =Model!$I$37 -> 1 | E38: =Model!$I$40 -> 0.0327905 | G38: Interest | I38: =I36*I39 -> 0 | J38: =J36*J39 -> 0 | K38: =K36*K39 -> 0 | L38: =L36*L39 -> 0 | M38: =M36*M39 -> 0 | N38: =N36*N39 -> 0 | O38: =O36*O39 -> 0 | P38: =P36*P39 -> 0 | ... NH38: =NH36*NH39 -> #N/A | NI38: x
B39: Spread over SOFR | E39: =Model!$I$38 -> 0.04 | G39: Rate (Monthly) | I39: =I34 -> 0.0067959833 | J39: =J34 -> 0.006671475 | K39: =K34 -> 0.00663525 | L39: =L34 -> 0.0064544833 | M39: =M34 -> 0.0064148 | N39: =N34 -> 0.0063772417 | O39: =O34 -> 0.0063346333 | P39: =P34 -> 0.0062816917 | ... NH39: =NH34 -> #N/A | NI39: x
B40: SOFR Ceiling | E40: =Model!$I$42 -> 1 | G40: Principal | I40: =I37-I38 -> 0 | J40: =J37-J38 -> 0 | K40: =K37-K38 -> 0 | L40: =L37-L38 -> 0 | M40: =M37-M38 -> 0 | N40: =N37-N38 -> 0 | O40: =O37-O38 -> 0 | P40: =P37-P38 -> 0 | ... NH40: =NH37-NH38 -> #N/A | NI40: x
B41: SOFR Floor | E41: =Model!$I$41 -> 0 | G41: Loan Funding | I41: =IF(I3=$E$43,$E$34,0) -> 0 | J41: =IF(J3=$E$43,$E$34,0) -> 0 | K41: =IF(K3=$E$43,$E$34,0) -> 0 | L41: =IF(L3=$E$43,$E$34,0) -> 0 | M41: =IF(M3=$E$43,$E$34,0) -> 0 | N41: =IF(N3=$E$43,$E$34,0) -> 0 | O41: =IF(O3=$E$43,$E$34,0) -> 0 | P41: =IF(P3=$E$43,$E$34,0) -> 0 | ... NH41: =IF(NH3=$E$43,$E$34,0) -> 0 | NI41: =IF(NI22=$D$3,$E$34,0) -> 51240548
B42: Amortization | D42: =$E$16/12 -> 30 | E42: =Model!$I$44*12 -> 360 | G42: Loan Payoff | I42: =IF(I3=$E$44,H43-I40,0) -> 0 | J42: =IF(J3=$E$44,I43-J40,0) -> 0 | K42: =IF(K3=$E$44,J43-K40,0) -> 0 | L42: =IF(L3=$E$44,K43-L40,0) -> 0 | M42: =IF(M3=$E$44,L43-M40,0) -> 0 | N42: =IF(N3=$E$44,M43-N40,0) -> 0 | O42: =IF(O3=$E$44,N43-O40,0) -> 0 | P42: =IF(P3=$E$44,O43-P40,0) -> 0 | ... NH42: =IF(NH3=$E$44,NG43-NH40,0) -> 0 | NI42: =IF(NI22=$E$44,NH43-NI40,0) -> 0
B43: Funding Month | E43: =Model!$O$29 -> 30 | G43: Ending Balance | I43: =I36-I40+I41-I42 -> 0 | J43: =J36-J40+J41-J42 -> 0 | K43: =K36-K40+K41-K42 -> 0 | L43: =L36-L40+L41-L42 -> 0 | M43: =M36-M40+M41-M42 -> 0 | N43: =N36-N40+N41-N42 -> 0 | O43: =O36-O40+O41-O42 -> 0 | P43: =P36-P40+P41-P42 -> 0 | ... NH43: =NH36-NH40+NH41-NH42 -> #N/A | NI43: x
B44: Payoff Month | E44: =Model!$O$37 -> 52 | NI44: x
B45: Interest-Only Period | D45: =$E$19/12 -> 4 | E45: =Model!$O$28 -> 48 | G45: Total Permanent Financing | NI45: x
...

Sheet Debt Schedule
A1: =Model!C3 -> Kimpton Anglers | J1: =EOMONTH(TODAY(),1) -> 46081
B2: Borrower | C2: TBD | M2: Year | O2: ='Debt & Refi'!I2 -> 0 | P2: ='Debt & Refi'!J2 -> 1 | Q2: ='Debt & Refi'!K2 -> 1 | R2: ='Debt & Refi'!L2 -> 1 | S2: ='Debt & Refi'!M2 -> 1 | T2: ='Debt & Refi'!N2 -> 1 | U2: ='Debt & Refi'!O2 -> 1 | V2: ='Debt & Refi'!P2 -> 1 | ... NN2: ='Debt & Refi'!NH2 -> 31
B3: Lender | C3: TBD | M3: Month | O3: ='Debt & Refi'!I3 -> 0 | P3: ='Debt & Refi'!J3 -> 1 | Q3: ='Debt & Refi'!K3 -> 2 | R3: ='Debt & Refi'!L3 -> 3 | S3: ='Debt & Refi'!M3 -> 4 | T3: ='Debt & Refi'!N3 -> 5 | U3: ='Debt & Refi'!O3 -> 6 | V3: ='Debt & Refi'!P3 -> 7 | ... NN3: ='Debt & Refi'!NH3 -> 363
B4: Original Total Loan Amount | C4: =++SUM(C5:C6) -> 65000000 | M4: Date | O4: ='Debt & Refi'!I4 -> 45930 | P4: ='Debt & Refi'!J4 -> 45961 | Q4: ='Debt & Refi'!K4 -> 45991 | R4: ='Debt & Refi'!L4 -> 46022 | S4: ='Debt & Refi'!M4 -> 46053 | T4: ='Debt & Refi'!N4 -> 46081 | U4: ='Debt & Refi'!O4 -> 46112 | V4: ='Debt & Refi'!P4 -> 46142 | ... NN4: ='Debt & Refi'!NH4 -> 56979
B5: Senior Loan Amount | C5: 35000000 | E5: Rate: SOFR + | F5: 0.05 | M5: Senior Debt
B6: PACE Loan Amount | C6: 30000000 | E6: Rate: SOFR + | F6: 0.05 | M6: Interest Rate
B7: Current Total Loan Balance | C7: =SUM(C8:C9) -> #N/A | M7: SOFR Ceiling | O7: ='Debt & Refi'!I7 -> 0.083333333 | P7: ='Debt & Refi'!J7 -> 0.083333333 | Q7: ='Debt & Refi'!K7 -> 0.083333333 | R7: ='Debt & Refi'!L7 -> 0.083333333 | S7: ='Debt & Refi'!M7 -> 0.083333333 | T7: ='Debt & Refi'!N7 -> 0.083333333 | U7: ='Debt & Refi'!O7 -> 0.083333333 | V7: ='Debt & Refi'!P7 -> 0.083333333 | ... NN7: ='Debt & Refi'!NH7 -> 0.083333333
B8: Senior Loan Balance | C8: {=INDEX($J$45:$BK$45,MATCH($J$1,$J$42:$BK$42))} -> #N/A | E8: Rate: SOFR + | F8: =++F5 -> 0.05 | M8: Floating SOFR | O8: ='Debt & Refi'!I8 -> 0.00346265 | P8: ='Debt & Refi'!J8 -> 0.0033381417 | Q8: ='Debt & Refi'!K8 -> 0.0033019167 | R8: ='Debt & Refi'!L8 -> 0.00312115 | S8: ='Debt & Refi'!M8 -> 0.0030814667 | T8: ='Debt & Refi'!N8 -> 0.0030439083 | U8: ='Debt & Refi'!O8 -> 0.0030013 | V8: ='Debt & Refi'!P8 -> 0.0029483583 | ... NN8: ='Debt & Refi'!NH8 -> #N/A
B9: Construction Loan Balance | C9: {=INDEX(#REF!,MATCH($J$1,$J$42:$BK$42))} -> #N/A | E9: Rate: SOFR + | F9: =F5 -> 0.05 | M9: Spread over SOFR | O9: ='Debt & Refi'!I9 -> 0.0029166667 | P9: ='Debt & Refi'!J9 -> 0.0029166667 | Q9: ='Debt & Refi'!K9 -> 0.0029166667 | R9: ='Debt & Refi'!L9 -> 0.0029166667 | S9: ='Debt & Refi'!M9 -> 0.0029166667 | T9: ='Debt & Refi'!N9 -> 0.0029166667 | U9: ='Debt & Refi'!O9 -> 0.0029166667 | V9: ='Debt & Refi'!P9 -> 0.0029166667 | ... NN9: ='Debt & Refi'!NH9 -> 0.0029166667
B10: Origination Date | C10: 46112 | M10: SOFR Floor | O10: ='Debt & Refi'!I10 -> 0 | P10: ='Debt & Refi'!J10 -> 0 | Q10: ='Debt & Refi'!K10 -> 0 | R10: ='Debt & Refi'!L10 -> 0 | S10: ='Debt & Refi'!M10 -> 0 | T10: ='Debt & Refi'!N10 -> 0 | U10: ='Debt & Refi'!O10 -> 0 | V10: ='Debt & Refi'!P10 -> 0 | ... NN10: ='Debt & Refi'!NH10 -> 0
B11: Initial Maturity Date | C11: =++EDATE(C10,36) -> 47208 | E11: Current Maturity | F11: =++C11 -> 47208 | M11: Interest Rate Used | O11: ='Debt & Refi'!I11 -> 0.0063793167 | P11: ='Debt & Refi'!J11 -> 0.0062548083 | Q11: ='Debt & Refi'!K11 -> 0.0062185833 | R11: ='Debt & Refi'!L11 -> 0.0060378167 | S11: ='Debt & Refi'!M11 -> 0.0059981333 | T11: ='Debt & Refi'!N11 -> 0.005960575 | U11: ='Debt & Refi'!O11 -> 0.0059179667 | V11: ='Debt & Refi'!P11 -> 0.005865025 | ... NN11: ='Debt & Refi'!NH11 -> #N/A
B12: Extension Options | C12: Two one-year extension terms
B13: Rate Cap | C13: 0.06 | E13: Expiry Date: | F13: 46200 | M13: Beginning Balance | O13: ='Debt & Refi'!I13 | P13: ='Debt & Refi'!J13 -> 23187000 | Q13: ='Debt & Refi'!K13 -> 23187000 | R13: ='Debt & Refi'!L13 -> 23187000 | S13: ='Debt & Refi'!M13 -> 23187000 | T13: ='Debt & Refi'!N13 -> 23187000 | U13: ='Debt & Refi'!O13 -> 23187000 | V13: ='Debt & Refi'!P13 -> 23187000 | ... NN13: ='Debt & Refi'!NH13 -> #N/A
B14: Rate Ceiling | C14: N/A | E14: Rate Floor | F14: 0.03 | M14: Payment | O14: ='Debt & Refi'!I14 -> 0 | P14: ='Debt & Refi'!J14 -> 145030.24 | Q14: ='Debt & Refi'!K14 -> 144190.29 | R14: ='Debt & Refi'!L14 -> 139998.86 | S14: ='Debt & Refi'!M14 -> 139078.72 | T14: ='Debt & Refi'!N14 -> 138207.85 | U14: ='Debt & Refi'!O14 -> 137219.89 | V14: ='Debt & Refi'!P14 -> 135992.33 | ... NN14: ='Debt & Refi'!NH14 -> #N/A
B15: Current Blended Interest Rate | C15: N/A | M15: Interest | O15: ='Debt & Refi'!I15 -> 0 | P15: ='Debt & Refi'!J15 -> 145030.24 | Q15: ='Debt & Refi'!K15 -> 144190.29 | R15: ='Debt & Refi'!L15 -> 139998.86 | S15: ='Debt & Refi'!M15 -> 139078.72 | T15: ='Debt & Refi'!N15 -> 138207.85 | U15: ='Debt & Refi'!O15 -> 137219.89 | V15: ='Debt & Refi'!P15 -> 135992.33 | ... NN15: ='Debt & Refi'!NH15 -> #N/A
B16: Effective Rate (with Cap) | C16: =IFERROR(C13+F5,"N/A") -> 0.11 | M16: Rate (Monthly) | O16: ='Debt & Refi'!I16 -> 0.0063793167 | P16: ='Debt & Refi'!J16 -> 0.0062548083 | Q16: ='Debt & Refi'!K16 -> 0.0062185833 | R16: ='Debt & Refi'!L16 -> 0.0060378167 | S16: ='Debt & Refi'!M16 -> 0.0059981333 | T16: ='Debt & Refi'!N16 -> 0.005960575 | U16: ='Debt & Refi'!O16 -> 0.0059179667 | V16: ='Debt & Refi'!P16 -> 0.005865025 | ... NN16: ='Debt & Refi'!NH16
B17: Interest Only | C17: Yes | M17: Principal | O17: ='Debt & Refi'!I17 -> 0 | P17: ='Debt & Refi'!J17 -> 0 | Q17: ='Debt & Refi'!K17 -> 0 | R17: ='Debt & Refi'!L17 -> 0 | S17: ='Debt & Refi'!M17 -> 0 | T17: ='Debt & Refi'!N17 -> 0 | U17: ='Debt & Refi'!O17 -> 0 | V17: ='Debt & Refi'!P17 -> 0 | ... NN17: ='Debt & Refi'!NH17 -> #N/A
B18: Cap or Swap Expiry Date | C18: =++EDATE(C10,24) -> 46843 | M18: Loan Funding | O18: ='Debt & Refi'!I18 -> 23187000 | P18: ='Debt & Refi'!J18 -> 0 | Q18: ='Debt & Refi'!K18 -> 0 | R18: ='Debt & Refi'!L18 -> 0 | S18: ='Debt & Refi'!M18 -> 0 | T18: ='Debt & Refi'!N18 -> 0 | U18: ='Debt & Refi'!O18 -> 0 | V18: ='Debt & Refi'!P18 -> 0 | ... NN18: ='Debt & Refi'!NH18 -> 0
B19: Lockout Prepayment Date | C19: N/A | M19: Loan Payoff | O19: ='Debt & Refi'!I19 -> 0 | P19: ='Debt & Refi'!J19 -> 0 | Q19: ='Debt & Refi'!K19 -> 0 | R19: ='Debt & Refi'!L19 -> 0 | S19: ='Debt & Refi'!M19 -> 0 | T19: ='Debt & Refi'!N19 -> 0 | U19: ='Debt & Refi'!O19 -> 0 | V19: ='Debt & Refi'!P19 -> 0 | ... NN19: ='Debt & Refi'!NH19 -> 0
B20: Prepayment Fee | C20: Greater of (i) yield maintenance through thr 18th payment date and (II) 1% of loan amount | M20: Ending Balance | O20: ='Debt & Refi'!I20 -> 23187000 | P20: ='Debt & Refi'!J20 -> 23187000 | Q20: ='Debt & Refi'!K20 -> 23187000 | R20: ='Debt & Refi'!L20 -> 23187000 | S20: ='Debt & Refi'!M20 -> 23187000 | T20: ='Debt & Refi'!N20 -> 23187000 | U20: ='Debt & Refi'!O20 -> 23187000 | V20: ='Debt & Refi'!P20 -> 23187000 | ... NN20: ='Debt & Refi'!NH20 -> #N/A
B21: Open Prepayment Date | C21: =++EDATE(C10,18) -> 46660
B22: Debt Yield Threshold (i) | C22: 0.1 | D22: Until: | E22: =EOMONTH(C10,39) -> 47299 | G22: Test Frequency: | H22: Quarterly starting 12/31/2028 | M22: Senior Debt (Refinance) | NO22: x
B23: Debt Yield Threshold (ii) | C23: 0.11 | D23: Until: | E23: =EOMONTH(E22,6) -> 47483 | M23: Interest Rate | NO23: x
B24: Debt Yield Threshold (Senior + PACE) | C24: N/A | D24: Until: | E24: =E23 -> 47483 | G24: Test Frequency: | H24: Quarterly starting 6/30/2028 | M24: SOFR Ceiling | O24: ='Debt & Refi'!I30 -> 0.083333333 | P24: ='Debt & Refi'!J30 -> 0.083333333 | Q24: ='Debt & Refi'!K30 -> 0.083333333 | R24: ='Debt & Refi'!L30 -> 0.083333333 | S24: ='Debt & Refi'!M30 -> 0.083333333 | T24: ='Debt & Refi'!N30 -> 0.083333333 | U24: ='Debt & Refi'!O30 -> 0.083333333 | V24: ='Debt & Refi'!P30 -> 0.083333333 | ... NO24: ='Debt & Refi'!NI30 -> x
B25: DSCR Threshold (i) | C25: 1 | D25: Until: | E25: =E22 -> 47299 | G25: Test Frequency: | H25: Quarterly starting 12/31/2028 | M25: Floating SOFR | O25: ='Debt & Refi'!I31 -> 0.00346265 | P25: ='Debt & Refi'!J31 -> 0.0033381417 | Q25: ='Debt & Refi'!K31 -> 0.0033019167 | R25: ='Debt & Refi'!L31 -> 0.00312115 | S25: ='Debt & Refi'!M31 -> 0.0030814667 | T25: ='Debt & Refi'!N31 -> 0.0030439083 | U25: ='Debt & Refi'!O31 -> 0.0030013 | V25: ='Debt & Refi'!P31 -> 0.0029483583 | ... NO25: ='Debt & Refi'!NI31 -> #N/A
B26: DSCR Threshold (ii) | C26: 1.2 | D26: Until: | E26: =EOMONTH(E25,6) -> 47483 | M26: Spread over SOFR | O26: ='Debt & Refi'!I32 -> 0.0033333333 | P26: ='Debt & Refi'!J32 -> 0.0033333333 | Q26: ='Debt & Refi'!K32 -> 0.0033333333 | R26: ='Debt & Refi'!L32 -> 0.0033333333 | S26: ='Debt & Refi'!M32 -> 0.0033333333 | T26: ='Debt & Refi'!N32 -> 0.0033333333 | U26: ='Debt & Refi'!O32 -> 0.0033333333 | V26: ='Debt & Refi'!P32 -> 0.0033333333 | ... NO26: ='Debt & Refi'!NI32 -> x
B27: DSCR Threshold (Senior + PACE) | C27: 1.25 | D27: Until: | E27: =E26 -> 47483 | G27: Test Frequency: | H27: Quarterly starting 12/31/2028 | M27: SOFR Floor | O27: ='Debt & Refi'!I33 -> 0 | P27: ='Debt & Refi'!J33 -> 0 | Q27: ='Debt & Refi'!K33 -> 0 | R27: ='Debt & Refi'!L33 -> 0 | S27: ='Debt & Refi'!M33 -> 0 | T27: ='Debt & Refi'!N33 -> 0 | U27: ='Debt & Refi'!O33 -> 0 | V27: ='Debt & Refi'!P33 -> 0 | ... NO27: ='Debt & Refi'!NI33 -> x
B28: DY Cure / Carry Reserve (i) | C28: =++C22+0.25% -> 0.1025 | D28: For 2 consecutive quarters; 25 bps above applicable DY threshold | M28: Interest Rate Used | O28: ='Debt & Refi'!I34 -> 0.0067959833 | P28: ='Debt & Refi'!J34 -> 0.006671475 | Q28: ='Debt & Refi'!K34 -> 0.00663525 | R28: ='Debt & Refi'!L34 -> 0.0064544833 | S28: ='Debt & Refi'!M34 -> 0.0064148 | T28: ='Debt & Refi'!N34 -> 0.0063772417 | U28: ='Debt & Refi'!O34 -> 0.0063346333 | V28: ='Debt & Refi'!P34 -> 0.0062816917 | ... NO28: ='Debt & Refi'!NI34 -> x
B29: DY Cure / Carry Reserve (ii) | C29: =++C23+0.25% -> 0.1125 | D29: For 2 consecutive quarters; 25 bps above applicable DY threshold
B30: DSCR Cure / Carry Reserve | C30: N/A | M30: Beginning Balance | O30: ='Debt & Refi'!I36 | P30: ='Debt & Refi'!J36 -> 0 | Q30: ='Debt & Refi'!K36 -> 0 | R30: ='Debt & Refi'!L36 -> 0 | S30: ='Debt & Refi'!M36 -> 0 | T30: ='Debt & Refi'!N36 -> 0 | U30: ='Debt & Refi'!O36 -> 0 | V30: ='Debt & Refi'!P36 -> 0 | ... NO30: ='Debt & Refi'!NI36 -> x
B31: LTV Ratio Max | C31: 0.65 | M31: Payment | O31: ='Debt & Refi'!I37 -> 0 | P31: ='Debt & Refi'!J37 -> 0 | Q31: ='Debt & Refi'!K37 -> 0 | R31: ='Debt & Refi'!L37 -> 0 | S31: ='Debt & Refi'!M37 -> 0 | T31: ='Debt & Refi'!N37 -> 0 | U31: ='Debt & Refi'!O37 -> 0 | V31: ='Debt & Refi'!P37 -> 0 | ... NO31: ='Debt & Refi'!NI37
B32: Debt Yield - extension 1 | C32: 0.1025 | D32: Only for extension option | M32: Interest | O32: ='Debt & Refi'!I38 -> 0 | P32: ='Debt & Refi'!J38 -> 0 | Q32: ='Debt & Refi'!K38 -> 0 | R32: ='Debt & Refi'!L38 -> 0 | S32: ='Debt & Refi'!M38 -> 0 | T32: ='Debt & Refi'!N38 -> 0 | U32: ='Debt & Refi'!O38 -> 0 | V32: ='Debt & Refi'!P38 -> 0 | ... NO32: ='Debt & Refi'!NI38 -> x
B33: Debt Yield - extension 2 | C33: 0.115 | D33: Only for extension option | M33: Rate (Monthly) | O33: ='Debt & Refi'!I39 -> 0.0067959833 | P33: ='Debt & Refi'!J39 -> 0.006671475 | Q33: ='Debt & Refi'!K39 -> 0.00663525 | R33: ='Debt & Refi'!L39 -> 0.0064544833 | S33: ='Debt & Refi'!M39 -> 0.0064148 | T33: ='Debt & Refi'!N39 -> 0.0063772417 | U33: ='Debt & Refi'!O39 -> 0.0063346333 | V33: ='Debt & Refi'!P39 -> 0.0062816917 | ... NO33: ='Debt & Refi'!NI39 -> x
B34: Cash Trap | C34: Yes | D34: Two consecutive quarters of threshold failures | M34: Principal | O34: ='Debt & Refi'!I40 -> 0 | P34: ='Debt & Refi'!J40 -> 0 | Q34: ='Debt & Refi'!K40 -> 0 | R34: ='Debt & Refi'!L40 -> 0 | S34: ='Debt & Refi'!M40 -> 0 | T34: ='Debt & Refi'!N40 -> 0 | U34: ='Debt & Refi'!O40 -> 0 | V34: ='Debt & Refi'!P40 -> 0 | ... NO34: ='Debt & Refi'!NI40 -> x
B35: Distribution Blocker | C35: N/A | M35: Loan Funding | O35: ='Debt & Refi'!I41 -> 0 | P35: ='Debt & Refi'!J41 -> 0 | Q35: ='Debt & Refi'!K41 -> 0 | R35: ='Debt & Refi'!L41 -> 0 | S35: ='Debt & Refi'!M41 -> 0 | T35: ='Debt & Refi'!N41 -> 0 | U35: ='Debt & Refi'!O41 -> 0 | V35: ='Debt & Refi'!P41 -> 0 | ... NO35: ='Debt & Refi'!NI41 -> 51240548
B36: Exit Fee | C36: N/A | M36: Loan Payoff | O36: ='Debt & Refi'!I42 -> 0 | P36: ='Debt & Refi'!J42 -> 0 | Q36: ='Debt & Refi'!K42 -> 0 | R36: ='Debt & Refi'!L42 -> 0 | S36: ='Debt & Refi'!M42 -> 0 | T36: ='Debt & Refi'!N42 -> 0 | U36: ='Debt & Refi'!O42 -> 0 | V36: ='Debt & Refi'!P42 -> 0 | ... NO36: ='Debt & Refi'!NI42 -> 0
M37: Ending Balance | O37: ='Debt & Refi'!I43 -> 0 | P37: ='Debt & Refi'!J43 -> 0 | Q37: ='Debt & Refi'!K43 -> 0 | R37: ='Debt & Refi'!L43 -> 0 | S37: ='Debt & Refi'!M43 -> 0 | T37: ='Debt & Refi'!N43 -> 0 | U37: ='Debt & Refi'!O43 -> 0 | V37: ='Debt & Refi'!P43 -> 0 | ... NO37: ='Debt & Refi'!NI43 -> x
B41: Quarterly Analysis
C42: 47118 | D42: =EOMONTH(C42,3) -> 47208 | E42: =EOMONTH(D42,3) -> 47299 | F42: =EOMONTH(E42,3) -> 47391 | G42: =EOMONTH(F42,3) -> 47483 | H42: =EOMONTH(G42,3) -> 47573 | J42: 46783 | K42: =EOMONTH(J42,1) -> 46812 | L42: =EOMONTH(K42,1) -> 46843 | M42: =EOMONTH(L42,1) -> 46873 | N42: =EOMONTH(M42,1) -> 46904 | O42: =EOMONTH(N42,1) -> 46934 | P42: =EOMONTH(O42,1) -> 46965 | Q42: =EOMONTH(P42,1) -> 46996 | R42: =EOMONTH(Q42,1) -> 47026 | ... BK42: =EOMONTH(BJ42,1) -> 48395
C43: Forecast | D43: Forecast | E43: Forecast | F43: Forecast | G43: Forecast | H43: Forecast | J43: Forecast | K43: Forecast | L43: Forecast | M43: Forecast | N43: Forecast | O43: Forecast | P43: Forecast | Q43: Forecast | R43: Forecast | S43: Forecast | T43: Forecast | U43: Forecast | V43: Forecast | W43: Forecast | X43: Forecast | Y43: Forecast | Z43: Forecast | AA43: Forecast | AB43: Forecast | AC43: Forecast | AD43: Forecast | AE43: Forecast | AF43: Forecast | AG43: Forecast | AH43: Forecast | AI43: Forecast | AJ43: Forecast | AK43: Forecast | AL43: Forecast | AM43: Forecast | AN43: Forecast | AO43: Forecast | AP43: Forecast | AQ43: Forecast | AR43: Forecast | AS43: Forecast | AT43: Forecast | AU43: Forecast | AV43: Forecast | AW43: Forecast | AX43: Forecast | AY43: Forecast | AZ43: Forecast | BA43: Forecast | BB43: Forecast | BC43: Forecast | BD43: Forecast | BE43: Forecast | BF43: Forecast | BG43: Forecast | BH43: Forecast | BI43: Forecast | BJ43: Forecast | BK43: Forecast
...

Sheet Waterfall
C2: =Model!C3 -> Kimpton Anglers
C3: Waterfall Distribution
C5: Returns | F5: Profit | G5: IRR | H5: EM | J5: Equity Breakdown | M5: % | N5: Amount
C6: Deal Levered | F6: =SUM(F24:BY24) -> 29235441 | G6: =B24 -> 0.39585511 | H6: =B26 -> 2.4726538 | J6: Sponsor/GP | M6: 0.1 | N6: =M6*$M$12 -> 1938567.8
C7: LP | F7: =SUM(F96:BY96) -> 21302518 | G7: =B94 -> 0.36236156 | H7: =B96 -> 2.1922832 | J7: LP Investor | M7: =1-M6 -> 0.9 | N7: =M7*$M$12 -> 17447110
C8: GP | F8: =SUM(F101:BY101) -> 7932923.6 | G8: =B99 -> 0.57671394 | H8: =B101 -> 4.995989
J9: Transaction Sources
C10: Cash Flow Waterfall | F10: Return | G10: GP CF | H10: LP CF | M10: Amount | N10: Per Key | O10: %
C11: Pref Return | F11: 0.1 | G11: 0 | H11: =1-G11 -> 1 | J11: Debt | M11: =Model!$N$18 -> 23187000 | N11: =Model!$O$18 -> 175659.09 | O11: =Model!$P$18 -> 0.54464509
C12: Hurdle #2 | F12: 0.15 | G12: 0.2 | H12: =1-G12 -> 0.8 | J12: Equity | M12: =Model!$N$22 -> 19385678 | N12: =Model!$O$22 -> 146861.19 | O12: =Model!$P$22 -> 0.45535491
C13: Hurdle #3 | F13: 0.2 | G13: 0.25 | H13: =1-G13 -> 0.75 | J13: Total Sources | M13: =SUM(M11:M12) -> 42572678 | N13: =Model!O23 -> 322520.28 | O13: =SUM(O11:O12) -> 1
C14: Hurdle #4 | F14: 0.25 | G14: 0.25 | H14: =1-G14 -> 0.75
C15: Hurdle #5 | F15: 0.3 | G15: 0.25 | H15: =1-G15 -> 0.75
C16: Hurdle #6 | F16: >30% | G16: 0.5 | H16: =1-G16 -> 0.5
C18: Cash Flow Waterfall | DA18: x
C19: Year | F19: =YEAR(F22) -> 2025 | G19: =YEAR(G22) -> 2025 | H19: =YEAR(H22) -> 2025 | I19: =YEAR(I22) -> 2025 | J19: =YEAR(J22) -> 2026 | K19: =YEAR(K22) -> 2026 | L19: =YEAR(L22) -> 2026 | M19: =YEAR(M22) -> 2026 | ... CZ19: =YEAR(CZ22) -> 2033
C20: Year # | F20: =ROUNDUP(F21/12,0) -> 0 | G20: =ROUNDUP(G21/12,0) -> 1 | H20: =ROUNDUP(H21/12,0) -> 1 | I20: =ROUNDUP(I21/12,0) -> 1 | J20: =ROUNDUP(J21/12,0) -> 1 | K20: =ROUNDUP(K21/12,0) -> 1 | L20: =ROUNDUP(L21/12,0) -> 1 | M20: =ROUNDUP(M21/12,0) -> 1 | ... CZ20: =ROUNDUP(CZ21/12,0) -> 9
C21: Month | F21: 0 | G21: =F21+1 -> 1 | H21: =G21+1 -> 2 | I21: =H21+1 -> 3 | J21: =I21+1 -> 4 | K21: =J21+1 -> 5 | L21: =K21+1 -> 6 | M21: =L21+1 -> 7 | N21: =M21+1 -> 8 | ... CZ21: =CY21+1 -> 98
C22: Date | F22: =Model!S71 -> 45930 | G22: =EOMONTH(F22,1) -> 45961 | H22: =EOMONTH(G22,1) -> 45991 | I22: =EOMONTH(H22,1) -> 46022 | J22: =EOMONTH(I22,1) -> 46053 | K22: =EOMONTH(J22,1) -> 46081 | L22: =EOMONTH(K22,1) -> 46112 | M22: =EOMONTH(L22,1) -> 46142 | N22: =EOMONTH(M22,1) -> 46173 | ... CZ22: =EOMONTH(CY22,1) -> 48913
B23: IRR
B24: =XIRR($F$24:$CZ$24,$F$22:$CZ$22) -> 0.39585511 | C24: Levered Cash Flow | F24: =Model!S96 -> -14783049 | G24: =Model!T96 -> 126557.56 | H24: =Model!U96 -> 111906.6 | I24: =Model!V96 -> 103035.4 | J24: =Model!W96 -> -568556.76 | K24: =Model!X96 -> -608617.82 | L24: =Model!Y96 -> -607140.53 | M24: =Model!Z96 -> -617000.57 | ... CZ24: =Model!DM96 -> 0
B25: EM
B26: =-SUMIF(F24:BY24,">0",F24:BY24)/SUMIF(F24:BY24,"<0",F24:BY24) -> 2.4726538 | C26: Preferred Return
C27: Beginning Balance | F27: =E31 | G27: =F31 -> 13304744 | H27: =G31 -> 13286323 | I27: =H31 -> 13278907 | J27: =I31 -> 13283798 | K27: =J31 -> 13903466 | L27: =K31 -> 14553249 | M27: =L31 -> 15217960 | ... CZ27: =CY31 -> 0
