Workbook
Name CY: #REF!
Name Month1: #REF!
Name Room_Revenue_Factor: #REF!
Name RPTDATE: #REF!
Name RPTMONTH: #REF!
Name ytdhEADER: #REF!

Sheet P&L
A1: Angler's
A2: STATEMENT OF INCOME
A3: FOR THE PERIOD ENDING APRIL 30, 2025
C5: APRIL 2025 - PERIODIC | L5: APRIL 2025 - YEAR TO DATE
C6: Actual | E6: Budget | H6: Prior Year - Actual | L6: Actual | N6: Budget | Q6: Prior Year - Actual
C7: $ | D7: % | E7: $ | F7: % | G7: Variance | H7: $ | I7: % | J7: Variance | L7: $ | M7: % | N7: $ | O7: % | P7: Variance | Q7: $ | R7: % | S7: Variance
B9: Available Rooms | C9: 3960 | E9: 3960 | G9: =C9-E9 -> 0 | H9: 3960 | J9: =C9-H9 -> 0 | L9: 15840 | N9: 15840 | P9: =L9-N9 -> 0 | Q9: 15972 | S9: =L9-Q9 -> -132
B10: Total Rooms Sold | C10: 3684 | E10: 3645 | G10: =C10-E10 -> 39 | H10: 3692 | J10: =C10-H10 -> -8 | L10: 14556 | N10: 14563 | P10: =L10-N10 -> -7 | Q10: 14696 | S10: =L10-Q10 -> -140
B11: Occupancy | C11: =C10/C9 -> 0.93030303 | E11: =E10/E9 -> 0.92045455 | G11: =C11-E11 -> 0.0098484848 | H11: =H10/H9 -> 0.93232323 | J11: =C11-H11 -> -0.002020202 | L11: =L10/L9 -> 0.91893939 | N11: =N10/N9 -> 0.91938131 | P11: =L11-N11 -> -0.00044191919 | Q11: =Q10/Q9 -> 0.92011019 | S11: =L11-Q11 -> -0.0011707989
B12: Average Daily Rate | C12: =C17/C10 -> 266.56628 | E12: =E17/E10 -> 263.2116 | G12: =C12-E12 -> 3.3546817 | H12: =H17/H10 -> 258.44728 | J12: =C12-H12 -> 8.1190006 | L12: =L17/L10 -> 295.51506 | N12: =N17/N10 -> 307.02472 | P12: =L12-N12 -> -11.509669 | Q12: =Q17/Q10 -> 301.98569 | S12: =L12-Q12 -> -6.4706296
B13: Revenue per Available Room | C13: =C11*C12 -> 247.98742 | E13: =E11*E12 -> 242.27432 | G13: =C13-E13 -> 5.7131061 | H13: =H11*H12 -> 240.95641 | J13: =C13-H13 -> 7.0310152 | L13: =L11*L12 -> 271.56043 | N13: =N11*N12 -> 282.27279 | P13: =L13-N13 -> -10.712369 | Q13: =Q11*Q12 -> 277.86011 | S13: =L13-Q13 -> -6.2996809
B16: Revenues
B17: Rooms | C17: 982030.19 | D17: =C17/C21 -> 0.65086039 | E17: 959406.29 | F17: =E17/E$21 -> 0.631665 | G17: =C17-E17 -> 22623.9 | H17: 954187.37 | I17: =H17/H$21 -> 0.72319515 | J17: =C17-H17 -> 27842.82 | L17: 4301517.2 | M17: =L17/L$21 -> 0.68394804 | N17: 4471201.1 | O17: =N17/N$21 -> 0.66098689 | P17: =L17-N17 -> -169683.92 | Q17: 4437981.6 | R17: =Q17/Q$21 -> 0.75674011 | S17: =L17-Q17 -> -136464.48
B18: Food & Beverage | C18: 379131.93 | D18: =C18/C21 -> 0.25127736 | E18: 437605.85 | F18: =E18/E$21 -> 0.288116 | G18: =C18-E18 -> -58473.92 | H18: 250971.01 | I18: =H18/H$21 -> 0.19021528 | J18: =C18-H18 -> 128160.92 | L18: 1523965.8 | M18: =L18/L$21 -> 0.24231297 | N18: 1792694 | O18: =N18/N$21 -> 0.26501766 | P18: =L18-N18 -> -268728.2 | Q18: 916590.74 | R18: =Q18/Q$21 -> 0.15629199 | S18: =L18-Q18 -> 607375.05
B19: Other Operated Departments | C19: 2948.44 | D19: =C19/C21 -> 0.0019541383 | E19: 1557.87 | F19: =E19/E$21 -> 0.0010256885 | G19: =C19-E19 -> 1390.57 | H19: 1461.55 | I19: =H19/H$21 -> 0.0011077341 | J19: =C19-H19 -> 1486.89 | L19: 9874.14 | M19: =L19/L$21 -> 0.0015700039 | N19: 6224.22 | O19: =N19/N$21 -> 0.0009201393 | P19: =L19-N19 -> 3649.92 | Q19: 7206.75 | R19: =Q19/Q$21 -> 0.0012288552 | S19: =L19-Q19 -> 2667.39
B20: Miscellaneous Income | C20: 144707.94 | D20: =C20/C21 -> 0.095908116 | E20: 120283 | F20: =E20/E$21 -> 0.079193312 | G20: =C20-E20 -> 24424.94 | H20: 112785.17 | I20: =H20/H$21 -> 0.085481836 | J20: =C20-H20 -> 31922.77 | L20: 453888.45 | M20: =L20/L$21 -> 0.072168982 | N20: 494313 | O20: =N20/N$21 -> 0.073075312 | P20: =L20-N20 -> -40424.55 | Q20: 502825.58 | R20: =Q20/Q$21 -> 0.085739041 | S20: =L20-Q20 -> -48937.13
B21: Total Revenues | C21: =SUM(C17:C20) -> 1508818.5 | D21: =C21/C21 -> 1 | E21: =SUM(E17:E20) -> 1518853 | F21: =E21/E$21 -> 1 | G21: =C21-E21 -> -10034.51 | H21: =SUM(H17:H20) -> 1319405.1 | I21: =H21/H$21 -> 1 | J21: =C21-H21 -> 189413.4 | L21: =SUM(L17:L20) -> 6289245.5 | M21: =L21/L$21 -> 1 | N21: =SUM(N17:N20) -> 6764432.3 | O21: =N21/N$21 -> 1 | P21: =L21-N21 -> -475186.75 | Q21: =SUM(Q17:Q20) -> 5864604.7 | R21: =Q21/Q$21 -> 1 | S21: =L21-Q21 -> 424640.83
B24: Departmental Expense
B25: Rooms | C25: 278444.2 | D25: =C25/C17 -> 0.28353935 | E25: 245118.34 | F25: =E25/E17 -> 0.25548961 | G25: =C25-E25 -> 33325.86 | H25: 261858.86 | I25: =H25/H17 -> 0.27443128 | J25: =C25-H25 -> 16585.34 | L25: 1048369.3 | M25: =L25/L17 -> 0.24372082 | N25: 1019678.2 | O25: =N25/N17 -> 0.22805465 | P25: =L25-N25 -> 28691.08 | Q25: 1030793.9 | R25: =Q25/Q17 -> 0.23226638 | S25: =L25-Q25 -> 17575.33
B26: Food & Beverage | C26: 291396.9 | D26: =C26/C18 -> 0.76858971 | E26: 298555.95 | F26: =E26/E18 -> 0.68224854 | G26: =C26-E26 -> -7159.054 | H26: 228871.12 | I26: =H26/H18 -> 0.91194246 | J26: =C26-H26 -> 62525.78 | L26: 1080000.5 | M26: =L26/L18 -> 0.70867763 | N26: 1223767.9 | O26: =N26/N18 -> 0.68264185 | P26: =L26-N26 -> -143767.48 | Q26: 774579.62 | R26: =Q26/Q18 -> 0.84506595 | S26: =L26-Q26 -> 305420.85
B27: Other Operated Departments | C27: 1105.98 | D27: =C27/C19 -> 0.37510684 | E27: 531.38 | F27: =E27/E19 -> 0.34109393 | G27: =C27-E27 -> 574.6 | H27: 642.24 | I27: =H27/H19 -> 0.4394239 | J27: =C27-H27 -> 463.74 | L27: 5073 | M27: =L27/L19 -> 0.51376626 | N27: 2123.05 | O27: =N27/N19 -> 0.34109495 | P27: =L27-N27 -> 2949.95 | Q27: 2321.77 | R27: =Q27/Q19 -> 0.32216602 | S27: =L27-Q27 -> 2751.23
B28: Total Departmental Expense | C28: =SUM(C25:C27) -> 570947.08 | D28: =C28/C21 -> 0.37840673 | E28: =SUM(E25:E27) -> 544205.67 | F28: =E28/E$21 -> 0.35830042 | G28: =C28-E28 -> 26741.406 | H28: =SUM(H25:H27) -> 491372.22 | I28: =H28/H$21 -> 0.37241952 | J28: =C28-H28 -> 79574.86 | L28: =SUM(L25:L27) -> 2133442.7 | M28: =L28/L$21 -> 0.33922077 | N28: =SUM(N25:N27) -> 2245569.2 | O28: =N28/N$21 -> 0.33196713 | P28: =L28-N28 -> -112126.45 | Q28: =SUM(Q25:Q27) -> 1807695.3 | R28: =Q28/Q$21 -> 0.30823822 | S28: =L28-Q28 -> 325747.41
B30: Total Departmental Profit | C30: =C21-C28 -> 937871.42 | D30: =C30/C21 -> 0.62159327 | E30: =E21-E28 -> 974647.34 | F30: =E30/E$21 -> 0.64169958 | G30: =C30-E30 -> -36775.916 | H30: =H21-H28 -> 828032.88 | I30: =H30/H$21 -> 0.62758048 | J30: =C30-H30 -> 109838.54 | L30: =L21-L28 -> 4155802.8 | M30: =L30/L$21 -> 0.66077923 | N30: =N21-N28 -> 4518863.1 | O30: =N30/N$21 -> 0.66803287 | P30: =L30-N30 -> -363060.3 | Q30: =Q21-Q28 -> 4056909.4 | R30: =Q30/Q$21 -> 0.69176178 | S30: =L30-Q30 -> 98893.42
B32: Undistributed Expenses
B33: Administrative & General | C33: 133968.94 | D33: =C33/C21 -> 0.088790627 | E33: 138401.36 | F33: =E33/E$21 -> 0.091122285 | G33: =C33-E33 -> -4432.4168 | H33: 118161.63 | I33: =H33/H$21 -> 0.089556748 | J33: =C33-H33 -> 15807.31 | L33: 495671.28 | M33: =L33/L$21 -> 0.078812519 | N33: 544392.4 | O33: =N33/N$21 -> 0.080478653 | P33: =L33-N33 -> -48721.121 | Q33: 457549.71 | R33: =Q33/Q$21 -> 0.078018849 | S33: =L33-Q33 -> 38121.57
B34: Information & Telecom Systems | C34: 16160.83 | D34: =C34/C21 -> 0.010710917 | E34: 15681.7 | F34: =E34/E$21 -> 0.010324699 | G34: =C34-E34 -> 479.13 | H34: 15829.8 | I34: =H34/H$21 -> 0.01199768 | J34: =C34-H34 -> 331.03 | L34: 80361.22 | M34: =L34/L$21 -> 0.012777561 | N34: 79636.02 | O34: =N34/N$21 -> 0.011772757 | P34: =L34-N34 -> 725.2 | Q34: 78045.46 | R34: =Q34/Q$21 -> 0.013307881 | S34: =L34-Q34 -> 2315.76
B35: Sales & Marketing | C35: 88393.96 | D35: =C35/C21 -> 0.058584886 | E35: 104759.66 | F35: =E35/E$21 -> 0.068972876 | G35: =C35-E35 -> -16365.7 | H35: 115727.72 | I35: =H35/H$21 -> 0.087712045 | J35: =C35-H35 -> -27333.76 | L35: 381980.89 | M35: =L35/L$21 -> 0.060735566 | N35: 470940.58 | O35: =N35/N$21 -> 0.069620119 | P35: =L35-N35 -> -88959.69 | Q35: 417390.76 | R35: =Q35/Q$21 -> 0.071171167 | S35: =L35-Q35 -> -35409.87
B36: Property Operations & Maintenance | C36: 57358.85 | D36: =C36/C21 -> 0.038015739 | E36: 65333.87 | F36: =E36/E$21 -> 0.043015268 | G36: =C36-E36 -> -7975.0199 | H36: 37576.64 | I36: =H36/H$21 -> 0.028479987 | J36: =C36-H36 -> 19782.21 | L36: 220794.79 | M36: =L36/L$21 -> 0.035106721 | N36: 267358.96 | O36: =N36/N$21 -> 0.039524228 | P36: =L36-N36 -> -46564.174 | Q36: 225470.27 | R36: =Q36/Q$21 -> 0.038445945 | S36: =L36-Q36 -> -4675.48
B37: Utilities | C37: 24121.87 | D37: =C37/C21 -> 0.015987258 | E37: 23162.39 | F37: =E37/E$21 -> 0.015249922 | G37: =C37-E37 -> 959.48 | H37: 25806.47 | I37: =H37/H$21 -> 0.019559171 | J37: =C37-H37 -> -1684.6 | L37: 93445.37 | M37: =L37/L$21 -> 0.014857962 | N37: 90217.04 | O37: =N37/N$21 -> 0.013336971 | P37: =L37-N37 -> 3228.33 | Q37: 95974.61 | R37: =Q37/Q$21 -> 0.01636506 | S37: =L37-Q37 -> -2529.24
B38: Total Undistributed Expenses | C38: =SUM(C33:C37) -> 320004.45 | D38: =C38/C21 -> 0.21208943 | E38: =SUM(E33:E37) -> 347338.98 | F38: =E38/E$21 -> 0.22868505 | G38: =C38-E38 -> -27334.527 | H38: =SUM(H33:H37) -> 313102.26 | I38: =H38/H$21 -> 0.23730563 | J38: =C38-H38 -> 6902.19 | L38: =SUM(L33:L37) -> 1272253.5 | M38: =L38/L$21 -> 0.20229033 | N38: =SUM(N33:N37) -> 1452545 | O38: =N38/N$21 -> 0.21473273 | P38: =L38-N38 -> -180291.45 | Q38: =SUM(Q33:Q37) -> 1274430.8 | R38: =Q38/Q$21 -> 0.2173089 | S38: =L38-Q38 -> -2177.26
B40: Gross Operating Profit | C40: =C30-C38 -> 617866.97 | D40: =C40/C21 -> 0.40950384 | E40: =E30-E38 -> 627308.36 | F40: =E40/E$21 -> 0.41301453 | G40: =C40-E40 -> -9441.3894 | H40: =H30-H38 -> 514930.62 | I40: =H40/H$21 -> 0.39027484 | J40: =C40-H40 -> 102936.35 | L40: =L30-L38 -> 2883549.2 | M40: =L40/L$21 -> 0.4584889 | N40: =N30-N38 -> 3066318.1 | O40: =N40/N$21 -> 0.45330014 | P40: =L40-N40 -> -182768.85 | Q40: =Q30-Q38 -> 2782478.6 | R40: =Q40/Q$21 -> 0.47445287 | S40: =L40-Q40 -> 101070.68
B42: Management Fees | C42: 68430.22 | D42: =C42/C21 -> 0.045353513 | E42: 70783.77 | F42: =E42/E$21 -> 0.046603437 | G42: =C42-E42 -> -2353.55 | H42: 56917.53 | I42: =H42/H$21 -> 0.043138783 | J42: =C42-H42 -> 11512.69 | L42: 273972.26 | M42: =L42/L$21 -> 0.043562023 | N42: 306966.13 | O42: =N42/N$21 -> 0.045379437 | P42: =L42-N42 -> -32993.87 | Q42: 243369.3 | R42: =Q42/Q$21 -> 0.041497989 | S42: =L42-Q42 -> 30602.96
B43: Income before non-operating inc & expense | C43: =C40-C42 -> 549436.75 | D43: =C43/C21 -> 0.36415033 | E43: =E40-E42 -> 556524.59 | F43: =E43/E$21 -> 0.36641109 | G43: =C43-E43 -> -7087.8394 | H43: =H40-H42 -> 458013.09 | I43: =H43/H$21 -> 0.34713606 | J43: =C43-H43 -> 91423.66 | L43: =L40-L42 -> 2609577 | M43: =L43/L$21 -> 0.41492687 | N43: =N40-N42 -> 2759352 | O43: =N43/N$21 -> 0.4079207 | P43: =L43-N43 -> -149774.98 | Q43: =Q40-Q42 -> 2539109.3 | R43: =Q43/Q$21 -> 0.43295489 | S43: =L43-Q43 -> 70467.72
B45: Income | C45: -1631.67 | D45: =C45/C21 -> -0.0010814223 | E45: -2031 | F45: =E45/E$21 -> -0.0013371933 | G45: =C45-E45 -> 399.33 | H45: -1967.65 | I45: =H45/H$21 -> -0.001491316 | J45: =C45-H45 -> 335.98 | L45: -9884.92 | M45: =L45/L$21 -> -0.0015717179 | N45: -8124 | O45: =N45/N$21 -> -0.0012009877 | P45: =L45-N45 -> -1760.92 | Q45: -7748.25 | R45: =Q45/Q$21 -> -0.0013211888 | S45: =L45-Q45 -> -2136.67
B46: Rent | C46: 277.09 | D46: =C46/C21 -> 0.00018364701 | E46: 1100.5 | F46: =E46/E$21 -> 0.00072455991 | G46: =C46-E46 -> -823.41 | H46: -196.17 | I46: =H46/H$21 -> -0.00014868064 | J46: =C46-H46 -> 473.26 | L46: 3931.72 | M46: =L46/L$21 -> 0.00062514971 | N46: 4615 | O46: =N46/N$21 -> 0.00068224499 | P46: =L46-N46 -> -683.28 | Q46: 4172.12 | R46: =Q46/Q$21 -> 0.00071140686 | S46: =L46-Q46 -> -240.4
B47: Property & Other Taxes | C47: 33677.12 | D47: =C47/C21 -> 0.022320193 | E47: 64957 | F47: =E47/E$21 -> 0.04276714 | G47: =C47-E47 -> -31279.88 | H47: 62050.2 | I47: =H47/H$21 -> 0.047028922 | J47: =C47-H47 -> -28373.08 | L47: 178781.12 | M47: =L47/L$21 -> 0.028426481 | N47: 210061 | O47: =N47/N$21 -> 0.031053752 | P47: =L47-N47 -> -31279.88 | Q47: 201899.2 | R47: =Q47/Q$21 -> 0.034426736 | S47: =L47-Q47 -> -23118.08
B48: Insurance | C48: 115207.8 | D48: =C48/C21 -> 0.076356301 | E48: 120639.82 | F48: =E48/E$21 -> 0.079428239 | G48: =C48-E48 -> -5432.02 | H48: 130984.32 | I48: =H48/H$21 -> 0.099275287 | J48: =C48-H48 -> -15776.52 | L48: 461216.33 | M48: =L48/L$21 -> 0.073334127 | N48: 482770.78 | O48: =N48/N$21 -> 0.071369002 | P48: =L48-N48 -> -21554.45 | Q48: 521879.55 | R48: =Q48/Q$21 -> 0.088988018 | S48: =L48-Q48 -> -60663.22
B49: Other | C49: 0 | D49: =C49/C21 -> 0 | E49: 0 | F49: =E49/E$21 -> 0 | G49: =C49-E49 -> 0 | H49: 0 | I49: =H49/H$21 -> 0 | J49: =C49-H49 -> 0 | L49: 0 | M49: =L49/L$21 -> 0 | N49: 0 | O49: =N49/N$21 -> 0 | P49: =L49-N49 -> 0 | Q49: 0 | R49: =Q49/Q$21 -> 0 | S49: =L49-Q49 -> 0
B50: Total non-operating income & expenses | C50: =SUM(C45:C49) -> 147530.34 | D50: =C50/C21 -> 0.097778719 | E50: =SUM(E45:E49) -> 184666.32 | F50: =E50/E$21 -> 0.12158275 | G50: =C50-E50 -> -37135.98 | H50: =SUM(H45:H49) -> 190870.7 | I50: =H50/H$21 -> 0.14466421 | J50: =C50-H50 -> -43340.36 | L50: =SUM(L45:L49) -> 634044.25 | M50: =L50/L$21 -> 0.10081404 | N50: =SUM(N45:N49) -> 689322.78 | O50: =N50/N$21 -> 0.10190401 | P50: =L50-N50 -> -55278.53 | Q50: =SUM(Q45:Q49) -> 720202.62 | R50: =Q50/Q$21 -> 0.12280497 | S50: =L50-Q50 -> -86158.37
B52: EBITDA | C52: =C43-C50 -> 401906.41 | D52: =C52/C21 -> 0.26637161 | E52: =E43-E50 -> 371858.27 | F52: =E52/E$21 -> 0.24482835 | G52: =C52-E52 -> 30048.141 | H52: =H43-H50 -> 267142.39 | I52: =H52/H$21 -> 0.20247185 | J52: =C52-H52 -> 134764.02 | L52: =L43-L50 -> 1975532.7 | M52: =L52/L$21 -> 0.31411283 | N52: =N43-N50 -> 2070029.2 | O52: =N52/N$21 -> 0.30601669 | P52: =L52-N52 -> -94496.445 | Q52: =Q43-Q50 -> 1818906.6 | R52: =Q52/Q$21 -> 0.31014991 | S52: =L52-Q52 -> 156626.09
...

Sheet T12
A1: Angler's
A2: T12 STATEMENT OF INCOME
A3: FOR THE PERIOD ENDING APRIL 30, 2025
D6: 45443 | E6: 45473 | F6: 45504 | G6: 45535 | H6: 45565 | I6: 45596 | J6: 45626 | K6: 45657 | L6: 45688 | M6: 45716 | N6: 45747 | O6: 45777 | P6: TOTAL
D7: Actual | E7: Actual | F7: Actual | G7: Actual | H7: Actual | I7: Actual | J7: Actual | K7: Actual | L7: Actual | M7: Actual | N7: Actual | O7: Actual
D8: 0 | E8: 0 | F8: 0 | G8: 0 | H8: 0 | I8: 0 | J8: 0 | K8: 0 | L8: 0 | M8: 0 | N8: 0 | O8: 0
B9: Available Rooms | D9: 4092 | E9: 3960 | F9: 4092 | G9: 4092 | H9: 3960 | I9: 4092 | J9: 3960 | K9: 4092 | L9: 4092 | M9: 3696 | N9: 4092 | O9: 3960 | P9: =+SUM(D9:O9) -> 48180
B10: Total Rooms Sold | D10: 3471 | E10: 3102 | F10: 3016 | G10: 3030 | H10: 2625 | I10: 3173 | J10: 3516 | K10: 3594 | L10: 3709 | M10: 3426 | N10: 3737 | O10: 3684 | P10: =+SUM(D10:O10) -> 40083
B11: Occupancy | D11: 0.8482 | E11: 0.7833 | F11: 0.737 | G11: 0.7405 | H11: 0.6629 | I11: 0.7754 | J11: 0.8879 | K11: 0.8783 | L11: 0.9064 | M11: 0.9269 | N11: 0.9132 | O11: =O10/O9 -> 0.93030303 | P11: =P10/P9 -> 0.83194271
B12: Average Daily Rate | D12: 223.8615 | E12: 171.1737 | F12: 179.4268 | G12: 158.695 | H12: 160.4022 | I12: 192.317 | J12: 197.7415 | K12: 278.7668 | L12: 280.5929 | M12: 341.1863 | N12: 296.9933 | O12: =O17/O10 -> 266.56628 | P12: =P17/P10 -> 233.51403
B13: Revenue per Available Room | D13: 189.8884 | E13: 134.086 | F13: 132.2462 | G13: 117.5088 | H13: 106.3272 | I13: 149.1256 | J13: 175.5705 | K13: 244.8406 | L13: 254.3301 | M13: 316.262 | N13: 271.2277 | O13: =O11*O12 -> 247.98742 | P13: =P11*P12 -> 194.27029
B16: Revenues
B17: Rooms | D17: 777023.21 | E17: 530980.7 | F17: 541151.31 | G17: 480845.86 | H17: 421055.73 | I17: 610221.83 | J17: 695259.21 | K17: 1001887.7 | L17: 1040719 | M17: 1168904.2 | N17: 1109863.8 | O17: 982030.19 | P17: =+SUM(D17:O17) -> 9359942.7
B18: Food & Beverage | D18: 276217.51 | E18: 201588.78 | F18: 210893.26 | G18: 189691.38 | H18: 205467.1 | I18: 195962.94 | J18: 235866.06 | K18: 305129.22 | L18: 354251.28 | M18: 423507.82 | N18: 367074.76 | O18: 379131.93 | P18: =+SUM(D18:O18) -> 3344782
B19: Other Operated Departments | D19: 686.39 | E19: 971.47 | F19: 1646.04 | G19: 900.7 | H19: 865.48 | I19: 1388.87 | J19: 2028.13 | K19: 2112.59 | L19: 2237.04 | M19: 2324.18 | N19: 2364.48 | O19: 2948.44 | P19: =+SUM(D19:O19) -> 20473.81
B20: Miscellaneous Income | D20: 110919.27 | E20: 93308.28 | F20: 102674.98 | G20: 101401.82 | H20: 75369.05 | I20: 102100.27 | J20: 114522.56 | K20: 125354.13 | L20: 107218.88 | M20: 91349.99 | N20: 110611.64 | O20: 144707.94 | P20: =+SUM(D20:O20) -> 1279538.8
B21: Total Revenues | D21: 1164846.4 | E21: 826849.23 | F21: 856365.59 | G21: 772839.76 | H21: 702757.36 | I21: 909673.91 | J21: 1047676 | K21: 1434483.7 | L21: 1504426.2 | M21: 1686086.2 | N21: 1589914.7 | O21: =SUM(O17:O20) -> 1508818.5 | P21: =+SUM(D21:O21) -> 14004737
B23: Departmental Expense
B24: Rooms | D24: 267324.25 | E24: 206882.07 | F24: 214773.66 | G24: 200502.01 | H24: 185458.87 | I24: 194298.83 | J24: 214598.12 | K24: 255145.18 | L24: 279344.62 | M24: 240150.76 | N24: 250429.69 | O24: 278444.2 | P24: =+SUM(D24:O24) -> 2787352.3
B25: Food & Beverage | D25: 226868.58 | E25: 181455.91 | F25: 187917.75 | G25: 183640.15 | H25: 144001.82 | I25: 168612.12 | J25: 192181.82 | K25: 231097.5 | L25: 248459.71 | M25: 275568.11 | N25: 264575.75 | O25: 291396.9 | P25: =+SUM(D25:O25) -> 2595776.1
B26: Other Operated Departments | D26: 294.5 | E26: 206.68 | F26: 520.26 | G26: 165.54 | H26: 348.76 | I26: 319.45 | J26: 767.44 | K26: 180.6 | L26: 1154.6 | M26: 1424.85 | N26: 1387.57 | O26: 1105.98 | P26: =+SUM(D26:O26) -> 7876.23
B27: Total Departmental Expense | D27: 494487.33 | E27: 388544.66 | F27: 403211.67 | G27: 384307.7 | H27: 329809.45 | I27: 363230.4 | J27: 407547.38 | K27: 486423.28 | L27: 528958.93 | M27: 517143.72 | N27: 516393.01 | O27: =SUM(O24:O26) -> 570947.08 | P27: =+SUM(D27:O27) -> 5391004.6
B29: Total Departmental Profit | D29: 670359.05 | E29: 438304.57 | F29: 453153.92 | G29: 388532.06 | H29: 372947.91 | I29: 546443.51 | J29: 640128.58 | K29: 948060.4 | L29: 975467.24 | M29: 1168942.5 | N29: 1073521.6 | O29: =O21-O27 -> 937871.42 | P29: =+SUM(D29:O29) -> 8613732.8
B31: Undistributed Expenses
B32: Administrative & General | D32: 111994.31 | E32: 82539.25 | F32: 90862.62 | G32: 94776.16 | H32: 100956.57 | I32: 101881.17 | J32: 97703.56 | K32: 130844.77 | L32: 124940.54 | M32: 116597.61 | N32: 120164.19 | O32: 133968.94 | P32: =+SUM(D32:O32) -> 1307229.7
B33: Information & Telecom Systems | D33: 15157.74 | E33: 11148.06 | F33: 12448.49 | G33: 9078.45 | H33: 8251.67 | I33: 10860.33 | J33: 13045.09 | K33: 19091.71 | L33: 21170.28 | M33: 24910.61 | N33: 18119.5 | O33: 16160.83 | P33: =+SUM(D33:O33) -> 179442.76
B34: Sales & Marketing | D34: 106611.29 | E34: 96066.24 | F34: 97447.53 | G34: 91547.39 | H34: 90642.09 | I34: 89372.2 | J34: 96385.97 | K34: 83929.4 | L34: 103819.96 | M34: 95261.58 | N34: 94505.39 | O34: 88393.96 | P34: =+SUM(D34:O34) -> 1133983
B35: Property Operation & Maintenan | D35: 53729.18 | E35: 45389.36 | F35: 48251.05 | G35: 50469.87 | H35: 54761.56 | I35: 53366.78 | J35: 55631.99 | K35: 51815.5 | L35: 63453.34 | M35: 52586.01 | N35: 47396.59 | O35: 57358.85 | P35: =+SUM(D35:O35) -> 634210.08
B36: Utilities | D36: 26430.89 | E36: 28545.41 | F36: 24940.23 | G36: 23587.33 | H36: 25144.4 | I36: 24473.06 | J36: 22625.96 | K36: 16277.43 | L36: 25067.23 | M36: 21552.88 | N36: 22703.39 | O36: 24121.87 | P36: =+SUM(D36:O36) -> 285470.08
B37: Total Undistributed Expenses | D37: 313923.41 | E37: 263688.32 | F37: 273949.92 | G37: 269459.2 | H37: 279756.29 | I37: 279953.54 | J37: 285392.57 | K37: 301958.81 | L37: 338451.35 | M37: 310908.69 | N37: 302889.06 | O37: =SUM(O32:O36) -> 320004.45 | P37: =+SUM(D37:O37) -> 3540335.6
B39: Gross Operating Profit | D39: 356435.64 | E39: 174616.25 | F39: 179204 | G39: 119072.86 | H39: 93191.62 | I39: 266489.97 | J39: 354736.01 | K39: 646101.59 | L39: 637015.89 | M39: 858033.79 | N39: 770632.59 | O39: =O29-O37 -> 617866.97 | P39: =+SUM(D39:O39) -> 5073397.2
B41: Management Fees | D41: 55821.92 | E41: 41157.66 | F41: 41987.72 | G41: 37762.94 | H41: 37196.82 | I41: 42657.18 | J41: 55537.08 | K41: 64343.02 | L41: 59537.97 | M41: 76013.26 | N41: 69990.81 | O41: 68430.22 | P41: =+SUM(D41:O41) -> 650436.6
B42: Income before non-operating inc & expense | D42: 300613.72 | E42: 133458.59 | F42: 137216.28 | G42: 81309.92 | H42: 55994.8 | I42: 223832.79 | J42: 299198.93 | K42: 581758.57 | L42: 577477.92 | M42: 782020.53 | N42: 700641.78 | O42: =O39-O41 -> 549436.75 | P42: =+SUM(D42:O42) -> 4422960.6
B44: Income | D44: -2116.07 | E44: -2077.49 | F44: -2152.03 | G44: -2157.5 | H44: -1997.83 | I44: -1918.92 | J44: 0 | K44: 0 | L44: -5053.16 | M44: -1517.29 | N44: -1682.8 | O44: -1631.67 | P44: =+SUM(D44:O44) -> -22304.76
B45: Rent | D45: 1870.24 | E45: 658.13 | F45: 837.03 | G45: 517.89 | H45: 3514.57 | I45: -800.55 | J45: 2224.88 | K45: -2950.36 | L45: 2257.12 | M45: 473.27 | N45: 924.24 | O45: 277.09 | P45: =+SUM(D45:O45) -> 9803.55
B46: Property & Other Taxes | D46: 45461 | E46: 45461 | F46: 45461 | G46: 45461 | H46: 45461 | I46: 45461 | J46: 86358.56 | K46: 2281.72 | L46: 48368 | M46: 48368 | N46: 48368 | O46: 33677.12 | P46: =+SUM(D46:O46) -> 540187.4
B47: Insurance | D47: 117207.72 | E47: 117470.98 | F47: 117470.94 | G47: 116313.08 | H47: 117717.47 | I47: 117717.35 | J47: 117717.35 | K47: 130965.02 | L47: 115247.19 | M47: 115553.45 | N47: 115207.89 | O47: 115207.8 | P47: =+SUM(D47:O47) -> 1413796.2
B48: Other | D48: 0 | E48: 0 | F48: 0 | G48: 0 | H48: 0 | I48: 0 | J48: 0 | K48: 0 | L48: 0 | M48: 0 | N48: 0 | O48: 0 | P48: =+SUM(D48:O48) -> 0
B49: Total non-operating income & expenses | D49: 162422.89 | E49: 161512.62 | F49: 161616.94 | G49: 160134.47 | H49: 164695.21 | I49: 160458.88 | J49: 206300.79 | K49: 130296.38 | L49: 160819.15 | M49: 162877.43 | N49: 162817.33 | O49: =SUM(O44:O48) -> 147530.34 | P49: =+SUM(D49:O49) -> 1941482.4
B51: EBITDA | D51: 138190.83 | E51: -28054.03 | F51: -24400.66 | G51: -78824.55 | H51: -108700.41 | I51: 63373.91 | J51: 92898.14 | K51: 451462.19 | L51: 416658.77 | M51: 619143.1 | N51: 537824.45 | O51: =O42-O49 -> 401906.41 | P51: =+SUM(D51:O51) -> 2481478.1
...

Sheet Adjusted T12
A1: Angler's
A2: T12 STATEMENT OF INCOME
A3: FOR THE PERIOD ENDING APRIL 30, 2025
D6: 45443 | E6: 45473 | F6: 45504 | G6: 45535 | H6: 45565 | I6: 45596 | J6: 45626 | K6: 45657 | L6: 45688 | M6: 45716 | N6: 45747 | O6: 45777 | P6: TOTAL
D7: Actual | E7: Actual | F7: Actual | G7: Actual | H7: Actual | I7: Actual | J7: Actual | K7: Actual | L7: Actual | M7: Actual | N7: Actual | O7: Actual
D8: 0 | E8: 0 | F8: 0 | G8: 0 | H8: 0 | I8: 0 | J8: 0 | K8: 0 | L8: 0 | M8: 0 | N8: 0 | O8: 0
B9: Available Rooms | D9: 4092 | E9: 3960 | F9: 4092 | G9: 4092 | H9: 3960 | I9: 4092 | J9: 3960 | K9: 4092 | L9: 4092 | M9: 3696 | N9: 4092 | O9: 3960 | P9: =+SUM(D9:O9) -> 48180
B10: Total Rooms Sold | D10: 3471 | E10: 3102 | F10: 3016 | G10: 3030 | H10: 2625 | I10: 3173 | J10: 3516 | K10: 3594 | L10: 3709 | M10: 3426 | N10: 3737 | O10: 3684 | P10: =+SUM(D10:O10) -> 40083
B11: Occupancy | D11: 0.8482 | E11: 0.7833 | F11: 0.737 | G11: 0.7405 | H11: 0.6629 | I11: 0.7754 | J11: 0.8879 | K11: 0.8783 | L11: 0.9064 | M11: 0.9269 | N11: 0.9132 | O11: =O10/O9 -> 0.93030303 | P11: =P10/P9 -> 0.83194271
B12: Average Daily Rate | D12: 223.8615 | E12: 171.1737 | F12: 179.4268 | G12: 158.695 | H12: 160.4022 | I12: 192.317 | J12: 197.7415 | K12: 278.7668 | L12: 280.5929 | M12: 341.1863 | N12: 296.9933 | O12: =O17/O10 -> 266.56628 | P12: =P17/P10 -> 233.51403
B13: Revenue per Available Room | D13: 189.8884 | E13: 134.086 | F13: 132.2462 | G13: 117.5088 | H13: 106.3272 | I13: 149.1256 | J13: 175.5705 | K13: 244.8406 | L13: 254.3301 | M13: 316.262 | N13: 271.2277 | O13: =O11*O12 -> 247.98742 | P13: =P11*P12 -> 194.27029
B16: Revenues
B17: Rooms | D17: 777023.21 | E17: 530980.7 | F17: 541151.31 | G17: 480845.86 | H17: 421055.73 | I17: 610221.83 | J17: 695259.21 | K17: 1001887.7 | L17: 1040719 | M17: 1168904.2 | N17: 1109863.8 | O17: 982030.19 | P17: =+SUM(D17:O17) -> 9359942.7
B18: Food & Beverage | D18: 276217.51 | E18: 201588.78 | F18: 210893.26 | G18: 189691.38 | H18: 205467.1 | I18: 195962.94 | J18: 235866.06 | K18: 305129.22 | L18: 354251.28 | M18: 423507.82 | N18: 367074.76 | O18: 379131.93 | P18: =+SUM(D18:O18) -> 3344782
B19: Other Operated Departments | D19: 686.39 | E19: 971.47 | F19: 1646.04 | G19: 900.7 | H19: 865.48 | I19: 1388.87 | J19: 2028.13 | K19: 2112.59 | L19: 2237.04 | M19: 2324.18 | N19: 2364.48 | O19: 2948.44 | P19: =+SUM(D19:O19) -> 20473.81
B20: Miscellaneous Income | D20: 110919.27 | E20: 93308.28 | F20: 102674.98 | G20: 101401.82 | H20: 75369.05 | I20: 102100.27 | J20: 114522.56 | K20: 125354.13 | L20: 107218.88 | M20: 91349.99 | N20: 110611.64 | O20: 144707.94 | P20: =+SUM(D20:O20) -> 1279538.8
B21: Total Revenues | D21: 1164846.4 | E21: 826849.23 | F21: 856365.59 | G21: 772839.76 | H21: 702757.36 | I21: 909673.91 | J21: 1047676 | K21: 1434483.7 | L21: 1504426.2 | M21: 1686086.2 | N21: 1589914.7 | O21: =SUM(O17:O20) -> 1508818.5 | P21: =+SUM(D21:O21) -> 14004737
B23: Departmental Expense
B24: Rooms | D24: 267324.25 | E24: 206882.07 | F24: 214773.66 | G24: 200502.01 | H24: 185458.87 | I24: 194298.83 | J24: 214598.12 | K24: 255145.18 | L24: 279344.62 | M24: 240150.76 | N24: 250429.69 | O24: 278444.2 | P24: =+SUM(D24:O24) -> 2787352.3
B25: Food & Beverage | D25: 226868.58 | E25: 181455.91 | F25: 187917.75 | G25: 183640.15 | H25: 144001.82 | I25: 168612.12 | J25: 192181.82 | K25: 231097.5 | L25: 248459.71 | M25: 275568.11 | N25: 264575.75 | O25: 291396.9 | P25: =+SUM(D25:O25) -> 2595776.1
B26: Other Operated Departments | D26: 294.5 | E26: 206.68 | F26: 520.26 | G26: 165.54 | H26: 348.76 | I26: 319.45 | J26: 767.44 | K26: 180.6 | L26: 1154.6 | M26: 1424.85 | N26: 1387.57 | O26: 1105.98 | P26: =+SUM(D26:O26) -> 7876.23
B27: Total Departmental Expense | D27: 494487.33 | E27: 388544.66 | F27: 403211.67 | G27: 384307.7 | H27: 329809.45 | I27: 363230.4 | J27: 407547.38 | K27: 486423.28 | L27: 528958.93 | M27: 517143.72 | N27: 516393.01 | O27: =SUM(O24:O26) -> 570947.08 | P27: =+SUM(D27:O27) -> 5391004.6
B29: Total Departmental Profit | D29: 670359.05 | E29: 438304.57 | F29: 453153.92 | G29: 388532.06 | H29: 372947.91 | I29: 546443.51 | J29: 640128.58 | K29: 948060.4 | L29: 975467.24 | M29: 1168942.5 | N29: 1073521.6 | O29: =O21-O27 -> 937871.42 | P29: =+SUM(D29:O29) -> 8613732.8
B31: Undistributed Expenses
B32: Administrative & General | D32: 111994.31 | E32: 82539.25 | F32: 90862.62 | G32: 94776.16 | H32: 100956.57 | I32: 101881.17 | J32: 97703.56 | K32: 130844.77 | L32: 124940.54 | M32: 116597.61 | N32: 120164.19 | O32: 133968.94 | P32: =+SUM(D32:O32) -> 1307229.7
B33: Information & Telecom Systems | D33: 15157.74 | E33: 11148.06 | F33: 12448.49 | G33: 9078.45 | H33: 8251.67 | I33: 10860.33 | J33: 13045.09 | K33: 19091.71 | L33: 21170.28 | M33: 24910.61 | N33: 18119.5 | O33: 16160.83 | P33: =+SUM(D33:O33) -> 179442.76
B34: Sales & Marketing | D34: 106611.29 | E34: 96066.24 | F34: 97447.53 | G34: 91547.39 | H34: 90642.09 | I34: 89372.2 | J34: 96385.97 | K34: 83929.4 | L34: 103819.96 | M34: 95261.58 | N34: 94505.39 | O34: 88393.96 | P34: =+SUM(D34:O34) -> 1133983
B35: Property Operation & Maintenan | D35: 53729.18 | E35: 45389.36 | F35: 48251.05 | G35: 50469.87 | H35: 54761.56 | I35: 53366.78 | J35: 55631.99 | K35: 51815.5 | L35: 63453.34 | M35: 52586.01 | N35: 47396.59 | O35: 57358.85 | P35: =+SUM(D35:O35) -> 634210.08
B36: Utilities | D36: 26430.89 | E36: 28545.41 | F36: 24940.23 | G36: 23587.33 | H36: 25144.4 | I36: 24473.06 | J36: 22625.96 | K36: 16277.43 | L36: 25067.23 | M36: 21552.88 | N36: 22703.39 | O36: 24121.87 | P36: =+SUM(D36:O36) -> 285470.08
B37: Total Undistributed Expenses | D37: 313923.41 | E37: 263688.32 | F37: 273949.92 | G37: 269459.2 | H37: 279756.29 | I37: 279953.54 | J37: 285392.57 | K37: 301958.81 | L37: 338451.35 | M37: 310908.69 | N37: 302889.06 | O37: =SUM(O32:O36) -> 320004.45 | P37: =+SUM(D37:O37) -> 3540335.6
B39: Gross Operating Profit | D39: 356435.64 | E39: 174616.25 | F39: 179204 | G39: 119072.86 | H39: 93191.62 | I39: 266489.97 | J39: 354736.01 | K39: 646101.59 | L39: 637015.89 | M39: 858033.79 | N39: 770632.59 | O39: =O29-O37 -> 617866.97 | P39: =+SUM(D39:O39) -> 5073397.2
B41: Management Fees | D41: =3%*D21 -> 34945.391 | E41: =3%*E21 -> 24805.477 | F41: =3%*F21 -> 25690.968 | G41: =3%*G21 -> 23185.193 | H41: =3%*H21 -> 21082.721 | I41: =3%*I21 -> 27290.217 | J41: =3%*J21 -> 31430.279 | K41: =3%*K21 -> 43034.51 | ... O41: =3%*O21 -> 45264.555 | P41: =+SUM(D41:O41) -> 420142.12
B42: Income before non-operating inc & expense | D42: =D39-D41 -> 321490.25 | E42: =E39-E41 -> 149810.77 | F42: =F39-F41 -> 153513.03 | G42: =G39-G41 -> 95887.667 | H42: =H39-H41 -> 72108.899 | I42: =I39-I41 -> 239199.75 | J42: =J39-J41 -> 323305.73 | K42: =K39-K41 -> 603067.08 | ... O42: =O39-O41 -> 572602.41 | P42: =+SUM(D42:O42) -> 4653255.1
B44: Income | D44: -2116.07 | E44: -2077.49 | F44: -2152.03 | G44: -2157.5 | H44: -1997.83 | I44: -1918.92 | J44: 0 | K44: 0 | L44: -5053.16 | M44: -1517.29 | N44: -1682.8 | O44: -1631.67 | P44: =+SUM(D44:O44) -> -22304.76
B45: Rent | D45: 1870.24 | E45: 658.13 | F45: 837.03 | G45: 517.89 | H45: 3514.57 | I45: -800.55 | J45: 2224.88 | K45: -2950.36 | L45: 2257.12 | M45: 473.27 | N45: 924.24 | O45: 277.09 | P45: =+SUM(D45:O45) -> 9803.55
B46: Property & Other Taxes | D46: 45461 | E46: 45461 | F46: 45461 | G46: 45461 | H46: 45461 | I46: 45461 | J46: 86358.56 | K46: 2281.72 | L46: 48368 | M46: 48368 | N46: 48368 | O46: 33677.12 | P46: =+SUM(D46:O46) -> 540187.4
B47: Insurance | D47: ='Adjusted Forecast'!C47 -> 96851.1 | E47: ='Adjusted Forecast'!D47 -> 96851.1 | F47: ='Adjusted Forecast'!E47 -> 96851.1 | G47: ='Adjusted Forecast'!F47 -> 96851.1 | H47: ='Adjusted Forecast'!G47 -> 96851.1 | I47: ='Adjusted Forecast'!H47 -> 96851.1 | J47: ='Adjusted Forecast'!I47 -> 96851.1 | K47: ='Adjusted Forecast'!J47 -> 96851.1 | ... O47: ='Adjusted Forecast'!N47 -> 96851.1 | P47: =+SUM(D47:O47) -> 1162213.2
B48: Other | D48: 0 | E48: 0 | F48: 0 | G48: 0 | H48: 0 | I48: 0 | J48: 0 | K48: 0 | L48: 0 | M48: 0 | N48: 0 | O48: 0 | P48: =+SUM(D48:O48) -> 0
B49: Total non-operating income & expenses | D49: =SUM(D44:D48) -> 142066.27 | E49: =SUM(E44:E48) -> 140892.74 | F49: =SUM(F44:F48) -> 140997.1 | G49: =SUM(G44:G48) -> 140672.49 | H49: =SUM(H44:H48) -> 143828.84 | I49: =SUM(I44:I48) -> 139592.63 | J49: =SUM(J44:J48) -> 185434.54 | K49: =SUM(K44:K48) -> 96182.46 | ... O49: =SUM(O44:O48) -> 129173.64 | P49: =+SUM(D49:O49) -> 1689899.4
B51: EBITDA | D51: =D42-D49 -> 179423.98 | E51: =E42-E49 -> 8918.0331 | F51: =F42-F49 -> 12515.932 | G51: =G42-G49 -> -44784.823 | H51: =H42-H49 -> -71719.941 | I51: =I42-I49 -> 99607.123 | J51: =J42-J49 -> 137871.19 | K51: =K42-K49 -> 506884.62 | ... O51: =O42-O49 -> 443428.77 | P51: =+SUM(D51:O51) -> 2963355.7
...

Sheet FORECAST
A1: Angler's
A2: FORECASTED STATEMENT OF INCOME
A3: FOR THE PERIOD ENDING DECEMBER 31, 2025
C6: 45688 | D6: 45716 | E6: 45747 | F6: 45777 | G6: 45808 | H6: 45838 | I6: 45869 | J6: 45900 | K6: 45930 | L6: 45961 | M6: 45991 | N6: 46022 | O6: TOTAL
C7: Actual | D7: Actual | E7: Actual | F7: Actual | G7: Forecast | H7: Forecast | I7: Forecast | J7: Forecast | K7: Forecast | L7: Forecast | M7: Forecast | N7: Forecast
B9: Available Rooms | C9: 4092 | D9: 3696 | E9: 4092 | F9: 3960 | G9: 4092 | H9: 3960 | I9: 4092 | J9: 4092 | K9: 3960 | L9: 4092 | M9: 3960 | N9: 4092 | O9: =SUM(C9:N9) -> 48180
B10: Total Rooms Sold | C10: 3709 | D10: 3426 | E10: 3737 | F10: 3684 | G10: 3264 | H10: 2855 | I10: 2920 | J10: 2871 | K10: 2461 | L10: 3286 | M10: 3319 | N10: 3557 | O10: =SUM(C10:N10) -> 39089
B11: Occupancy | C11: 0.9064 | D11: 0.9269 | E11: 0.9132 | F11: =F10/F9 -> 0.93030303 | G11: =G10/G9 -> 0.79765396 | H11: =H10/H9 -> 0.7209596 | I11: =I10/I9 -> 0.71358749 | J11: =J10/J9 -> 0.7016129 | K11: =K10/K9 -> 0.62146465 | L11: =L10/L9 -> 0.8030303 | M11: =M10/M9 -> 0.83813131 | ... O11: =O10/O9 -> 0.81131175
B12: Average Daily Rate | C12: 280.5929 | D12: 341.1863 | E12: 296.9933 | F12: =F17/F10 -> 266.56628 | G12: =G17/G10 -> 223.74368 | H12: =H17/H10 -> 182.12489 | I12: =I17/I10 -> 178.92017 | J12: =J17/J10 -> 165.50697 | K12: =K17/K10 -> 148.67055 | L12: =L17/L10 -> 196.85383 | M12: =M17/M10 -> 212.2182 | ... O12: =O17/O10 -> 239.90992
B13: Revenue per Available Room | C13: 254.3301 | D13: 316.262 | E13: 271.2277 | F13: =F11*F12 -> 247.98742 | G13: =G11*G12 -> 178.47003 | H13: =H11*H12 -> 131.30469 | I13: =I11*I12 -> 127.6752 | J13: =J11*J12 -> 116.12182 | K13: =K11*K12 -> 92.393492 | L13: =L11*L12 -> 158.07959 | M13: =M11*M12 -> 177.86672 | ... O13: =O11*O12 -> 194.64174
B16: Revenues
B17: Rooms | C17: 1040719 | D17: 1168904.2 | E17: 1109863.8 | F17: 982030.19 | G17: 730299.37 | H17: 519966.56 | I17: 522446.91 | J17: 475170.5 | K17: 365878.23 | L17: 646861.69 | M17: 704352.21 | N17: 1111346.4 | O17: =SUM(C17:N17) -> 9377839
B18: Food & Beverage | C18: 354251.28 | D18: 423507.82 | E18: 367074.76 | F18: 379131.93 | G18: 364017.56 | H18: 300373.15 | I18: 300485.6 | J18: 281361.83 | K18: 320944.45 | L18: 339544.78 | M18: 406007.87 | N18: 450651.61 | O18: =SUM(C18:N18) -> 4287352.6
B19: Other Operated Departments | C19: 2237.04 | D19: 2324.18 | E19: 2364.48 | F19: 2948.44 | G19: 1308.8 | H19: 1142 | I19: 1168 | J19: 1148.4 | K19: 986 | L19: 1314.4 | M19: 1327.6 | N19: 1422.8 | O19: =SUM(C19:N19) -> 19692.14
B20: Miscellaneous Income | C20: 107218.88 | D20: 91349.99 | E20: 110611.64 | F20: 144707.94 | G20: 109128.85 | H20: 94329.12 | I20: 94748.22 | J20: 92333.37 | K20: 81981.5 | L20: 105907 | M20: 106523 | N20: 117805 | O20: =SUM(C20:N20) -> 1256644.5
B21: Total Revenues | C21: 1504426.2 | D21: 1686086.2 | E21: 1589914.7 | F21: =SUM(F17:F20) -> 1508818.5 | G21: =SUM(G17:G20) -> 1204754.6 | H21: =SUM(H17:H20) -> 915810.83 | I21: =SUM(I17:I20) -> 918848.73 | J21: =SUM(J17:J20) -> 850014.1 | K21: =SUM(K17:K20) -> 769790.18 | L21: =SUM(L17:L20) -> 1093627.9 | M21: =SUM(M17:M20) -> 1218210.7 | N21: =SUM(N17:N20) -> 1681225.8 | O21: =SUM(C21:N21) -> 14941528
B23: Departmental Expense
B24: Rooms | C24: 279344.62 | D24: 240150.76 | E24: 250429.69 | F24: 278444.2 | G24: 213683.97 | H24: 187153.72 | I24: 210134.31 | J24: 196622.17 | K24: 181097.72 | L24: 221034.58 | M24: 228171.4 | N24: 258164.05 | O24: =SUM(C24:N24) -> 2744431.2
B25: Food & Beverage | C25: 248459.71 | D25: 275568.11 | E25: 264575.75 | F25: 291396.9 | G25: 254359.85 | H25: 213956.27 | I25: 213992.49 | J25: 201803.15 | K25: 227600.8 | L25: 238733.87 | M25: 281148.42 | N25: 309508.64 | O25: =SUM(C25:N25) -> 3021104
B26: Other Operated Departments | C26: 1154.6 | D26: 1424.85 | E26: 1387.57 | F26: 1105.98 | G26: 575.02 | H26: 501.74 | I26: 513.16 | J26: 504.55 | K26: 433.2 | L26: 577.48 | M26: 583.28 | N26: 625.1 | O26: =SUM(C26:N26) -> 9386.53
B27: Total Departmental Expense | C27: 528958.93 | D27: 517143.72 | E27: 516393.01 | F27: =SUM(F24:F26) -> 570947.08 | G27: =SUM(G24:G26) -> 468618.84 | H27: =SUM(H24:H26) -> 401611.73 | I27: =SUM(I24:I26) -> 424639.96 | J27: =SUM(J24:J26) -> 398929.87 | K27: =SUM(K24:K26) -> 409131.72 | L27: =SUM(L24:L26) -> 460345.93 | M27: =SUM(M24:M26) -> 509903.1 | N27: =SUM(N24:N26) -> 568297.79 | O27: =SUM(C27:N27) -> 5774921.7
B29: Total Departmental Profit | C29: 975467.24 | D29: 1168942.5 | E29: 1073521.6 | F29: =F21-F27 -> 937871.42 | G29: =G21-G27 -> 736135.74 | H29: =H21-H27 -> 514199.1 | I29: =I21-I27 -> 494208.77 | J29: =J21-J27 -> 451084.23 | K29: =K21-K27 -> 360658.46 | L29: =L21-L27 -> 633281.94 | M29: =M21-M27 -> 708307.58 | N29: =N21-N27 -> 1112928 | O29: =SUM(C29:N29) -> 9166606.6
B31: Undistributed Expenses
B32: Administrative & General | C32: 124940.54 | D32: 116597.61 | E32: 120164.19 | F32: 133968.94 | G32: 110313.25 | H32: 101120.89 | I32: 97294.276 | J32: 104234.38 | K32: 94274.67 | L32: 107921.23 | M32: 111445.43 | N32: 133047.79 | O32: =SUM(C32:N32) -> 1355323.2
B33: Information & Telecom Systems | C33: 21170.28 | D33: 24910.61 | E33: 18119.5 | F33: 16160.83 | G33: 12039.74 | H33: 13388.12 | I33: 12790.86 | J33: 13359.3 | K33: 9484.27 | L33: 11476.84 | M33: 11854.86 | N33: 14576 | O33: =SUM(C33:N33) -> 179331.21
B34: Sales & Marketing | C34: 103819.96 | D34: 95261.58 | E34: 94505.39 | F34: 88393.96 | G34: 108622.14 | H34: 92928.35 | I34: 90705.23 | J34: 76584.14 | K34: 78185.66 | L34: 92030.77 | M34: 98458.82 | N34: 102410.6 | O34: =SUM(C34:N34) -> 1121906.6
B35: Property Operation & Maintenan | C35: 63453.34 | D35: 52586.01 | E35: 47396.59 | F35: 57358.85 | G35: 61697.52 | H35: 59573.74 | I35: 60107.65 | J35: 59589.95 | K35: 59620.14 | L35: 63507.53 | M35: 65829.45 | N35: 66101.18 | O35: =SUM(C35:N35) -> 716821.95
B36: Utilities | C36: 25067.23 | D36: 21552.88 | E36: 22703.39 | F36: 24121.87 | G36: 23464.45 | H36: 28511.44 | I36: 25168.45 | J36: 23361.59 | K36: 22409.85 | L36: 22283.76 | M36: 18664.63 | N36: 18757.33 | O36: =SUM(C36:N36) -> 276066.87
B37: Total Undistributed Expenses | C37: 338451.35 | D37: 310908.69 | E37: 302889.06 | F37: =SUM(F32:F36) -> 320004.45 | G37: =SUM(G32:G36) -> 316137.1 | H37: =SUM(H32:H36) -> 295522.54 | I37: =SUM(I32:I36) -> 286066.47 | J37: =SUM(J32:J36) -> 277129.36 | K37: =SUM(K32:K36) -> 263974.59 | L37: =SUM(L32:L36) -> 297220.13 | M37: =SUM(M32:M36) -> 306253.19 | N37: =SUM(N32:N36) -> 334892.9 | O37: =SUM(C37:N37) -> 3649449.8
B39: Gross Operating Profit | C39: 637015.89 | D39: 858033.79 | E39: 770632.59 | F39: =F29-F37 -> 617866.97 | G39: =G29-G37 -> 419998.64 | H39: =H29-H37 -> 218676.57 | I39: =I29-I37 -> 208142.31 | J39: =J29-J37 -> 173954.87 | K39: =K29-K37 -> 96683.87 | L39: =L29-L37 -> 336061.81 | M39: =M29-M37 -> 402054.39 | N39: =N29-N37 -> 778035.12 | O39: =SUM(C39:N39) -> 5517156.8
B41: Management Fees | C41: 59537.97 | D41: 76013.26 | E41: 69990.81 | F41: 68430.22 | G41: =[1]Forecast!K$45 -> 58018.889 | H41: =[1]Forecast!L$45 -> 46459.938 | I41: =[1]Forecast!M$45 -> 46558.638 | J41: =[1]Forecast!N$45 -> 43665.225 | K41: =[1]Forecast!O$45 -> 42449.15 | L41: =[1]Forecast!P$45 -> 53563.11 | M41: =[1]Forecast!Q$45 -> 59902.392 | N41: =[1]Forecast!R$45 -> 76471.616 | O41: =SUM(C41:N41) -> 701061.22
B42: Income before non-operating inc & expense | C42: 577477.92 | D42: 782020.53 | E42: 700641.78 | F42: =F39-F41 -> 549436.75 | G42: =G39-G41 -> 361979.75 | H42: =H39-H41 -> 172216.63 | I42: =I39-I41 -> 161583.67 | J42: =J39-J41 -> 130289.64 | K42: =K39-K41 -> 54234.72 | L42: =L39-L41 -> 282498.7 | M42: =M39-M41 -> 342151.99 | N42: =N39-N41 -> 701563.51 | O42: =SUM(C42:N42) -> 4816095.6
B44: Income | C44: -5053.16 | D44: -1517.29 | E44: -1682.8 | F44: -1631.67 | G44: -2031 | H44: -2031 | I44: -2031 | J44: -2031 | K44: -2031 | L44: -2031 | M44: -2031 | N44: -2031 | O44: =SUM(C44:N44) -> -26132.92
B45: Rent | C45: 2257.12 | D45: 473.27 | E45: 924.24 | F45: 277.09 | G45: 1100.5 | H45: 1100.5 | I45: 1100.5 | J45: 1100.5 | K45: 1100.5 | L45: 1100.5 | M45: 1100.5 | N45: 1600.5 | O45: =SUM(C45:N45) -> 13235.72
B46: Property & Other Taxes | C46: 48368 | D46: 48368 | E46: 48368 | F46: 33677.12 | G46: 48368 | H46: 48368 | I46: 48368 | J46: 48368 | K46: 48368 | L46: 48368 | M46: 48619 | N46: 48619 | O46: =SUM(C46:N46) -> 566227.12
B47: Insurance | C47: 115247.19 | D47: 115553.45 | E47: 115207.89 | F47: 115207.8 | G47: 96851.1 | H47: 96851.1 | I47: 96851.1 | J47: 96851.1 | K47: 96851.1 | L47: 96851.1 | M47: 96851.1 | N47: 96851.1 | O47: =SUM(C47:N47) -> 1236025.1
B48: Other | C48: 0 | D48: 0 | E48: 0 | F48: 0 | G48: 0 | H48: 0 | I48: 0 | J48: 0 | K48: 0 | L48: 0 | M48: 0 | N48: 0 | O48: =SUM(C48:N48) -> 0
B49: Total non-operating income & expenses | C49: 160819.15 | D49: 162877.43 | E49: 162817.33 | F49: =SUM(F44:F48) -> 147530.34 | G49: =SUM(G44:G48) -> 144288.6 | H49: =SUM(H44:H48) -> 144288.6 | I49: =SUM(I44:I48) -> 144288.6 | J49: =SUM(J44:J48) -> 144288.6 | K49: =SUM(K44:K48) -> 144288.6 | L49: =SUM(L44:L48) -> 144288.6 | M49: =SUM(M44:M48) -> 144539.6 | ... O49: =SUM(O44:O48) -> 1789355.1
B51: EBITDA | C51: 416658.77 | D51: 619143.1 | E51: 537824.45 | F51: =F42-F49 -> 401906.41 | G51: =G42-G49 -> 217691.15 | H51: =H42-H49 -> 27928.028 | I51: =I42-I49 -> 17295.068 | J51: =J42-J49 -> -13998.955 | K51: =K42-K49 -> -90053.88 | L51: =L42-L49 -> 138210.1 | M51: =M42-M49 -> 197612.39 | N51: =N42-N49 -> 556523.91 | O51: =SUM(C51:N51) -> 3026740.5
B53: FF&E Proforma Calculation | C53: 60177.047 | D53: 67443.448 | E53: 63596.586 | F53: 60772.54 | G53: =G21*0.04 -> 48190.183 | H53: =H21*0.04 -> 36632.433 | I53: =I21*0.04 -> 36753.949 | J53: =J21*0.04 -> 34000.564 | K53: =K21*0.04 -> 30791.607 | L53: =L21*0.04 -> 43745.115 | M53: =M21*0.04 -> 48728.427 | N53: =N21*0.04 -> 67249.032 | O53: =SUM(C53:N53) -> 598080.93
...

Sheet Adjusted Forecast
A1: Angler's
A2: FORECASTED STATEMENT OF INCOME
A3: FOR THE PERIOD ENDING DECEMBER 31, 2025
C6: 45688 | D6: 45716 | E6: 45747 | F6: 45777 | G6: 45808 | H6: 45838 | I6: 45869 | J6: 45900 | K6: 45930 | L6: 45961 | M6: 45991 | N6: 46022 | O6: TOTAL
C7: Actual | D7: Actual | E7: Actual | F7: Actual | G7: Forecast | H7: Forecast | I7: Forecast | J7: Forecast | K7: Forecast | L7: Forecast | M7: Forecast | N7: Forecast
B9: Available Rooms | C9: 4092 | D9: 3696 | E9: 4092 | F9: 3960 | G9: 4092 | H9: 3960 | I9: 4092 | J9: 4092 | K9: 3960 | L9: 4092 | M9: 3960 | N9: 4092 | O9: =SUM(C9:N9) -> 48180
B10: Total Rooms Sold | C10: 3709 | D10: 3426 | E10: 3737 | F10: 3684 | G10: 3264 | H10: 2855 | I10: 2920 | J10: 2871 | K10: 2461 | L10: 3286 | M10: 3319 | N10: 3557 | O10: =SUM(C10:N10) -> 39089
B11: Occupancy | C11: 0.9064 | D11: 0.9269 | E11: 0.9132 | F11: =F10/F9 -> 0.93030303 | G11: =G10/G9 -> 0.79765396 | H11: =H10/H9 -> 0.7209596 | I11: =I10/I9 -> 0.71358749 | J11: =J10/J9 -> 0.7016129 | K11: =K10/K9 -> 0.62146465 | L11: =L10/L9 -> 0.8030303 | M11: =M10/M9 -> 0.83813131 | ... O11: =O10/O9 -> 0.81131175
B12: Average Daily Rate | C12: 280.5929 | D12: 341.1863 | E12: 296.9933 | F12: =F17/F10 -> 266.56628 | G12: =G17/G10 -> 223.74368 | H12: =H17/H10 -> 182.12489 | I12: =I17/I10 -> 178.92017 | J12: =J17/J10 -> 165.50697 | K12: =K17/K10 -> 148.67055 | L12: =L17/L10 -> 196.85383 | M12: =M17/M10 -> 212.2182 | ... O12: =O17/O10 -> 239.90992
B13: Revenue per Available Room | C13: 254.3301 | D13: 316.262 | E13: 271.2277 | F13: =F11*F12 -> 247.98742 | G13: =G11*G12 -> 178.47003 | H13: =H11*H12 -> 131.30469 | I13: =I11*I12 -> 127.6752 | J13: =J11*J12 -> 116.12182 | K13: =K11*K12 -> 92.393492 | L13: =L11*L12 -> 158.07959 | M13: =M11*M12 -> 177.86672 | ... O13: =O11*O12 -> 194.64174
B16: Revenues
B17: Rooms | C17: 1040719 | D17: 1168904.2 | E17: 1109863.8 | F17: 982030.19 | G17: 730299.37 | H17: 519966.56 | I17: 522446.91 | J17: 475170.5 | K17: 365878.23 | L17: 646861.69 | M17: 704352.21 | N17: 1111346.4 | O17: =SUM(C17:N17) -> 9377839
B18: Food & Beverage | C18: 354251.28 | D18: 423507.82 | E18: 367074.76 | F18: 379131.93 | G18: 364017.56 | H18: 300373.15 | I18: 300485.6 | J18: 281361.83 | K18: 320944.45 | L18: 339544.78 | M18: 406007.87 | N18: 450651.61 | O18: =SUM(C18:N18) -> 4287352.6
B19: Other Operated Departments | C19: 2237.04 | D19: 2324.18 | E19: 2364.48 | F19: 2948.44 | G19: 1308.8 | H19: 1142 | I19: 1168 | J19: 1148.4 | K19: 986 | L19: 1314.4 | M19: 1327.6 | N19: 1422.8 | O19: =SUM(C19:N19) -> 19692.14
B20: Miscellaneous Income | C20: 107218.88 | D20: 91349.99 | E20: 110611.64 | F20: 144707.94 | G20: 109128.85 | H20: 94329.12 | I20: 94748.22 | J20: 92333.37 | K20: 81981.5 | L20: 105907 | M20: 106523 | N20: 117805 | O20: =SUM(C20:N20) -> 1256644.5
B21: Total Revenues | C21: 1504426.2 | D21: 1686086.2 | E21: 1589914.7 | F21: =SUM(F17:F20) -> 1508818.5 | G21: =SUM(G17:G20) -> 1204754.6 | H21: =SUM(H17:H20) -> 915810.83 | I21: =SUM(I17:I20) -> 918848.73 | J21: =SUM(J17:J20) -> 850014.1 | K21: =SUM(K17:K20) -> 769790.18 | L21: =SUM(L17:L20) -> 1093627.9 | M21: =SUM(M17:M20) -> 1218210.7 | N21: =SUM(N17:N20) -> 1681225.8 | O21: =SUM(C21:N21) -> 14941528
B23: Departmental Expense
B24: Rooms | C24: 279344.62 | D24: 240150.76 | E24: 250429.69 | F24: 278444.2 | G24: 213683.97 | H24: 187153.72 | I24: 210134.31 | J24: 196622.17 | K24: 181097.72 | L24: 221034.58 | M24: 228171.4 | N24: 258164.05 | O24: =SUM(C24:N24) -> 2744431.2
B25: Food & Beverage | C25: 248459.71 | D25: 275568.11 | E25: 264575.75 | F25: 291396.9 | G25: 254359.85 | H25: 213956.27 | I25: 213992.49 | J25: 201803.15 | K25: 227600.8 | L25: 238733.87 | M25: 281148.42 | N25: 309508.64 | O25: =SUM(C25:N25) -> 3021104
B26: Other Operated Departments | C26: 1154.6 | D26: 1424.85 | E26: 1387.57 | F26: 1105.98 | G26: 575.02 | H26: 501.74 | I26: 513.16 | J26: 504.55 | K26: 433.2 | L26: 577.48 | M26: 583.28 | N26: 625.1 | O26: =SUM(C26:N26) -> 9386.53
B27: Total Departmental Expense | C27: 528958.93 | D27: 517143.72 | E27: 516393.01 | F27: =SUM(F24:F26) -> 570947.08 | G27: =SUM(G24:G26) -> 468618.84 | H27: =SUM(H24:H26) -> 401611.73 | I27: =SUM(I24:I26) -> 424639.96 | J27: =SUM(J24:J26) -> 398929.87 | K27: =SUM(K24:K26) -> 409131.72 | L27: =SUM(L24:L26) -> 460345.93 | M27: =SUM(M24:M26) -> 509903.1 | N27: =SUM(N24:N26) -> 568297.79 | O27: =SUM(C27:N27) -> 5774921.7
B29: Total Departmental Profit | C29: 975467.24 | D29: 1168942.5 | E29: 1073521.6 | F29: =F21-F27 -> 937871.42 | G29: =G21-G27 -> 736135.74 | H29: =H21-H27 -> 514199.1 | I29: =I21-I27 -> 494208.77 | J29: =J21-J27 -> 451084.23 | K29: =K21-K27 -> 360658.46 | L29: =L21-L27 -> 633281.94 | M29: =M21-M27 -> 708307.58 | N29: =N21-N27 -> 1112928 | O29: =SUM(C29:N29) -> 9166606.6
B31: Undistributed Expenses
B32: Administrative & General | C32: 124940.54 | D32: 116597.61 | E32: 120164.19 | F32: 133968.94 | G32: 110313.25 | H32: 101120.89 | I32: 97294.276 | J32: 104234.38 | K32: 94274.67 | L32: 107921.23 | M32: 111445.43 | N32: 133047.79 | O32: =SUM(C32:N32) -> 1355323.2
B33: Information & Telecom Systems | C33: 21170.28 | D33: 24910.61 | E33: 18119.5 | F33: 16160.83 | G33: 12039.74 | H33: 13388.12 | I33: 12790.86 | J33: 13359.3 | K33: 9484.27 | L33: 11476.84 | M33: 11854.86 | N33: 14576 | O33: =SUM(C33:N33) -> 179331.21
B34: Sales & Marketing | C34: 103819.96 | D34: 95261.58 | E34: 94505.39 | F34: 88393.96 | G34: 108622.14 | H34: 92928.35 | I34: 90705.23 | J34: 76584.14 | K34: 78185.66 | L34: 92030.77 | M34: 98458.82 | N34: 102410.6 | O34: =SUM(C34:N34) -> 1121906.6
B35: Property Operation & Maintenan | C35: 63453.34 | D35: 52586.01 | E35: 47396.59 | F35: 57358.85 | G35: 61697.52 | H35: 59573.74 | I35: 60107.65 | J35: 59589.95 | K35: 59620.14 | L35: 63507.53 | M35: 65829.45 | N35: 66101.18 | O35: =SUM(C35:N35) -> 716821.95
B36: Utilities | C36: 25067.23 | D36: 21552.88 | E36: 22703.39 | F36: 24121.87 | G36: 23464.45 | H36: 28511.44 | I36: 25168.45 | J36: 23361.59 | K36: 22409.85 | L36: 22283.76 | M36: 18664.63 | N36: 18757.33 | O36: =SUM(C36:N36) -> 276066.87
B37: Total Undistributed Expenses | C37: 338451.35 | D37: 310908.69 | E37: 302889.06 | F37: =SUM(F32:F36) -> 320004.45 | G37: =SUM(G32:G36) -> 316137.1 | H37: =SUM(H32:H36) -> 295522.54 | I37: =SUM(I32:I36) -> 286066.47 | J37: =SUM(J32:J36) -> 277129.36 | K37: =SUM(K32:K36) -> 263974.59 | L37: =SUM(L32:L36) -> 297220.13 | M37: =SUM(M32:M36) -> 306253.19 | N37: =SUM(N32:N36) -> 334892.9 | O37: =SUM(C37:N37) -> 3649449.8
B39: Gross Operating Profit | C39: =C29-C37 -> 637015.89 | D39: =D29-D37 -> 858033.79 | E39: =E29-E37 -> 770632.59 | F39: =F29-F37 -> 617866.97 | G39: =G29-G37 -> 419998.64 | H39: =H29-H37 -> 218676.57 | I39: =I29-I37 -> 208142.31 | J39: =J29-J37 -> 173954.87 | ... N39: =N29-N37 -> 778035.12 | O39: =SUM(C39:N39) -> 5517156.8
B41: Management Fees | C41: =C21*3% -> 45132.785 | D41: =D21*3% -> 50582.586 | E41: =E21*3% -> 47697.44 | F41: =F21*3% -> 45264.555 | G41: =G21*3% -> 36142.637 | H41: =H21*3% -> 27474.325 | I41: =I21*3% -> 27565.462 | J41: =J21*3% -> 25500.423 | ... N41: =N21*3% -> 50436.774 | O41: =SUM(C41:N41) -> 448245.85
B42: Income before non-operating inc & expense | C42: =C39-C41 -> 591883.1 | D42: =D39-D41 -> 807451.2 | E42: =E39-E41 -> 722935.15 | F42: =F39-F41 -> 572602.41 | G42: =G39-G41 -> 383856 | H42: =H39-H41 -> 191202.24 | I42: =I39-I41 -> 180576.84 | J42: =J39-J41 -> 148454.45 | ... N42: =N39-N41 -> 727598.35 | O42: =SUM(C42:N42) -> 5068911
B44: Income | C44: -5053.16 | D44: -1517.29 | E44: -1682.8 | F44: -1631.67 | G44: -2031 | H44: -2031 | I44: -2031 | J44: -2031 | K44: -2031 | L44: -2031 | M44: -2031 | N44: -2031 | O44: =SUM(C44:N44) -> -26132.92
B45: Rent | C45: 2257.12 | D45: 473.27 | E45: 924.24 | F45: 277.09 | G45: 1100.5 | H45: 1100.5 | I45: 1100.5 | J45: 1100.5 | K45: 1100.5 | L45: 1100.5 | M45: 1100.5 | N45: 1600.5 | O45: =SUM(C45:N45) -> 13235.72
B46: Property & Other Taxes | C46: 48368 | D46: 48368 | E46: 48368 | F46: 33677.12 | G46: 48368 | H46: 48368 | I46: 48368 | J46: 48368 | K46: 48368 | L46: 48368 | M46: 48619 | N46: 48619 | O46: =SUM(C46:N46) -> 566227.12
B47: Insurance | C47: 96851.1 | D47: 96851.1 | E47: 96851.1 | F47: 96851.1 | G47: 96851.1 | H47: 96851.1 | I47: 96851.1 | J47: 96851.1 | K47: 96851.1 | L47: 96851.1 | M47: 96851.1 | N47: 96851.1 | O47: =SUM(C47:N47) -> 1162213.2
B48: Other | C48: 0 | D48: 0 | E48: 0 | F48: 0 | G48: 0 | H48: 0 | I48: 0 | J48: 0 | K48: 0 | L48: 0 | M48: 0 | N48: 0 | O48: =SUM(C48:N48) -> 0
B49: Total non-operating income & expenses | C49: =SUM(C44:C48) -> 142423.06 | D49: =SUM(D44:D48) -> 144175.08 | E49: =SUM(E44:E48) -> 144460.54 | F49: =SUM(F44:F48) -> 129173.64 | G49: =SUM(G44:G48) -> 144288.6 | H49: =SUM(H44:H48) -> 144288.6 | I49: =SUM(I44:I48) -> 144288.6 | J49: =SUM(J44:J48) -> 144288.6 | ... O49: =SUM(O44:O48) -> 1715543.1
B51: EBITDA | C51: =C42-C49 -> 449460.04 | D51: =D42-D49 -> 663276.12 | E51: =E42-E49 -> 578474.61 | F51: =F42-F49 -> 443428.77 | G51: =G42-G49 -> 239567.4 | H51: =H42-H49 -> 46913.641 | I51: =I42-I49 -> 36288.244 | J51: =J42-J49 -> 4165.8467 | ... N51: =N42-N49 -> 582558.75 | O51: =SUM(C51:N51) -> 3353367.8
B53: FF&E Proforma Calculation | C53: =C21*0.04 -> 60177.047 | D53: =D21*0.04 -> 67443.448 | E53: =E21*0.04 -> 63596.586 | F53: =F21*0.04 -> 60352.74 | G53: =G21*0.04 -> 48190.183 | H53: =H21*0.04 -> 36632.433 | I53: =I21*0.04 -> 36753.949 | J53: =J21*0.04 -> 34000.564 | ... N53: =N21*0.04 -> 67249.032 | O53: =SUM(C53:N53) -> 597661.13
...
